[Tue Sep 12 23:09:07.329539 2017] [wsgi:error] [pid 18975] [client 209.54.86.83:57132] [2017-09-12 23:09:07,327] ERROR in app: Exception on /add [POST], referer: http://www.zachflask.tk/
[Tue Sep 12 23:09:07.329584 2017] [wsgi:error] [pid 18975] [client 209.54.86.83:57132] Traceback (most recent call last):, referer: http://www.zachflask.tk/
[Tue Sep 12 23:09:07.329587 2017] [wsgi:error] [pid 18975] [client 209.54.86.83:57132]   File "/usr/local/lib/python2.7/dist-packages/flask/app.py", line 1982, in wsgi_app, referer: http://www.zachflask.tk/
[Tue Sep 12 23:09:07.329589 2017] [wsgi:error] [pid 18975] [client 209.54.86.83:57132]     response = self.full_dispatch_request(), referer: http://www.zachflask.tk/
[Tue Sep 12 23:09:07.329591 2017] [wsgi:error] [pid 18975] [client 209.54.86.83:57132]   File "/usr/local/lib/python2.7/dist-packages/flask/app.py", line 1614, in full_dispatch_request, referer: http://www.zachflask.tk/
[Tue Sep 12 23:09:07.329593 2017] [wsgi:error] [pid 18975] [client 209.54.86.83:57132]     rv = self.handle_user_exception(e), referer: http://www.zachflask.tk/
[Tue Sep 12 23:09:07.329594 2017] [wsgi:error] [pid 18975] [client 209.54.86.83:57132]   File "/usr/local/lib/python2.7/dist-packages/flask/app.py", line 1517, in handle_user_exception, referer: http://www.zachflask.tk/
[Tue Sep 12 23:09:07.329596 2017] [wsgi:error] [pid 18975] [client 209.54.86.83:57132]     reraise(exc_type, exc_value, tb), referer: http://www.zachflask.tk/
[Tue Sep 12 23:09:07.329598 2017] [wsgi:error] [pid 18975] [client 209.54.86.83:57132]   File "/usr/local/lib/python2.7/dist-packages/flask/app.py", line 1612, in full_dispatch_request, referer: http://www.zachflask.tk/
[Tue Sep 12 23:09:07.329600 2017] [wsgi:error] [pid 18975] [client 209.54.86.83:57132]     rv = self.dispatch_request(), referer: http://www.zachflask.tk/
[Tue Sep 12 23:09:07.329602 2017] [wsgi:error] [pid 18975] [client 209.54.86.83:57132]   File "/usr/local/lib/python2.7/dist-packages/flask/app.py", line 1598, in dispatch_request, referer: http://www.zachflask.tk/
[Tue Sep 12 23:09:07.329604 2017] [wsgi:error] [pid 18975] [client 209.54.86.83:57132]     return self.view_functions[rule.endpoint](**req.view_args), referer: http://www.zachflask.tk/
[Tue Sep 12 23:09:07.329605 2017] [wsgi:error] [pid 18975] [client 209.54.86.83:57132]   File "/var/www/FlaskApp/FlaskApp/FlaskApp.py", line 76, in add_entry, referer: http://www.zachflask.tk/
[Tue Sep 12 23:09:07.329607 2017] [wsgi:error] [pid 18975] [client 209.54.86.83:57132]     [request.form['title'], request.form['text']]), referer: http://www.zachflask.tk/
[Tue Sep 12 23:09:07.329609 2017] [wsgi:error] [pid 18975] [client 209.54.86.83:57132] OperationalError: attempt to write a readonly database, referer: http://www.zachflask.tk/
[Tue Sep 12 23:09:14.851969 2017] [wsgi:error] [pid 18954] [client 209.54.86.83:57134] [2017-09-12 23:09:14,851] ERROR in app: Exception on /add [POST], referer: http://www.zachflask.tk/
[Tue Sep 12 23:09:14.852001 2017] [wsgi:error] [pid 18954] [client 209.54.86.83:57134] Traceback (most recent call last):, referer: http://www.zachflask.tk/
[Tue Sep 12 23:09:14.852004 2017] [wsgi:error] [pid 18954] [client 209.54.86.83:57134]   File "/usr/local/lib/python2.7/dist-packages/flask/app.py", line 1982, in wsgi_app, referer: http://www.zachflask.tk/
[Tue Sep 12 23:09:14.852006 2017] [wsgi:error] [pid 18954] [client 209.54.86.83:57134]     response = self.full_dispatch_request(), referer: http://www.zachflask.tk/
[Tue Sep 12 23:09:14.852008 2017] [wsgi:error] [pid 18954] [client 209.54.86.83:57134]   File "/usr/local/lib/python2.7/dist-packages/flask/app.py", line 1614, in full_dispatch_request, referer: http://www.zachflask.tk/
[Tue Sep 12 23:09:14.852011 2017] [wsgi:error] [pid 18954] [client 209.54.86.83:57134]     rv = self.handle_user_exception(e), referer: http://www.zachflask.tk/
[Tue Sep 12 23:09:14.852013 2017] [wsgi:error] [pid 18954] [client 209.54.86.83:57134]   File "/usr/local/lib/python2.7/dist-packages/flask/app.py", line 1517, in handle_user_exception, referer: http://www.zachflask.tk/
[Tue Sep 12 23:09:14.852025 2017] [wsgi:error] [pid 18954] [client 209.54.86.83:57134]     reraise(exc_type, exc_value, tb), referer: http://www.zachflask.tk/
[Tue Sep 12 23:09:14.852027 2017] [wsgi:error] [pid 18954] [client 209.54.86.83:57134]   File "/usr/local/lib/python2.7/dist-packages/flask/app.py", line 1612, in full_dispatch_request, referer: http://www.zachflask.tk/
[Tue Sep 12 23:09:14.852029 2017] [wsgi:error] [pid 18954] [client 209.54.86.83:57134]     rv = self.dispatch_request(), referer: http://www.zachflask.tk/
[Tue Sep 12 23:09:14.852031 2017] [wsgi:error] [pid 18954] [client 209.54.86.83:57134]   File "/usr/local/lib/python2.7/dist-packages/flask/app.py", line 1598, in dispatch_request, referer: http://www.zachflask.tk/
[Tue Sep 12 23:09:14.852033 2017] [wsgi:error] [pid 18954] [client 209.54.86.83:57134]     return self.view_functions[rule.endpoint](**req.view_args), referer: http://www.zachflask.tk/
[Tue Sep 12 23:09:14.852035 2017] [wsgi:error] [pid 18954] [client 209.54.86.83:57134]   File "/var/www/FlaskApp/FlaskApp/FlaskApp.py", line 76, in add_entry, referer: http://www.zachflask.tk/
[Tue Sep 12 23:09:14.852037 2017] [wsgi:error] [pid 18954] [client 209.54.86.83:57134]     [request.form['title'], request.form['text']]), referer: http://www.zachflask.tk/
[Tue Sep 12 23:09:14.852038 2017] [wsgi:error] [pid 18954] [client 209.54.86.83:57134] OperationalError: attempt to write a readonly database, referer: http://www.zachflask.tk/
[Tue Sep 12 23:15:17.497778 2017] [wsgi:error] [pid 18957] [client 209.54.86.83:57176] [2017-09-12 23:15:17,497] ERROR in app: Exception on /add [POST], referer: http://www.zachflask.tk/
[Tue Sep 12 23:15:17.497814 2017] [wsgi:error] [pid 18957] [client 209.54.86.83:57176] Traceback (most recent call last):, referer: http://www.zachflask.tk/
[Tue Sep 12 23:15:17.497817 2017] [wsgi:error] [pid 18957] [client 209.54.86.83:57176]   File "/usr/local/lib/python2.7/dist-packages/flask/app.py", line 1982, in wsgi_app, referer: http://www.zachflask.tk/
[Tue Sep 12 23:15:17.497819 2017] [wsgi:error] [pid 18957] [client 209.54.86.83:57176]     response = self.full_dispatch_request(), referer: http://www.zachflask.tk/
[Tue Sep 12 23:15:17.497822 2017] [wsgi:error] [pid 18957] [client 209.54.86.83:57176]   File "/usr/local/lib/python2.7/dist-packages/flask/app.py", line 1614, in full_dispatch_request, referer: http://www.zachflask.tk/
[Tue Sep 12 23:15:17.497824 2017] [wsgi:error] [pid 18957] [client 209.54.86.83:57176]     rv = self.handle_user_exception(e), referer: http://www.zachflask.tk/
[Tue Sep 12 23:15:17.497826 2017] [wsgi:error] [pid 18957] [client 209.54.86.83:57176]   File "/usr/local/lib/python2.7/dist-packages/flask/app.py", line 1517, in handle_user_exception, referer: http://www.zachflask.tk/
[Tue Sep 12 23:15:17.497829 2017] [wsgi:error] [pid 18957] [client 209.54.86.83:57176]     reraise(exc_type, exc_value, tb), referer: http://www.zachflask.tk/
[Tue Sep 12 23:15:17.497831 2017] [wsgi:error] [pid 18957] [client 209.54.86.83:57176]   File "/usr/local/lib/python2.7/dist-packages/flask/app.py", line 1612, in full_dispatch_request, referer: http://www.zachflask.tk/
[Tue Sep 12 23:15:17.497833 2017] [wsgi:error] [pid 18957] [client 209.54.86.83:57176]     rv = self.dispatch_request(), referer: http://www.zachflask.tk/
[Tue Sep 12 23:15:17.497835 2017] [wsgi:error] [pid 18957] [client 209.54.86.83:57176]   File "/usr/local/lib/python2.7/dist-packages/flask/app.py", line 1598, in dispatch_request, referer: http://www.zachflask.tk/
[Tue Sep 12 23:15:17.497837 2017] [wsgi:error] [pid 18957] [client 209.54.86.83:57176]     return self.view_functions[rule.endpoint](**req.view_args), referer: http://www.zachflask.tk/
[Tue Sep 12 23:15:17.497839 2017] [wsgi:error] [pid 18957] [client 209.54.86.83:57176]   File "/var/www/FlaskApp/FlaskApp/FlaskApp.py", line 76, in add_entry, referer: http://www.zachflask.tk/
[Tue Sep 12 23:15:17.497841 2017] [wsgi:error] [pid 18957] [client 209.54.86.83:57176]     [request.form['title'], request.form['text']]), referer: http://www.zachflask.tk/
[Tue Sep 12 23:15:17.497853 2017] [wsgi:error] [pid 18957] [client 209.54.86.83:57176] OperationalError: attempt to write a readonly database, referer: http://www.zachflask.tk/
[Tue Sep 12 23:26:54.797178 2017] [wsgi:error] [pid 18973] [client 209.54.86.83:57283] [2017-09-12 23:26:54,796] ERROR in app: Exception on /add [POST], referer: http://www.zachflask.tk/
[Tue Sep 12 23:26:54.797217 2017] [wsgi:error] [pid 18973] [client 209.54.86.83:57283] Traceback (most recent call last):, referer: http://www.zachflask.tk/
[Tue Sep 12 23:26:54.797220 2017] [wsgi:error] [pid 18973] [client 209.54.86.83:57283]   File "/usr/local/lib/python2.7/dist-packages/flask/app.py", line 1982, in wsgi_app, referer: http://www.zachflask.tk/
[Tue Sep 12 23:26:54.797223 2017] [wsgi:error] [pid 18973] [client 209.54.86.83:57283]     response = self.full_dispatch_request(), referer: http://www.zachflask.tk/
[Tue Sep 12 23:26:54.797225 2017] [wsgi:error] [pid 18973] [client 209.54.86.83:57283]   File "/usr/local/lib/python2.7/dist-packages/flask/app.py", line 1614, in full_dispatch_request, referer: http://www.zachflask.tk/
[Tue Sep 12 23:26:54.797228 2017] [wsgi:error] [pid 18973] [client 209.54.86.83:57283]     rv = self.handle_user_exception(e), referer: http://www.zachflask.tk/
[Tue Sep 12 23:26:54.797230 2017] [wsgi:error] [pid 18973] [client 209.54.86.83:57283]   File "/usr/local/lib/python2.7/dist-packages/flask/app.py", line 1517, in handle_user_exception, referer: http://www.zachflask.tk/
[Tue Sep 12 23:26:54.797232 2017] [wsgi:error] [pid 18973] [client 209.54.86.83:57283]     reraise(exc_type, exc_value, tb), referer: http://www.zachflask.tk/
[Tue Sep 12 23:26:54.797234 2017] [wsgi:error] [pid 18973] [client 209.54.86.83:57283]   File "/usr/local/lib/python2.7/dist-packages/flask/app.py", line 1612, in full_dispatch_request, referer: http://www.zachflask.tk/
[Tue Sep 12 23:26:54.797236 2017] [wsgi:error] [pid 18973] [client 209.54.86.83:57283]     rv = self.dispatch_request(), referer: http://www.zachflask.tk/
[Tue Sep 12 23:26:54.797238 2017] [wsgi:error] [pid 18973] [client 209.54.86.83:57283]   File "/usr/local/lib/python2.7/dist-packages/flask/app.py", line 1598, in dispatch_request, referer: http://www.zachflask.tk/
[Tue Sep 12 23:26:54.797240 2017] [wsgi:error] [pid 18973] [client 209.54.86.83:57283]     return self.view_functions[rule.endpoint](**req.view_args), referer: http://www.zachflask.tk/
[Tue Sep 12 23:26:54.797243 2017] [wsgi:error] [pid 18973] [client 209.54.86.83:57283]   File "/var/www/FlaskApp/FlaskApp/FlaskApp.py", line 76, in add_entry, referer: http://www.zachflask.tk/
[Tue Sep 12 23:26:54.797245 2017] [wsgi:error] [pid 18973] [client 209.54.86.83:57283]     [request.form['title'], request.form['text']]), referer: http://www.zachflask.tk/
[Tue Sep 12 23:26:54.797246 2017] [wsgi:error] [pid 18973] [client 209.54.86.83:57283] OperationalError: attempt to write a readonly database, referer: http://www.zachflask.tk/
[Tue Sep 12 23:27:59.574389 2017] [wsgi:error] [pid 18975] [client 209.54.86.83:57307] [2017-09-12 23:27:59,574] ERROR in app: Exception on /add [POST], referer: http://www.zachflask.tk/
[Tue Sep 12 23:27:59.574423 2017] [wsgi:error] [pid 18975] [client 209.54.86.83:57307] Traceback (most recent call last):, referer: http://www.zachflask.tk/
[Tue Sep 12 23:27:59.574427 2017] [wsgi:error] [pid 18975] [client 209.54.86.83:57307]   File "/usr/local/lib/python2.7/dist-packages/flask/app.py", line 1982, in wsgi_app, referer: http://www.zachflask.tk/
[Tue Sep 12 23:27:59.574430 2017] [wsgi:error] [pid 18975] [client 209.54.86.83:57307]     response = self.full_dispatch_request(), referer: http://www.zachflask.tk/
[Tue Sep 12 23:27:59.574432 2017] [wsgi:error] [pid 18975] [client 209.54.86.83:57307]   File "/usr/local/lib/python2.7/dist-packages/flask/app.py", line 1614, in full_dispatch_request, referer: http://www.zachflask.tk/
[Tue Sep 12 23:27:59.574434 2017] [wsgi:error] [pid 18975] [client 209.54.86.83:57307]     rv = self.handle_user_exception(e), referer: http://www.zachflask.tk/
[Tue Sep 12 23:27:59.574437 2017] [wsgi:error] [pid 18975] [client 209.54.86.83:57307]   File "/usr/local/lib/python2.7/dist-packages/flask/app.py", line 1517, in handle_user_exception, referer: http://www.zachflask.tk/
[Tue Sep 12 23:27:59.574450 2017] [wsgi:error] [pid 18975] [client 209.54.86.83:57307]     reraise(exc_type, exc_value, tb), referer: http://www.zachflask.tk/
[Tue Sep 12 23:27:59.574452 2017] [wsgi:error] [pid 18975] [client 209.54.86.83:57307]   File "/usr/local/lib/python2.7/dist-packages/flask/app.py", line 1612, in full_dispatch_request, referer: http://www.zachflask.tk/
[Tue Sep 12 23:27:59.574454 2017] [wsgi:error] [pid 18975] [client 209.54.86.83:57307]     rv = self.dispatch_request(), referer: http://www.zachflask.tk/
[Tue Sep 12 23:27:59.574456 2017] [wsgi:error] [pid 18975] [client 209.54.86.83:57307]   File "/usr/local/lib/python2.7/dist-packages/flask/app.py", line 1598, in dispatch_request, referer: http://www.zachflask.tk/
[Tue Sep 12 23:27:59.574457 2017] [wsgi:error] [pid 18975] [client 209.54.86.83:57307]     return self.view_functions[rule.endpoint](**req.view_args), referer: http://www.zachflask.tk/
[Tue Sep 12 23:27:59.574459 2017] [wsgi:error] [pid 18975] [client 209.54.86.83:57307]   File "/var/www/FlaskApp/FlaskApp/FlaskApp.py", line 76, in add_entry, referer: http://www.zachflask.tk/
[Tue Sep 12 23:27:59.574461 2017] [wsgi:error] [pid 18975] [client 209.54.86.83:57307]     [request.form['title'], request.form['text']]), referer: http://www.zachflask.tk/
[Tue Sep 12 23:27:59.574463 2017] [wsgi:error] [pid 18975] [client 209.54.86.83:57307] OperationalError: attempt to write a readonly database, referer: http://www.zachflask.tk/
[Tue Sep 12 23:33:28.934516 2017] [wsgi:error] [pid 19307] [client 209.54.86.83:57392] [2017-09-12 23:33:28,933] ERROR in app: Exception on /add [POST], referer: http://www.zachflask.tk/
[Tue Sep 12 23:33:28.934557 2017] [wsgi:error] [pid 19307] [client 209.54.86.83:57392] Traceback (most recent call last):, referer: http://www.zachflask.tk/
[Tue Sep 12 23:33:28.934560 2017] [wsgi:error] [pid 19307] [client 209.54.86.83:57392]   File "/usr/local/lib/python2.7/dist-packages/flask/app.py", line 1982, in wsgi_app, referer: http://www.zachflask.tk/
[Tue Sep 12 23:33:28.934563 2017] [wsgi:error] [pid 19307] [client 209.54.86.83:57392]     response = self.full_dispatch_request(), referer: http://www.zachflask.tk/
[Tue Sep 12 23:33:28.934565 2017] [wsgi:error] [pid 19307] [client 209.54.86.83:57392]   File "/usr/local/lib/python2.7/dist-packages/flask/app.py", line 1614, in full_dispatch_request, referer: http://www.zachflask.tk/
[Tue Sep 12 23:33:28.934567 2017] [wsgi:error] [pid 19307] [client 209.54.86.83:57392]     rv = self.handle_user_exception(e), referer: http://www.zachflask.tk/
[Tue Sep 12 23:33:28.934569 2017] [wsgi:error] [pid 19307] [client 209.54.86.83:57392]   File "/usr/local/lib/python2.7/dist-packages/flask/app.py", line 1517, in handle_user_exception, referer: http://www.zachflask.tk/
[Tue Sep 12 23:33:28.934571 2017] [wsgi:error] [pid 19307] [client 209.54.86.83:57392]     reraise(exc_type, exc_value, tb), referer: http://www.zachflask.tk/
[Tue Sep 12 23:33:28.934573 2017] [wsgi:error] [pid 19307] [client 209.54.86.83:57392]   File "/usr/local/lib/python2.7/dist-packages/flask/app.py", line 1612, in full_dispatch_request, referer: http://www.zachflask.tk/
[Tue Sep 12 23:33:28.934575 2017] [wsgi:error] [pid 19307] [client 209.54.86.83:57392]     rv = self.dispatch_request(), referer: http://www.zachflask.tk/
[Tue Sep 12 23:33:28.934577 2017] [wsgi:error] [pid 19307] [client 209.54.86.83:57392]   File "/usr/local/lib/python2.7/dist-packages/flask/app.py", line 1598, in dispatch_request, referer: http://www.zachflask.tk/
[Tue Sep 12 23:33:28.934579 2017] [wsgi:error] [pid 19307] [client 209.54.86.83:57392]     return self.view_functions[rule.endpoint](**req.view_args), referer: http://www.zachflask.tk/
[Tue Sep 12 23:33:28.934581 2017] [wsgi:error] [pid 19307] [client 209.54.86.83:57392]   File "/var/www/FlaskApp/FlaskApp/FlaskApp.py", line 76, in add_entry, referer: http://www.zachflask.tk/
[Tue Sep 12 23:33:28.934594 2017] [wsgi:error] [pid 19307] [client 209.54.86.83:57392]     [request.form['title'], request.form['text']]), referer: http://www.zachflask.tk/
[Tue Sep 12 23:33:28.934596 2017] [wsgi:error] [pid 19307] [client 209.54.86.83:57392] OperationalError: attempt to write a readonly database, referer: http://www.zachflask.tk/
[Tue Sep 12 23:40:22.424862 2017] [wsgi:error] [pid 19477] [client 209.54.86.83:57490] [2017-09-12 23:40:22,424] ERROR in app: Exception on /add [POST], referer: http://www.zachflask.tk/
[Tue Sep 12 23:40:22.424904 2017] [wsgi:error] [pid 19477] [client 209.54.86.83:57490] Traceback (most recent call last):, referer: http://www.zachflask.tk/
[Tue Sep 12 23:40:22.424907 2017] [wsgi:error] [pid 19477] [client 209.54.86.83:57490]   File "/usr/local/lib/python2.7/dist-packages/flask/app.py", line 1982, in wsgi_app, referer: http://www.zachflask.tk/
[Tue Sep 12 23:40:22.424910 2017] [wsgi:error] [pid 19477] [client 209.54.86.83:57490]     response = self.full_dispatch_request(), referer: http://www.zachflask.tk/
[Tue Sep 12 23:40:22.424912 2017] [wsgi:error] [pid 19477] [client 209.54.86.83:57490]   File "/usr/local/lib/python2.7/dist-packages/flask/app.py", line 1614, in full_dispatch_request, referer: http://www.zachflask.tk/
[Tue Sep 12 23:40:22.424914 2017] [wsgi:error] [pid 19477] [client 209.54.86.83:57490]     rv = self.handle_user_exception(e), referer: http://www.zachflask.tk/
[Tue Sep 12 23:40:22.424917 2017] [wsgi:error] [pid 19477] [client 209.54.86.83:57490]   File "/usr/local/lib/python2.7/dist-packages/flask/app.py", line 1517, in handle_user_exception, referer: http://www.zachflask.tk/
[Tue Sep 12 23:40:22.424919 2017] [wsgi:error] [pid 19477] [client 209.54.86.83:57490]     reraise(exc_type, exc_value, tb), referer: http://www.zachflask.tk/
[Tue Sep 12 23:40:22.424921 2017] [wsgi:error] [pid 19477] [client 209.54.86.83:57490]   File "/usr/local/lib/python2.7/dist-packages/flask/app.py", line 1612, in full_dispatch_request, referer: http://www.zachflask.tk/
[Tue Sep 12 23:40:22.424923 2017] [wsgi:error] [pid 19477] [client 209.54.86.83:57490]     rv = self.dispatch_request(), referer: http://www.zachflask.tk/
[Tue Sep 12 23:40:22.424925 2017] [wsgi:error] [pid 19477] [client 209.54.86.83:57490]   File "/usr/local/lib/python2.7/dist-packages/flask/app.py", line 1598, in dispatch_request, referer: http://www.zachflask.tk/
[Tue Sep 12 23:40:22.424927 2017] [wsgi:error] [pid 19477] [client 209.54.86.83:57490]     return self.view_functions[rule.endpoint](**req.view_args), referer: http://www.zachflask.tk/
[Tue Sep 12 23:40:22.424929 2017] [wsgi:error] [pid 19477] [client 209.54.86.83:57490]   File "/var/www/FlaskApp/FlaskApp/FlaskApp.py", line 76, in add_entry, referer: http://www.zachflask.tk/
[Tue Sep 12 23:40:22.424931 2017] [wsgi:error] [pid 19477] [client 209.54.86.83:57490]     [request.form['title'], request.form['text']]), referer: http://www.zachflask.tk/
[Tue Sep 12 23:40:22.424933 2017] [wsgi:error] [pid 19477] [client 209.54.86.83:57490] OperationalError: attempt to write a readonly database, referer: http://www.zachflask.tk/
[Tue Sep 12 23:45:31.655830 2017] [wsgi:error] [pid 19484] [client 209.54.86.83:57528] [2017-09-12 23:45:31,655] ERROR in app: Exception on /add [POST], referer: http://www.zachflask.tk/
[Tue Sep 12 23:45:31.655872 2017] [wsgi:error] [pid 19484] [client 209.54.86.83:57528] Traceback (most recent call last):, referer: http://www.zachflask.tk/
[Tue Sep 12 23:45:31.655875 2017] [wsgi:error] [pid 19484] [client 209.54.86.83:57528]   File "/usr/local/lib/python2.7/dist-packages/flask/app.py", line 1982, in wsgi_app, referer: http://www.zachflask.tk/
[Tue Sep 12 23:45:31.655878 2017] [wsgi:error] [pid 19484] [client 209.54.86.83:57528]     response = self.full_dispatch_request(), referer: http://www.zachflask.tk/
[Tue Sep 12 23:45:31.655880 2017] [wsgi:error] [pid 19484] [client 209.54.86.83:57528]   File "/usr/local/lib/python2.7/dist-packages/flask/app.py", line 1614, in full_dispatch_request, referer: http://www.zachflask.tk/
[Tue Sep 12 23:45:31.655891 2017] [wsgi:error] [pid 19484] [client 209.54.86.83:57528]     rv = self.handle_user_exception(e), referer: http://www.zachflask.tk/
[Tue Sep 12 23:45:31.655894 2017] [wsgi:error] [pid 19484] [client 209.54.86.83:57528]   File "/usr/local/lib/python2.7/dist-packages/flask/app.py", line 1517, in handle_user_exception, referer: http://www.zachflask.tk/
[Tue Sep 12 23:45:31.655895 2017] [wsgi:error] [pid 19484] [client 209.54.86.83:57528]     reraise(exc_type, exc_value, tb), referer: http://www.zachflask.tk/
[Tue Sep 12 23:45:31.655897 2017] [wsgi:error] [pid 19484] [client 209.54.86.83:57528]   File "/usr/local/lib/python2.7/dist-packages/flask/app.py", line 1612, in full_dispatch_request, referer: http://www.zachflask.tk/
[Tue Sep 12 23:45:31.655899 2017] [wsgi:error] [pid 19484] [client 209.54.86.83:57528]     rv = self.dispatch_request(), referer: http://www.zachflask.tk/
[Tue Sep 12 23:45:31.655901 2017] [wsgi:error] [pid 19484] [client 209.54.86.83:57528]   File "/usr/local/lib/python2.7/dist-packages/flask/app.py", line 1598, in dispatch_request, referer: http://www.zachflask.tk/
[Tue Sep 12 23:45:31.655903 2017] [wsgi:error] [pid 19484] [client 209.54.86.83:57528]     return self.view_functions[rule.endpoint](**req.view_args), referer: http://www.zachflask.tk/
[Tue Sep 12 23:45:31.655905 2017] [wsgi:error] [pid 19484] [client 209.54.86.83:57528]   File "/var/www/FlaskApp/FlaskApp/FlaskApp.py", line 76, in add_entry, referer: http://www.zachflask.tk/
[Tue Sep 12 23:45:31.655907 2017] [wsgi:error] [pid 19484] [client 209.54.86.83:57528]     [request.form['title'], request.form['text']]), referer: http://www.zachflask.tk/
[Tue Sep 12 23:45:31.655908 2017] [wsgi:error] [pid 19484] [client 209.54.86.83:57528] OperationalError: attempt to write a readonly database, referer: http://www.zachflask.tk/
[Wed Sep 13 00:06:45.942501 2017] [wsgi:error] [pid 19670] [client 209.54.86.83:57694] [2017-09-13 00:06:45,941] ERROR in app: Exception on /add [POST], referer: http://www.zachflask.tk/
[Wed Sep 13 00:06:45.942540 2017] [wsgi:error] [pid 19670] [client 209.54.86.83:57694] Traceback (most recent call last):, referer: http://www.zachflask.tk/
[Wed Sep 13 00:06:45.942543 2017] [wsgi:error] [pid 19670] [client 209.54.86.83:57694]   File "/usr/local/lib/python2.7/dist-packages/flask/app.py", line 1982, in wsgi_app, referer: http://www.zachflask.tk/
[Wed Sep 13 00:06:45.942546 2017] [wsgi:error] [pid 19670] [client 209.54.86.83:57694]     response = self.full_dispatch_request(), referer: http://www.zachflask.tk/
[Wed Sep 13 00:06:45.942548 2017] [wsgi:error] [pid 19670] [client 209.54.86.83:57694]   File "/usr/local/lib/python2.7/dist-packages/flask/app.py", line 1614, in full_dispatch_request, referer: http://www.zachflask.tk/
[Wed Sep 13 00:06:45.942550 2017] [wsgi:error] [pid 19670] [client 209.54.86.83:57694]     rv = self.handle_user_exception(e), referer: http://www.zachflask.tk/
[Wed Sep 13 00:06:45.942553 2017] [wsgi:error] [pid 19670] [client 209.54.86.83:57694]   File "/usr/local/lib/python2.7/dist-packages/flask/app.py", line 1517, in handle_user_exception, referer: http://www.zachflask.tk/
[Wed Sep 13 00:06:45.942555 2017] [wsgi:error] [pid 19670] [client 209.54.86.83:57694]     reraise(exc_type, exc_value, tb), referer: http://www.zachflask.tk/
[Wed Sep 13 00:06:45.942557 2017] [wsgi:error] [pid 19670] [client 209.54.86.83:57694]   File "/usr/local/lib/python2.7/dist-packages/flask/app.py", line 1612, in full_dispatch_request, referer: http://www.zachflask.tk/
[Wed Sep 13 00:06:45.942559 2017] [wsgi:error] [pid 19670] [client 209.54.86.83:57694]     rv = self.dispatch_request(), referer: http://www.zachflask.tk/
[Wed Sep 13 00:06:45.942561 2017] [wsgi:error] [pid 19670] [client 209.54.86.83:57694]   File "/usr/local/lib/python2.7/dist-packages/flask/app.py", line 1598, in dispatch_request, referer: http://www.zachflask.tk/
[Wed Sep 13 00:06:45.942563 2017] [wsgi:error] [pid 19670] [client 209.54.86.83:57694]     return self.view_functions[rule.endpoint](**req.view_args), referer: http://www.zachflask.tk/
[Wed Sep 13 00:06:45.942575 2017] [wsgi:error] [pid 19670] [client 209.54.86.83:57694]   File "/var/www/FlaskApp/FlaskApp/FlaskApp.py", line 76, in add_entry, referer: http://www.zachflask.tk/
[Wed Sep 13 00:06:45.942577 2017] [wsgi:error] [pid 19670] [client 209.54.86.83:57694]     [request.form['title'], request.form['text']]), referer: http://www.zachflask.tk/
[Wed Sep 13 00:06:45.942579 2017] [wsgi:error] [pid 19670] [client 209.54.86.83:57694] OperationalError: attempt to write a readonly database, referer: http://www.zachflask.tk/
[Wed Sep 13 00:12:26.468745 2017] [wsgi:error] [pid 19764] [client 209.54.86.83:57733] [2017-09-13 00:12:26,468] ERROR in app: Exception on /add [POST], referer: http://www.zachflask.tk/
[Wed Sep 13 00:12:26.468791 2017] [wsgi:error] [pid 19764] [client 209.54.86.83:57733] Traceback (most recent call last):, referer: http://www.zachflask.tk/
[Wed Sep 13 00:12:26.468794 2017] [wsgi:error] [pid 19764] [client 209.54.86.83:57733]   File "/usr/local/lib/python2.7/dist-packages/flask/app.py", line 1982, in wsgi_app, referer: http://www.zachflask.tk/
[Wed Sep 13 00:12:26.468797 2017] [wsgi:error] [pid 19764] [client 209.54.86.83:57733]     response = self.full_dispatch_request(), referer: http://www.zachflask.tk/
[Wed Sep 13 00:12:26.468799 2017] [wsgi:error] [pid 19764] [client 209.54.86.83:57733]   File "/usr/local/lib/python2.7/dist-packages/flask/app.py", line 1614, in full_dispatch_request, referer: http://www.zachflask.tk/
[Wed Sep 13 00:12:26.468801 2017] [wsgi:error] [pid 19764] [client 209.54.86.83:57733]     rv = self.handle_user_exception(e), referer: http://www.zachflask.tk/
[Wed Sep 13 00:12:26.468803 2017] [wsgi:error] [pid 19764] [client 209.54.86.83:57733]   File "/usr/local/lib/python2.7/dist-packages/flask/app.py", line 1517, in handle_user_exception, referer: http://www.zachflask.tk/
[Wed Sep 13 00:12:26.468805 2017] [wsgi:error] [pid 19764] [client 209.54.86.83:57733]     reraise(exc_type, exc_value, tb), referer: http://www.zachflask.tk/
[Wed Sep 13 00:12:26.468807 2017] [wsgi:error] [pid 19764] [client 209.54.86.83:57733]   File "/usr/local/lib/python2.7/dist-packages/flask/app.py", line 1612, in full_dispatch_request, referer: http://www.zachflask.tk/
[Wed Sep 13 00:12:26.468809 2017] [wsgi:error] [pid 19764] [client 209.54.86.83:57733]     rv = self.dispatch_request(), referer: http://www.zachflask.tk/
[Wed Sep 13 00:12:26.468811 2017] [wsgi:error] [pid 19764] [client 209.54.86.83:57733]   File "/usr/local/lib/python2.7/dist-packages/flask/app.py", line 1598, in dispatch_request, referer: http://www.zachflask.tk/
[Wed Sep 13 00:12:26.468813 2017] [wsgi:error] [pid 19764] [client 209.54.86.83:57733]     return self.view_functions[rule.endpoint](**req.view_args), referer: http://www.zachflask.tk/
[Wed Sep 13 00:12:26.468815 2017] [wsgi:error] [pid 19764] [client 209.54.86.83:57733]   File "/var/www/FlaskApp/FlaskApp/FlaskApp.py", line 76, in add_entry, referer: http://www.zachflask.tk/
[Wed Sep 13 00:12:26.468817 2017] [wsgi:error] [pid 19764] [client 209.54.86.83:57733]     [request.form['title'], request.form['text']]), referer: http://www.zachflask.tk/
[Wed Sep 13 00:12:26.468819 2017] [wsgi:error] [pid 19764] [client 209.54.86.83:57733] OperationalError: attempt to write a readonly database, referer: http://www.zachflask.tk/
[Wed Sep 13 00:32:24.651449 2017] [wsgi:error] [pid 20347] [client 209.54.86.83:57927] [2017-09-13 00:32:24,650] ERROR in app: Exception on /add [POST], referer: http://www.zachflask.tk/
[Wed Sep 13 00:32:24.651485 2017] [wsgi:error] [pid 20347] [client 209.54.86.83:57927] Traceback (most recent call last):, referer: http://www.zachflask.tk/
[Wed Sep 13 00:32:24.651488 2017] [wsgi:error] [pid 20347] [client 209.54.86.83:57927]   File "/usr/local/lib/python2.7/dist-packages/flask/app.py", line 1982, in wsgi_app, referer: http://www.zachflask.tk/
[Wed Sep 13 00:32:24.651490 2017] [wsgi:error] [pid 20347] [client 209.54.86.83:57927]     response = self.full_dispatch_request(), referer: http://www.zachflask.tk/
[Wed Sep 13 00:32:24.651492 2017] [wsgi:error] [pid 20347] [client 209.54.86.83:57927]   File "/usr/local/lib/python2.7/dist-packages/flask/app.py", line 1614, in full_dispatch_request, referer: http://www.zachflask.tk/
[Wed Sep 13 00:32:24.651508 2017] [wsgi:error] [pid 20347] [client 209.54.86.83:57927]     rv = self.handle_user_exception(e), referer: http://www.zachflask.tk/
[Wed Sep 13 00:32:24.651510 2017] [wsgi:error] [pid 20347] [client 209.54.86.83:57927]   File "/usr/local/lib/python2.7/dist-packages/flask/app.py", line 1517, in handle_user_exception, referer: http://www.zachflask.tk/
[Wed Sep 13 00:32:24.651512 2017] [wsgi:error] [pid 20347] [client 209.54.86.83:57927]     reraise(exc_type, exc_value, tb), referer: http://www.zachflask.tk/
[Wed Sep 13 00:32:24.651514 2017] [wsgi:error] [pid 20347] [client 209.54.86.83:57927]   File "/usr/local/lib/python2.7/dist-packages/flask/app.py", line 1612, in full_dispatch_request, referer: http://www.zachflask.tk/
[Wed Sep 13 00:32:24.651516 2017] [wsgi:error] [pid 20347] [client 209.54.86.83:57927]     rv = self.dispatch_request(), referer: http://www.zachflask.tk/
[Wed Sep 13 00:32:24.651518 2017] [wsgi:error] [pid 20347] [client 209.54.86.83:57927]   File "/usr/local/lib/python2.7/dist-packages/flask/app.py", line 1598, in dispatch_request, referer: http://www.zachflask.tk/
[Wed Sep 13 00:32:24.651520 2017] [wsgi:error] [pid 20347] [client 209.54.86.83:57927]     return self.view_functions[rule.endpoint](**req.view_args), referer: http://www.zachflask.tk/
[Wed Sep 13 00:32:24.651521 2017] [wsgi:error] [pid 20347] [client 209.54.86.83:57927]   File "/var/www/FlaskApp/FlaskApp/FlaskApp.py", line 76, in add_entry, referer: http://www.zachflask.tk/
[Wed Sep 13 00:32:24.651523 2017] [wsgi:error] [pid 20347] [client 209.54.86.83:57927]     [request.form['title'], request.form['text']]), referer: http://www.zachflask.tk/
[Wed Sep 13 00:32:24.651525 2017] [wsgi:error] [pid 20347] [client 209.54.86.83:57927] OperationalError: attempt to write a readonly database, referer: http://www.zachflask.tk/
[Wed Sep 13 00:35:24.284268 2017] [wsgi:error] [pid 20347] [client 209.54.86.83:58447] [2017-09-13 00:35:24,284] ERROR in app: Exception on /add [POST], referer: http://www.zachflask.tk/
[Wed Sep 13 00:35:24.284305 2017] [wsgi:error] [pid 20347] [client 209.54.86.83:58447] Traceback (most recent call last):, referer: http://www.zachflask.tk/
[Wed Sep 13 00:35:24.284308 2017] [wsgi:error] [pid 20347] [client 209.54.86.83:58447]   File "/usr/local/lib/python2.7/dist-packages/flask/app.py", line 1982, in wsgi_app, referer: http://www.zachflask.tk/
[Wed Sep 13 00:35:24.284311 2017] [wsgi:error] [pid 20347] [client 209.54.86.83:58447]     response = self.full_dispatch_request(), referer: http://www.zachflask.tk/
[Wed Sep 13 00:35:24.284313 2017] [wsgi:error] [pid 20347] [client 209.54.86.83:58447]   File "/usr/local/lib/python2.7/dist-packages/flask/app.py", line 1614, in full_dispatch_request, referer: http://www.zachflask.tk/
[Wed Sep 13 00:35:24.284316 2017] [wsgi:error] [pid 20347] [client 209.54.86.83:58447]     rv = self.handle_user_exception(e), referer: http://www.zachflask.tk/
[Wed Sep 13 00:35:24.284319 2017] [wsgi:error] [pid 20347] [client 209.54.86.83:58447]   File "/usr/local/lib/python2.7/dist-packages/flask/app.py", line 1517, in handle_user_exception, referer: http://www.zachflask.tk/
[Wed Sep 13 00:35:24.284321 2017] [wsgi:error] [pid 20347] [client 209.54.86.83:58447]     reraise(exc_type, exc_value, tb), referer: http://www.zachflask.tk/
[Wed Sep 13 00:35:24.284323 2017] [wsgi:error] [pid 20347] [client 209.54.86.83:58447]   File "/usr/local/lib/python2.7/dist-packages/flask/app.py", line 1612, in full_dispatch_request, referer: http://www.zachflask.tk/
[Wed Sep 13 00:35:24.284325 2017] [wsgi:error] [pid 20347] [client 209.54.86.83:58447]     rv = self.dispatch_request(), referer: http://www.zachflask.tk/
[Wed Sep 13 00:35:24.284327 2017] [wsgi:error] [pid 20347] [client 209.54.86.83:58447]   File "/usr/local/lib/python2.7/dist-packages/flask/app.py", line 1598, in dispatch_request, referer: http://www.zachflask.tk/
[Wed Sep 13 00:35:24.284349 2017] [wsgi:error] [pid 20347] [client 209.54.86.83:58447]     return self.view_functions[rule.endpoint](**req.view_args), referer: http://www.zachflask.tk/
[Wed Sep 13 00:35:24.284351 2017] [wsgi:error] [pid 20347] [client 209.54.86.83:58447]   File "/var/www/FlaskApp/FlaskApp/FlaskApp.py", line 76, in add_entry, referer: http://www.zachflask.tk/
[Wed Sep 13 00:35:24.284353 2017] [wsgi:error] [pid 20347] [client 209.54.86.83:58447]     [request.form['title'], request.form['text']]), referer: http://www.zachflask.tk/
[Wed Sep 13 00:35:24.284355 2017] [wsgi:error] [pid 20347] [client 209.54.86.83:58447] OperationalError: attempt to write a readonly database, referer: http://www.zachflask.tk/
[Wed Sep 13 00:37:17.948247 2017] [wsgi:error] [pid 20342] [client 209.54.86.83:58467] [2017-09-13 00:37:17,947] ERROR in app: Exception on /add [POST], referer: http://www.zachflask.tk/
[Wed Sep 13 00:37:17.948285 2017] [wsgi:error] [pid 20342] [client 209.54.86.83:58467] Traceback (most recent call last):, referer: http://www.zachflask.tk/
[Wed Sep 13 00:37:17.948289 2017] [wsgi:error] [pid 20342] [client 209.54.86.83:58467]   File "/usr/local/lib/python2.7/dist-packages/flask/app.py", line 1982, in wsgi_app, referer: http://www.zachflask.tk/
[Wed Sep 13 00:37:17.948291 2017] [wsgi:error] [pid 20342] [client 209.54.86.83:58467]     response = self.full_dispatch_request(), referer: http://www.zachflask.tk/
[Wed Sep 13 00:37:17.948294 2017] [wsgi:error] [pid 20342] [client 209.54.86.83:58467]   File "/usr/local/lib/python2.7/dist-packages/flask/app.py", line 1614, in full_dispatch_request, referer: http://www.zachflask.tk/
[Wed Sep 13 00:37:17.948296 2017] [wsgi:error] [pid 20342] [client 209.54.86.83:58467]     rv = self.handle_user_exception(e), referer: http://www.zachflask.tk/
[Wed Sep 13 00:37:17.948299 2017] [wsgi:error] [pid 20342] [client 209.54.86.83:58467]   File "/usr/local/lib/python2.7/dist-packages/flask/app.py", line 1517, in handle_user_exception, referer: http://www.zachflask.tk/
[Wed Sep 13 00:37:17.948301 2017] [wsgi:error] [pid 20342] [client 209.54.86.83:58467]     reraise(exc_type, exc_value, tb), referer: http://www.zachflask.tk/
[Wed Sep 13 00:37:17.948303 2017] [wsgi:error] [pid 20342] [client 209.54.86.83:58467]   File "/usr/local/lib/python2.7/dist-packages/flask/app.py", line 1612, in full_dispatch_request, referer: http://www.zachflask.tk/
[Wed Sep 13 00:37:17.948305 2017] [wsgi:error] [pid 20342] [client 209.54.86.83:58467]     rv = self.dispatch_request(), referer: http://www.zachflask.tk/
[Wed Sep 13 00:37:17.948307 2017] [wsgi:error] [pid 20342] [client 209.54.86.83:58467]   File "/usr/local/lib/python2.7/dist-packages/flask/app.py", line 1598, in dispatch_request, referer: http://www.zachflask.tk/
[Wed Sep 13 00:37:17.948309 2017] [wsgi:error] [pid 20342] [client 209.54.86.83:58467]     return self.view_functions[rule.endpoint](**req.view_args), referer: http://www.zachflask.tk/
[Wed Sep 13 00:37:17.948311 2017] [wsgi:error] [pid 20342] [client 209.54.86.83:58467]   File "/var/www/FlaskApp/FlaskApp/FlaskApp.py", line 76, in add_entry, referer: http://www.zachflask.tk/
[Wed Sep 13 00:37:17.948313 2017] [wsgi:error] [pid 20342] [client 209.54.86.83:58467]     [request.form['title'], request.form['text']]), referer: http://www.zachflask.tk/
[Wed Sep 13 00:37:17.948315 2017] [wsgi:error] [pid 20342] [client 209.54.86.83:58467] OperationalError: attempt to write a readonly database, referer: http://www.zachflask.tk/
[Wed Sep 13 00:38:50.726887 2017] [wsgi:error] [pid 20513] [client 209.54.86.83:58471] [2017-09-13 00:38:50,726] ERROR in app: Exception on /add [POST], referer: http://www.zachflask.tk/
[Wed Sep 13 00:38:50.726922 2017] [wsgi:error] [pid 20513] [client 209.54.86.83:58471] Traceback (most recent call last):, referer: http://www.zachflask.tk/
[Wed Sep 13 00:38:50.726925 2017] [wsgi:error] [pid 20513] [client 209.54.86.83:58471]   File "/usr/local/lib/python2.7/dist-packages/flask/app.py", line 1982, in wsgi_app, referer: http://www.zachflask.tk/
[Wed Sep 13 00:38:50.726938 2017] [wsgi:error] [pid 20513] [client 209.54.86.83:58471]     response = self.full_dispatch_request(), referer: http://www.zachflask.tk/
[Wed Sep 13 00:38:50.726940 2017] [wsgi:error] [pid 20513] [client 209.54.86.83:58471]   File "/usr/local/lib/python2.7/dist-packages/flask/app.py", line 1614, in full_dispatch_request, referer: http://www.zachflask.tk/
[Wed Sep 13 00:38:50.726942 2017] [wsgi:error] [pid 20513] [client 209.54.86.83:58471]     rv = self.handle_user_exception(e), referer: http://www.zachflask.tk/
[Wed Sep 13 00:38:50.726944 2017] [wsgi:error] [pid 20513] [client 209.54.86.83:58471]   File "/usr/local/lib/python2.7/dist-packages/flask/app.py", line 1517, in handle_user_exception, referer: http://www.zachflask.tk/
[Wed Sep 13 00:38:50.726946 2017] [wsgi:error] [pid 20513] [client 209.54.86.83:58471]     reraise(exc_type, exc_value, tb), referer: http://www.zachflask.tk/
[Wed Sep 13 00:38:50.726948 2017] [wsgi:error] [pid 20513] [client 209.54.86.83:58471]   File "/usr/local/lib/python2.7/dist-packages/flask/app.py", line 1612, in full_dispatch_request, referer: http://www.zachflask.tk/
[Wed Sep 13 00:38:50.726949 2017] [wsgi:error] [pid 20513] [client 209.54.86.83:58471]     rv = self.dispatch_request(), referer: http://www.zachflask.tk/
[Wed Sep 13 00:38:50.726951 2017] [wsgi:error] [pid 20513] [client 209.54.86.83:58471]   File "/usr/local/lib/python2.7/dist-packages/flask/app.py", line 1598, in dispatch_request, referer: http://www.zachflask.tk/
[Wed Sep 13 00:38:50.726953 2017] [wsgi:error] [pid 20513] [client 209.54.86.83:58471]     return self.view_functions[rule.endpoint](**req.view_args), referer: http://www.zachflask.tk/
[Wed Sep 13 00:38:50.726955 2017] [wsgi:error] [pid 20513] [client 209.54.86.83:58471]   File "/var/www/FlaskApp/FlaskApp/FlaskApp.py", line 76, in add_entry, referer: http://www.zachflask.tk/
[Wed Sep 13 00:38:50.726957 2017] [wsgi:error] [pid 20513] [client 209.54.86.83:58471]     [request.form['title'], request.form['text']]), referer: http://www.zachflask.tk/
[Wed Sep 13 00:38:50.726958 2017] [wsgi:error] [pid 20513] [client 209.54.86.83:58471] OperationalError: unable to open database file, referer: http://www.zachflask.tk/
[Wed Sep 13 00:41:53.487816 2017] [wsgi:error] [pid 20701] [client 209.54.86.83:58484] [2017-09-13 00:41:53,487] ERROR in app: Exception on /add [POST], referer: http://www.zachflask.tk/
[Wed Sep 13 00:41:53.487850 2017] [wsgi:error] [pid 20701] [client 209.54.86.83:58484] Traceback (most recent call last):, referer: http://www.zachflask.tk/
[Wed Sep 13 00:41:53.487853 2017] [wsgi:error] [pid 20701] [client 209.54.86.83:58484]   File "/usr/local/lib/python2.7/dist-packages/flask/app.py", line 1982, in wsgi_app, referer: http://www.zachflask.tk/
[Wed Sep 13 00:41:53.487856 2017] [wsgi:error] [pid 20701] [client 209.54.86.83:58484]     response = self.full_dispatch_request(), referer: http://www.zachflask.tk/
[Wed Sep 13 00:41:53.487858 2017] [wsgi:error] [pid 20701] [client 209.54.86.83:58484]   File "/usr/local/lib/python2.7/dist-packages/flask/app.py", line 1614, in full_dispatch_request, referer: http://www.zachflask.tk/
[Wed Sep 13 00:41:53.487860 2017] [wsgi:error] [pid 20701] [client 209.54.86.83:58484]     rv = self.handle_user_exception(e), referer: http://www.zachflask.tk/
[Wed Sep 13 00:41:53.487863 2017] [wsgi:error] [pid 20701] [client 209.54.86.83:58484]   File "/usr/local/lib/python2.7/dist-packages/flask/app.py", line 1517, in handle_user_exception, referer: http://www.zachflask.tk/
[Wed Sep 13 00:41:53.487865 2017] [wsgi:error] [pid 20701] [client 209.54.86.83:58484]     reraise(exc_type, exc_value, tb), referer: http://www.zachflask.tk/
[Wed Sep 13 00:41:53.487867 2017] [wsgi:error] [pid 20701] [client 209.54.86.83:58484]   File "/usr/local/lib/python2.7/dist-packages/flask/app.py", line 1612, in full_dispatch_request, referer: http://www.zachflask.tk/
[Wed Sep 13 00:41:53.487869 2017] [wsgi:error] [pid 20701] [client 209.54.86.83:58484]     rv = self.dispatch_request(), referer: http://www.zachflask.tk/
[Wed Sep 13 00:41:53.487880 2017] [wsgi:error] [pid 20701] [client 209.54.86.83:58484]   File "/usr/local/lib/python2.7/dist-packages/flask/app.py", line 1598, in dispatch_request, referer: http://www.zachflask.tk/
[Wed Sep 13 00:41:53.487883 2017] [wsgi:error] [pid 20701] [client 209.54.86.83:58484]     return self.view_functions[rule.endpoint](**req.view_args), referer: http://www.zachflask.tk/
[Wed Sep 13 00:41:53.487885 2017] [wsgi:error] [pid 20701] [client 209.54.86.83:58484]   File "/var/www/FlaskApp/FlaskApp/FlaskApp.py", line 76, in add_entry, referer: http://www.zachflask.tk/
[Wed Sep 13 00:41:53.487887 2017] [wsgi:error] [pid 20701] [client 209.54.86.83:58484]     [request.form['title'], request.form['text']]), referer: http://www.zachflask.tk/
[Wed Sep 13 00:41:53.487888 2017] [wsgi:error] [pid 20701] [client 209.54.86.83:58484] OperationalError: attempt to write a readonly database, referer: http://www.zachflask.tk/
[Wed Sep 13 00:42:10.749552 2017] [wsgi:error] [pid 20701] [client 209.54.86.83:58489] [2017-09-13 00:42:10,749] ERROR in app: Exception on /add [POST], referer: http://www.zachflask.tk/
[Wed Sep 13 00:42:10.749578 2017] [wsgi:error] [pid 20701] [client 209.54.86.83:58489] Traceback (most recent call last):, referer: http://www.zachflask.tk/
[Wed Sep 13 00:42:10.749581 2017] [wsgi:error] [pid 20701] [client 209.54.86.83:58489]   File "/usr/local/lib/python2.7/dist-packages/flask/app.py", line 1982, in wsgi_app, referer: http://www.zachflask.tk/
[Wed Sep 13 00:42:10.749583 2017] [wsgi:error] [pid 20701] [client 209.54.86.83:58489]     response = self.full_dispatch_request(), referer: http://www.zachflask.tk/
[Wed Sep 13 00:42:10.749586 2017] [wsgi:error] [pid 20701] [client 209.54.86.83:58489]   File "/usr/local/lib/python2.7/dist-packages/flask/app.py", line 1614, in full_dispatch_request, referer: http://www.zachflask.tk/
[Wed Sep 13 00:42:10.749588 2017] [wsgi:error] [pid 20701] [client 209.54.86.83:58489]     rv = self.handle_user_exception(e), referer: http://www.zachflask.tk/
[Wed Sep 13 00:42:10.749590 2017] [wsgi:error] [pid 20701] [client 209.54.86.83:58489]   File "/usr/local/lib/python2.7/dist-packages/flask/app.py", line 1517, in handle_user_exception, referer: http://www.zachflask.tk/
[Wed Sep 13 00:42:10.749591 2017] [wsgi:error] [pid 20701] [client 209.54.86.83:58489]     reraise(exc_type, exc_value, tb), referer: http://www.zachflask.tk/
[Wed Sep 13 00:42:10.749593 2017] [wsgi:error] [pid 20701] [client 209.54.86.83:58489]   File "/usr/local/lib/python2.7/dist-packages/flask/app.py", line 1612, in full_dispatch_request, referer: http://www.zachflask.tk/
[Wed Sep 13 00:42:10.749595 2017] [wsgi:error] [pid 20701] [client 209.54.86.83:58489]     rv = self.dispatch_request(), referer: http://www.zachflask.tk/
[Wed Sep 13 00:42:10.749597 2017] [wsgi:error] [pid 20701] [client 209.54.86.83:58489]   File "/usr/local/lib/python2.7/dist-packages/flask/app.py", line 1598, in dispatch_request, referer: http://www.zachflask.tk/
[Wed Sep 13 00:42:10.749599 2017] [wsgi:error] [pid 20701] [client 209.54.86.83:58489]     return self.view_functions[rule.endpoint](**req.view_args), referer: http://www.zachflask.tk/
[Wed Sep 13 00:42:10.749600 2017] [wsgi:error] [pid 20701] [client 209.54.86.83:58489]   File "/var/www/FlaskApp/FlaskApp/FlaskApp.py", line 76, in add_entry, referer: http://www.zachflask.tk/
[Wed Sep 13 00:42:10.749602 2017] [wsgi:error] [pid 20701] [client 209.54.86.83:58489]     [request.form['title'], request.form['text']]), referer: http://www.zachflask.tk/
[Wed Sep 13 00:42:10.749604 2017] [wsgi:error] [pid 20701] [client 209.54.86.83:58489] OperationalError: attempt to write a readonly database, referer: http://www.zachflask.tk/
[Wed Sep 13 00:43:34.541007 2017] [wsgi:error] [pid 20850] [client 209.54.86.83:58493] [2017-09-13 00:43:34,540] ERROR in app: Exception on /add [POST], referer: http://www.zachflask.tk/
[Wed Sep 13 00:43:34.541044 2017] [wsgi:error] [pid 20850] [client 209.54.86.83:58493] Traceback (most recent call last):, referer: http://www.zachflask.tk/
[Wed Sep 13 00:43:34.541047 2017] [wsgi:error] [pid 20850] [client 209.54.86.83:58493]   File "/usr/local/lib/python2.7/dist-packages/flask/app.py", line 1982, in wsgi_app, referer: http://www.zachflask.tk/
[Wed Sep 13 00:43:34.541062 2017] [wsgi:error] [pid 20850] [client 209.54.86.83:58493]     response = self.full_dispatch_request(), referer: http://www.zachflask.tk/
[Wed Sep 13 00:43:34.541064 2017] [wsgi:error] [pid 20850] [client 209.54.86.83:58493]   File "/usr/local/lib/python2.7/dist-packages/flask/app.py", line 1614, in full_dispatch_request, referer: http://www.zachflask.tk/
[Wed Sep 13 00:43:34.541066 2017] [wsgi:error] [pid 20850] [client 209.54.86.83:58493]     rv = self.handle_user_exception(e), referer: http://www.zachflask.tk/
[Wed Sep 13 00:43:34.541068 2017] [wsgi:error] [pid 20850] [client 209.54.86.83:58493]   File "/usr/local/lib/python2.7/dist-packages/flask/app.py", line 1517, in handle_user_exception, referer: http://www.zachflask.tk/
[Wed Sep 13 00:43:34.541069 2017] [wsgi:error] [pid 20850] [client 209.54.86.83:58493]     reraise(exc_type, exc_value, tb), referer: http://www.zachflask.tk/
[Wed Sep 13 00:43:34.541071 2017] [wsgi:error] [pid 20850] [client 209.54.86.83:58493]   File "/usr/local/lib/python2.7/dist-packages/flask/app.py", line 1612, in full_dispatch_request, referer: http://www.zachflask.tk/
[Wed Sep 13 00:43:34.541073 2017] [wsgi:error] [pid 20850] [client 209.54.86.83:58493]     rv = self.dispatch_request(), referer: http://www.zachflask.tk/
[Wed Sep 13 00:43:34.541075 2017] [wsgi:error] [pid 20850] [client 209.54.86.83:58493]   File "/usr/local/lib/python2.7/dist-packages/flask/app.py", line 1598, in dispatch_request, referer: http://www.zachflask.tk/
[Wed Sep 13 00:43:34.541077 2017] [wsgi:error] [pid 20850] [client 209.54.86.83:58493]     return self.view_functions[rule.endpoint](**req.view_args), referer: http://www.zachflask.tk/
[Wed Sep 13 00:43:34.541078 2017] [wsgi:error] [pid 20850] [client 209.54.86.83:58493]   File "/var/www/FlaskApp/FlaskApp/FlaskApp.py", line 76, in add_entry, referer: http://www.zachflask.tk/
[Wed Sep 13 00:43:34.541080 2017] [wsgi:error] [pid 20850] [client 209.54.86.83:58493]     [request.form['title'], request.form['text']]), referer: http://www.zachflask.tk/
[Wed Sep 13 00:43:34.541082 2017] [wsgi:error] [pid 20850] [client 209.54.86.83:58493] OperationalError: attempt to write a readonly database, referer: http://www.zachflask.tk/
[Wed Sep 13 08:48:00.455568 2017] [wsgi:error] [pid 22192] [client 128.206.251.246:10732] [2017-09-13 08:48:00,449] ERROR in app: Exception on /add [POST], referer: http://www.zachflask.tk/
[Wed Sep 13 08:48:00.456042 2017] [wsgi:error] [pid 22192] [client 128.206.251.246:10732] Traceback (most recent call last):, referer: http://www.zachflask.tk/
[Wed Sep 13 08:48:00.456048 2017] [wsgi:error] [pid 22192] [client 128.206.251.246:10732]   File "/usr/local/lib/python2.7/dist-packages/flask/app.py", line 1982, in wsgi_app, referer: http://www.zachflask.tk/
[Wed Sep 13 08:48:00.456050 2017] [wsgi:error] [pid 22192] [client 128.206.251.246:10732]     response = self.full_dispatch_request(), referer: http://www.zachflask.tk/
[Wed Sep 13 08:48:00.456053 2017] [wsgi:error] [pid 22192] [client 128.206.251.246:10732]   File "/usr/local/lib/python2.7/dist-packages/flask/app.py", line 1614, in full_dispatch_request, referer: http://www.zachflask.tk/
[Wed Sep 13 08:48:00.456055 2017] [wsgi:error] [pid 22192] [client 128.206.251.246:10732]     rv = self.handle_user_exception(e), referer: http://www.zachflask.tk/
[Wed Sep 13 08:48:00.456057 2017] [wsgi:error] [pid 22192] [client 128.206.251.246:10732]   File "/usr/local/lib/python2.7/dist-packages/flask/app.py", line 1517, in handle_user_exception, referer: http://www.zachflask.tk/
[Wed Sep 13 08:48:00.456059 2017] [wsgi:error] [pid 22192] [client 128.206.251.246:10732]     reraise(exc_type, exc_value, tb), referer: http://www.zachflask.tk/
[Wed Sep 13 08:48:00.456061 2017] [wsgi:error] [pid 22192] [client 128.206.251.246:10732]   File "/usr/local/lib/python2.7/dist-packages/flask/app.py", line 1612, in full_dispatch_request, referer: http://www.zachflask.tk/
[Wed Sep 13 08:48:00.456072 2017] [wsgi:error] [pid 22192] [client 128.206.251.246:10732]     rv = self.dispatch_request(), referer: http://www.zachflask.tk/
[Wed Sep 13 08:48:00.456074 2017] [wsgi:error] [pid 22192] [client 128.206.251.246:10732]   File "/usr/local/lib/python2.7/dist-packages/flask/app.py", line 1598, in dispatch_request, referer: http://www.zachflask.tk/
[Wed Sep 13 08:48:00.456076 2017] [wsgi:error] [pid 22192] [client 128.206.251.246:10732]     return self.view_functions[rule.endpoint](**req.view_args), referer: http://www.zachflask.tk/
[Wed Sep 13 08:48:00.456078 2017] [wsgi:error] [pid 22192] [client 128.206.251.246:10732]   File "/var/www/FlaskApp/FlaskApp/FlaskApp.py", line 76, in add_entry, referer: http://www.zachflask.tk/
[Wed Sep 13 08:48:00.456079 2017] [wsgi:error] [pid 22192] [client 128.206.251.246:10732]     [request.form['title'], request.form['text']]), referer: http://www.zachflask.tk/
[Wed Sep 13 08:48:00.456081 2017] [wsgi:error] [pid 22192] [client 128.206.251.246:10732] OperationalError: attempt to write a readonly database, referer: http://www.zachflask.tk/
[Wed Sep 13 08:55:30.532654 2017] [wsgi:error] [pid 22782] [client 128.206.251.246:50912] [2017-09-13 08:55:30,532] ERROR in app: Exception on /add [POST], referer: http://www.zachflask.tk/
[Wed Sep 13 08:55:30.532697 2017] [wsgi:error] [pid 22782] [client 128.206.251.246:50912] Traceback (most recent call last):, referer: http://www.zachflask.tk/
[Wed Sep 13 08:55:30.532701 2017] [wsgi:error] [pid 22782] [client 128.206.251.246:50912]   File "/usr/local/lib/python2.7/dist-packages/flask/app.py", line 1982, in wsgi_app, referer: http://www.zachflask.tk/
[Wed Sep 13 08:55:30.532703 2017] [wsgi:error] [pid 22782] [client 128.206.251.246:50912]     response = self.full_dispatch_request(), referer: http://www.zachflask.tk/
[Wed Sep 13 08:55:30.532706 2017] [wsgi:error] [pid 22782] [client 128.206.251.246:50912]   File "/usr/local/lib/python2.7/dist-packages/flask/app.py", line 1614, in full_dispatch_request, referer: http://www.zachflask.tk/
[Wed Sep 13 08:55:30.532709 2017] [wsgi:error] [pid 22782] [client 128.206.251.246:50912]     rv = self.handle_user_exception(e), referer: http://www.zachflask.tk/
[Wed Sep 13 08:55:30.532711 2017] [wsgi:error] [pid 22782] [client 128.206.251.246:50912]   File "/usr/local/lib/python2.7/dist-packages/flask/app.py", line 1517, in handle_user_exception, referer: http://www.zachflask.tk/
[Wed Sep 13 08:55:30.532713 2017] [wsgi:error] [pid 22782] [client 128.206.251.246:50912]     reraise(exc_type, exc_value, tb), referer: http://www.zachflask.tk/
[Wed Sep 13 08:55:30.532715 2017] [wsgi:error] [pid 22782] [client 128.206.251.246:50912]   File "/usr/local/lib/python2.7/dist-packages/flask/app.py", line 1612, in full_dispatch_request, referer: http://www.zachflask.tk/
[Wed Sep 13 08:55:30.532717 2017] [wsgi:error] [pid 22782] [client 128.206.251.246:50912]     rv = self.dispatch_request(), referer: http://www.zachflask.tk/
[Wed Sep 13 08:55:30.532719 2017] [wsgi:error] [pid 22782] [client 128.206.251.246:50912]   File "/usr/local/lib/python2.7/dist-packages/flask/app.py", line 1598, in dispatch_request, referer: http://www.zachflask.tk/
[Wed Sep 13 08:55:30.532721 2017] [wsgi:error] [pid 22782] [client 128.206.251.246:50912]     return self.view_functions[rule.endpoint](**req.view_args), referer: http://www.zachflask.tk/
[Wed Sep 13 08:55:30.532723 2017] [wsgi:error] [pid 22782] [client 128.206.251.246:50912]   File "/var/www/FlaskApp/FlaskApp/FlaskApp.py", line 76, in add_entry, referer: http://www.zachflask.tk/
[Wed Sep 13 08:55:30.532725 2017] [wsgi:error] [pid 22782] [client 128.206.251.246:50912]     [request.form['title'], request.form['text']]), referer: http://www.zachflask.tk/
[Wed Sep 13 08:55:30.532726 2017] [wsgi:error] [pid 22782] [client 128.206.251.246:50912] OperationalError: unable to open database file, referer: http://www.zachflask.tk/
[Wed Sep 13 10:56:01.315665 2017] [wsgi:error] [pid 22784] [client 128.206.251.55:50482] [2017-09-13 10:56:01,314] ERROR in app: Exception on /add [POST], referer: http://www.zachflask.tk/
[Wed Sep 13 10:56:01.315714 2017] [wsgi:error] [pid 22784] [client 128.206.251.55:50482] Traceback (most recent call last):, referer: http://www.zachflask.tk/
[Wed Sep 13 10:56:01.315717 2017] [wsgi:error] [pid 22784] [client 128.206.251.55:50482]   File "/usr/local/lib/python2.7/dist-packages/flask/app.py", line 1982, in wsgi_app, referer: http://www.zachflask.tk/
[Wed Sep 13 10:56:01.315719 2017] [wsgi:error] [pid 22784] [client 128.206.251.55:50482]     response = self.full_dispatch_request(), referer: http://www.zachflask.tk/
[Wed Sep 13 10:56:01.315721 2017] [wsgi:error] [pid 22784] [client 128.206.251.55:50482]   File "/usr/local/lib/python2.7/dist-packages/flask/app.py", line 1614, in full_dispatch_request, referer: http://www.zachflask.tk/
[Wed Sep 13 10:56:01.315722 2017] [wsgi:error] [pid 22784] [client 128.206.251.55:50482]     rv = self.handle_user_exception(e), referer: http://www.zachflask.tk/
[Wed Sep 13 10:56:01.315724 2017] [wsgi:error] [pid 22784] [client 128.206.251.55:50482]   File "/usr/local/lib/python2.7/dist-packages/flask/app.py", line 1517, in handle_user_exception, referer: http://www.zachflask.tk/
[Wed Sep 13 10:56:01.315726 2017] [wsgi:error] [pid 22784] [client 128.206.251.55:50482]     reraise(exc_type, exc_value, tb), referer: http://www.zachflask.tk/
[Wed Sep 13 10:56:01.315728 2017] [wsgi:error] [pid 22784] [client 128.206.251.55:50482]   File "/usr/local/lib/python2.7/dist-packages/flask/app.py", line 1612, in full_dispatch_request, referer: http://www.zachflask.tk/
[Wed Sep 13 10:56:01.315729 2017] [wsgi:error] [pid 22784] [client 128.206.251.55:50482]     rv = self.dispatch_request(), referer: http://www.zachflask.tk/
[Wed Sep 13 10:56:01.315731 2017] [wsgi:error] [pid 22784] [client 128.206.251.55:50482]   File "/usr/local/lib/python2.7/dist-packages/flask/app.py", line 1598, in dispatch_request, referer: http://www.zachflask.tk/
[Wed Sep 13 10:56:01.315733 2017] [wsgi:error] [pid 22784] [client 128.206.251.55:50482]     return self.view_functions[rule.endpoint](**req.view_args), referer: http://www.zachflask.tk/
[Wed Sep 13 10:56:01.315735 2017] [wsgi:error] [pid 22784] [client 128.206.251.55:50482]   File "/var/www/FlaskApp/FlaskApp/FlaskApp.py", line 76, in add_entry, referer: http://www.zachflask.tk/
[Wed Sep 13 10:56:01.315736 2017] [wsgi:error] [pid 22784] [client 128.206.251.55:50482]     [request.form['title'], request.form['text']]), referer: http://www.zachflask.tk/
[Wed Sep 13 10:56:01.315738 2017] [wsgi:error] [pid 22784] [client 128.206.251.55:50482] OperationalError: unable to open database file, referer: http://www.zachflask.tk/
[Wed Sep 13 12:33:36.830037 2017] [wsgi:error] [pid 22785] [client 128.206.251.55:58119] [2017-09-13 12:33:36,829] ERROR in app: Exception on /add [POST], referer: http://www.zachflask.tk/
[Wed Sep 13 12:33:36.830067 2017] [wsgi:error] [pid 22785] [client 128.206.251.55:58119] Traceback (most recent call last):, referer: http://www.zachflask.tk/
[Wed Sep 13 12:33:36.830071 2017] [wsgi:error] [pid 22785] [client 128.206.251.55:58119]   File "/usr/local/lib/python2.7/dist-packages/flask/app.py", line 1982, in wsgi_app, referer: http://www.zachflask.tk/
[Wed Sep 13 12:33:36.830073 2017] [wsgi:error] [pid 22785] [client 128.206.251.55:58119]     response = self.full_dispatch_request(), referer: http://www.zachflask.tk/
[Wed Sep 13 12:33:36.830075 2017] [wsgi:error] [pid 22785] [client 128.206.251.55:58119]   File "/usr/local/lib/python2.7/dist-packages/flask/app.py", line 1614, in full_dispatch_request, referer: http://www.zachflask.tk/
[Wed Sep 13 12:33:36.830077 2017] [wsgi:error] [pid 22785] [client 128.206.251.55:58119]     rv = self.handle_user_exception(e), referer: http://www.zachflask.tk/
[Wed Sep 13 12:33:36.830080 2017] [wsgi:error] [pid 22785] [client 128.206.251.55:58119]   File "/usr/local/lib/python2.7/dist-packages/flask/app.py", line 1517, in handle_user_exception, referer: http://www.zachflask.tk/
[Wed Sep 13 12:33:36.830082 2017] [wsgi:error] [pid 22785] [client 128.206.251.55:58119]     reraise(exc_type, exc_value, tb), referer: http://www.zachflask.tk/
[Wed Sep 13 12:33:36.830094 2017] [wsgi:error] [pid 22785] [client 128.206.251.55:58119]   File "/usr/local/lib/python2.7/dist-packages/flask/app.py", line 1612, in full_dispatch_request, referer: http://www.zachflask.tk/
[Wed Sep 13 12:33:36.830096 2017] [wsgi:error] [pid 22785] [client 128.206.251.55:58119]     rv = self.dispatch_request(), referer: http://www.zachflask.tk/
[Wed Sep 13 12:33:36.830098 2017] [wsgi:error] [pid 22785] [client 128.206.251.55:58119]   File "/usr/local/lib/python2.7/dist-packages/flask/app.py", line 1598, in dispatch_request, referer: http://www.zachflask.tk/
[Wed Sep 13 12:33:36.830100 2017] [wsgi:error] [pid 22785] [client 128.206.251.55:58119]     return self.view_functions[rule.endpoint](**req.view_args), referer: http://www.zachflask.tk/
[Wed Sep 13 12:33:36.830101 2017] [wsgi:error] [pid 22785] [client 128.206.251.55:58119]   File "/var/www/FlaskApp/FlaskApp/FlaskApp.py", line 76, in add_entry, referer: http://www.zachflask.tk/
[Wed Sep 13 12:33:36.830103 2017] [wsgi:error] [pid 22785] [client 128.206.251.55:58119]     [request.form['title'], request.form['text']]), referer: http://www.zachflask.tk/
[Wed Sep 13 12:33:36.830105 2017] [wsgi:error] [pid 22785] [client 128.206.251.55:58119] OperationalError: unable to open database file, referer: http://www.zachflask.tk/
[Wed Sep 13 13:25:40.199517 2017] [wsgi:error] [pid 23295] [client 128.206.251.55:2817] [2017-09-13 13:25:40,198] ERROR in app: Exception on /add [POST], referer: http://www.zachflask.tk/
[Wed Sep 13 13:25:40.199545 2017] [wsgi:error] [pid 23295] [client 128.206.251.55:2817] Traceback (most recent call last):, referer: http://www.zachflask.tk/
[Wed Sep 13 13:25:40.199548 2017] [wsgi:error] [pid 23295] [client 128.206.251.55:2817]   File "/usr/local/lib/python2.7/dist-packages/flask/app.py", line 1982, in wsgi_app, referer: http://www.zachflask.tk/
[Wed Sep 13 13:25:40.199551 2017] [wsgi:error] [pid 23295] [client 128.206.251.55:2817]     response = self.full_dispatch_request(), referer: http://www.zachflask.tk/
[Wed Sep 13 13:25:40.199553 2017] [wsgi:error] [pid 23295] [client 128.206.251.55:2817]   File "/usr/local/lib/python2.7/dist-packages/flask/app.py", line 1614, in full_dispatch_request, referer: http://www.zachflask.tk/
[Wed Sep 13 13:25:40.199555 2017] [wsgi:error] [pid 23295] [client 128.206.251.55:2817]     rv = self.handle_user_exception(e), referer: http://www.zachflask.tk/
[Wed Sep 13 13:25:40.199558 2017] [wsgi:error] [pid 23295] [client 128.206.251.55:2817]   File "/usr/local/lib/python2.7/dist-packages/flask/app.py", line 1517, in handle_user_exception, referer: http://www.zachflask.tk/
[Wed Sep 13 13:25:40.199560 2017] [wsgi:error] [pid 23295] [client 128.206.251.55:2817]     reraise(exc_type, exc_value, tb), referer: http://www.zachflask.tk/
[Wed Sep 13 13:25:40.199562 2017] [wsgi:error] [pid 23295] [client 128.206.251.55:2817]   File "/usr/local/lib/python2.7/dist-packages/flask/app.py", line 1612, in full_dispatch_request, referer: http://www.zachflask.tk/
[Wed Sep 13 13:25:40.199564 2017] [wsgi:error] [pid 23295] [client 128.206.251.55:2817]     rv = self.dispatch_request(), referer: http://www.zachflask.tk/
[Wed Sep 13 13:25:40.199566 2017] [wsgi:error] [pid 23295] [client 128.206.251.55:2817]   File "/usr/local/lib/python2.7/dist-packages/flask/app.py", line 1598, in dispatch_request, referer: http://www.zachflask.tk/
[Wed Sep 13 13:25:40.199568 2017] [wsgi:error] [pid 23295] [client 128.206.251.55:2817]     return self.view_functions[rule.endpoint](**req.view_args), referer: http://www.zachflask.tk/
[Wed Sep 13 13:25:40.199570 2017] [wsgi:error] [pid 23295] [client 128.206.251.55:2817]   File "/var/www/FlaskApp/FlaskApp/FlaskApp.py", line 76, in add_entry, referer: http://www.zachflask.tk/
[Wed Sep 13 13:25:40.199572 2017] [wsgi:error] [pid 23295] [client 128.206.251.55:2817]     [request.form['title'], request.form['text']]), referer: http://www.zachflask.tk/
[Wed Sep 13 13:25:40.199584 2017] [wsgi:error] [pid 23295] [client 128.206.251.55:2817] OperationalError: unable to open database file, referer: http://www.zachflask.tk/
[Wed Sep 13 13:28:06.180625 2017] [wsgi:error] [pid 23603] [client 128.206.251.55:22848] [2017-09-13 13:28:06,180] ERROR in app: Exception on /add [POST], referer: http://www.zachflask.tk/
[Wed Sep 13 13:28:06.180666 2017] [wsgi:error] [pid 23603] [client 128.206.251.55:22848] Traceback (most recent call last):, referer: http://www.zachflask.tk/
[Wed Sep 13 13:28:06.180669 2017] [wsgi:error] [pid 23603] [client 128.206.251.55:22848]   File "/usr/local/lib/python2.7/dist-packages/flask/app.py", line 1982, in wsgi_app, referer: http://www.zachflask.tk/
[Wed Sep 13 13:28:06.180672 2017] [wsgi:error] [pid 23603] [client 128.206.251.55:22848]     response = self.full_dispatch_request(), referer: http://www.zachflask.tk/
[Wed Sep 13 13:28:06.180674 2017] [wsgi:error] [pid 23603] [client 128.206.251.55:22848]   File "/usr/local/lib/python2.7/dist-packages/flask/app.py", line 1614, in full_dispatch_request, referer: http://www.zachflask.tk/
[Wed Sep 13 13:28:06.180676 2017] [wsgi:error] [pid 23603] [client 128.206.251.55:22848]     rv = self.handle_user_exception(e), referer: http://www.zachflask.tk/
[Wed Sep 13 13:28:06.180678 2017] [wsgi:error] [pid 23603] [client 128.206.251.55:22848]   File "/usr/local/lib/python2.7/dist-packages/flask/app.py", line 1517, in handle_user_exception, referer: http://www.zachflask.tk/
[Wed Sep 13 13:28:06.180681 2017] [wsgi:error] [pid 23603] [client 128.206.251.55:22848]     reraise(exc_type, exc_value, tb), referer: http://www.zachflask.tk/
[Wed Sep 13 13:28:06.180682 2017] [wsgi:error] [pid 23603] [client 128.206.251.55:22848]   File "/usr/local/lib/python2.7/dist-packages/flask/app.py", line 1612, in full_dispatch_request, referer: http://www.zachflask.tk/
[Wed Sep 13 13:28:06.180685 2017] [wsgi:error] [pid 23603] [client 128.206.251.55:22848]     rv = self.dispatch_request(), referer: http://www.zachflask.tk/
[Wed Sep 13 13:28:06.180686 2017] [wsgi:error] [pid 23603] [client 128.206.251.55:22848]   File "/usr/local/lib/python2.7/dist-packages/flask/app.py", line 1598, in dispatch_request, referer: http://www.zachflask.tk/
[Wed Sep 13 13:28:06.180688 2017] [wsgi:error] [pid 23603] [client 128.206.251.55:22848]     return self.view_functions[rule.endpoint](**req.view_args), referer: http://www.zachflask.tk/
[Wed Sep 13 13:28:06.180690 2017] [wsgi:error] [pid 23603] [client 128.206.251.55:22848]   File "/var/www/FlaskApp/FlaskApp/FlaskApp.py", line 76, in add_entry, referer: http://www.zachflask.tk/
[Wed Sep 13 13:28:06.180692 2017] [wsgi:error] [pid 23603] [client 128.206.251.55:22848]     [request.form['title'], request.form['text']]), referer: http://www.zachflask.tk/
[Wed Sep 13 13:28:06.180694 2017] [wsgi:error] [pid 23603] [client 128.206.251.55:22848] OperationalError: unable to open database file, referer: http://www.zachflask.tk/
[Wed Sep 13 13:29:41.145679 2017] [wsgi:error] [pid 23728] [client 128.206.251.55:11637] [2017-09-13 13:29:41,145] ERROR in app: Exception on /add [POST], referer: http://www.zachflask.tk/
[Wed Sep 13 13:29:41.145724 2017] [wsgi:error] [pid 23728] [client 128.206.251.55:11637] Traceback (most recent call last):, referer: http://www.zachflask.tk/
[Wed Sep 13 13:29:41.145727 2017] [wsgi:error] [pid 23728] [client 128.206.251.55:11637]   File "/usr/local/lib/python2.7/dist-packages/flask/app.py", line 1982, in wsgi_app, referer: http://www.zachflask.tk/
[Wed Sep 13 13:29:41.145730 2017] [wsgi:error] [pid 23728] [client 128.206.251.55:11637]     response = self.full_dispatch_request(), referer: http://www.zachflask.tk/
[Wed Sep 13 13:29:41.145733 2017] [wsgi:error] [pid 23728] [client 128.206.251.55:11637]   File "/usr/local/lib/python2.7/dist-packages/flask/app.py", line 1614, in full_dispatch_request, referer: http://www.zachflask.tk/
[Wed Sep 13 13:29:41.145735 2017] [wsgi:error] [pid 23728] [client 128.206.251.55:11637]     rv = self.handle_user_exception(e), referer: http://www.zachflask.tk/
[Wed Sep 13 13:29:41.145747 2017] [wsgi:error] [pid 23728] [client 128.206.251.55:11637]   File "/usr/local/lib/python2.7/dist-packages/flask/app.py", line 1517, in handle_user_exception, referer: http://www.zachflask.tk/
[Wed Sep 13 13:29:41.145749 2017] [wsgi:error] [pid 23728] [client 128.206.251.55:11637]     reraise(exc_type, exc_value, tb), referer: http://www.zachflask.tk/
[Wed Sep 13 13:29:41.145751 2017] [wsgi:error] [pid 23728] [client 128.206.251.55:11637]   File "/usr/local/lib/python2.7/dist-packages/flask/app.py", line 1612, in full_dispatch_request, referer: http://www.zachflask.tk/
[Wed Sep 13 13:29:41.145753 2017] [wsgi:error] [pid 23728] [client 128.206.251.55:11637]     rv = self.dispatch_request(), referer: http://www.zachflask.tk/
[Wed Sep 13 13:29:41.145755 2017] [wsgi:error] [pid 23728] [client 128.206.251.55:11637]   File "/usr/local/lib/python2.7/dist-packages/flask/app.py", line 1598, in dispatch_request, referer: http://www.zachflask.tk/
[Wed Sep 13 13:29:41.145757 2017] [wsgi:error] [pid 23728] [client 128.206.251.55:11637]     return self.view_functions[rule.endpoint](**req.view_args), referer: http://www.zachflask.tk/
[Wed Sep 13 13:29:41.145759 2017] [wsgi:error] [pid 23728] [client 128.206.251.55:11637]   File "/var/www/FlaskApp/FlaskApp/FlaskApp.py", line 76, in add_entry, referer: http://www.zachflask.tk/
[Wed Sep 13 13:29:41.145760 2017] [wsgi:error] [pid 23728] [client 128.206.251.55:11637]     [request.form['title'], request.form['text']]), referer: http://www.zachflask.tk/
[Wed Sep 13 13:29:41.145762 2017] [wsgi:error] [pid 23728] [client 128.206.251.55:11637] OperationalError: attempt to write a readonly database, referer: http://www.zachflask.tk/
[Wed Sep 13 13:32:06.288657 2017] [wsgi:error] [pid 23729] [client 128.206.251.55:50658] [2017-09-13 13:32:06,288] ERROR in app: Exception on /add [POST], referer: http://www.zachflask.tk/
[Wed Sep 13 13:32:06.288692 2017] [wsgi:error] [pid 23729] [client 128.206.251.55:50658] Traceback (most recent call last):, referer: http://www.zachflask.tk/
[Wed Sep 13 13:32:06.288695 2017] [wsgi:error] [pid 23729] [client 128.206.251.55:50658]   File "/usr/local/lib/python2.7/dist-packages/flask/app.py", line 1982, in wsgi_app, referer: http://www.zachflask.tk/
[Wed Sep 13 13:32:06.288697 2017] [wsgi:error] [pid 23729] [client 128.206.251.55:50658]     response = self.full_dispatch_request(), referer: http://www.zachflask.tk/
[Wed Sep 13 13:32:06.288700 2017] [wsgi:error] [pid 23729] [client 128.206.251.55:50658]   File "/usr/local/lib/python2.7/dist-packages/flask/app.py", line 1614, in full_dispatch_request, referer: http://www.zachflask.tk/
[Wed Sep 13 13:32:06.288702 2017] [wsgi:error] [pid 23729] [client 128.206.251.55:50658]     rv = self.handle_user_exception(e), referer: http://www.zachflask.tk/
[Wed Sep 13 13:32:06.288704 2017] [wsgi:error] [pid 23729] [client 128.206.251.55:50658]   File "/usr/local/lib/python2.7/dist-packages/flask/app.py", line 1517, in handle_user_exception, referer: http://www.zachflask.tk/
[Wed Sep 13 13:32:06.288707 2017] [wsgi:error] [pid 23729] [client 128.206.251.55:50658]     reraise(exc_type, exc_value, tb), referer: http://www.zachflask.tk/
[Wed Sep 13 13:32:06.288709 2017] [wsgi:error] [pid 23729] [client 128.206.251.55:50658]   File "/usr/local/lib/python2.7/dist-packages/flask/app.py", line 1612, in full_dispatch_request, referer: http://www.zachflask.tk/
[Wed Sep 13 13:32:06.288711 2017] [wsgi:error] [pid 23729] [client 128.206.251.55:50658]     rv = self.dispatch_request(), referer: http://www.zachflask.tk/
[Wed Sep 13 13:32:06.288713 2017] [wsgi:error] [pid 23729] [client 128.206.251.55:50658]   File "/usr/local/lib/python2.7/dist-packages/flask/app.py", line 1598, in dispatch_request, referer: http://www.zachflask.tk/
[Wed Sep 13 13:32:06.288715 2017] [wsgi:error] [pid 23729] [client 128.206.251.55:50658]     return self.view_functions[rule.endpoint](**req.view_args), referer: http://www.zachflask.tk/
[Wed Sep 13 13:32:06.288717 2017] [wsgi:error] [pid 23729] [client 128.206.251.55:50658]   File "/var/www/FlaskApp/FlaskApp/FlaskApp.py", line 76, in add_entry, referer: http://www.zachflask.tk/
[Wed Sep 13 13:32:06.288729 2017] [wsgi:error] [pid 23729] [client 128.206.251.55:50658]     [request.form['title'], request.form['text']]), referer: http://www.zachflask.tk/
[Wed Sep 13 13:32:06.288731 2017] [wsgi:error] [pid 23729] [client 128.206.251.55:50658] OperationalError: attempt to write a readonly database, referer: http://www.zachflask.tk/
[Wed Sep 13 15:40:23.914798 2017] [wsgi:error] [pid 23882] [client 209.54.86.83:49444] [2017-09-13 15:40:23,914] ERROR in app: Exception on /add [POST], referer: http://www.zachflask.tk/
[Wed Sep 13 15:40:23.914837 2017] [wsgi:error] [pid 23882] [client 209.54.86.83:49444] Traceback (most recent call last):, referer: http://www.zachflask.tk/
[Wed Sep 13 15:40:23.914840 2017] [wsgi:error] [pid 23882] [client 209.54.86.83:49444]   File "/usr/local/lib/python2.7/dist-packages/flask/app.py", line 1982, in wsgi_app, referer: http://www.zachflask.tk/
[Wed Sep 13 15:40:23.914843 2017] [wsgi:error] [pid 23882] [client 209.54.86.83:49444]     response = self.full_dispatch_request(), referer: http://www.zachflask.tk/
[Wed Sep 13 15:40:23.914845 2017] [wsgi:error] [pid 23882] [client 209.54.86.83:49444]   File "/usr/local/lib/python2.7/dist-packages/flask/app.py", line 1614, in full_dispatch_request, referer: http://www.zachflask.tk/
[Wed Sep 13 15:40:23.914847 2017] [wsgi:error] [pid 23882] [client 209.54.86.83:49444]     rv = self.handle_user_exception(e), referer: http://www.zachflask.tk/
[Wed Sep 13 15:40:23.914850 2017] [wsgi:error] [pid 23882] [client 209.54.86.83:49444]   File "/usr/local/lib/python2.7/dist-packages/flask/app.py", line 1517, in handle_user_exception, referer: http://www.zachflask.tk/
[Wed Sep 13 15:40:23.914852 2017] [wsgi:error] [pid 23882] [client 209.54.86.83:49444]     reraise(exc_type, exc_value, tb), referer: http://www.zachflask.tk/
[Wed Sep 13 15:40:23.914854 2017] [wsgi:error] [pid 23882] [client 209.54.86.83:49444]   File "/usr/local/lib/python2.7/dist-packages/flask/app.py", line 1612, in full_dispatch_request, referer: http://www.zachflask.tk/
[Wed Sep 13 15:40:23.914856 2017] [wsgi:error] [pid 23882] [client 209.54.86.83:49444]     rv = self.dispatch_request(), referer: http://www.zachflask.tk/
[Wed Sep 13 15:40:23.914858 2017] [wsgi:error] [pid 23882] [client 209.54.86.83:49444]   File "/usr/local/lib/python2.7/dist-packages/flask/app.py", line 1598, in dispatch_request, referer: http://www.zachflask.tk/
[Wed Sep 13 15:40:23.914860 2017] [wsgi:error] [pid 23882] [client 209.54.86.83:49444]     return self.view_functions[rule.endpoint](**req.view_args), referer: http://www.zachflask.tk/
[Wed Sep 13 15:40:23.914862 2017] [wsgi:error] [pid 23882] [client 209.54.86.83:49444]   File "/var/www/FlaskApp/FlaskApp/FlaskApp.py", line 76, in add_entry, referer: http://www.zachflask.tk/
[Wed Sep 13 15:40:23.914864 2017] [wsgi:error] [pid 23882] [client 209.54.86.83:49444]     [request.form['title'], request.form['text']]), referer: http://www.zachflask.tk/
[Wed Sep 13 15:40:23.914865 2017] [wsgi:error] [pid 23882] [client 209.54.86.83:49444] OperationalError: unable to open database file, referer: http://www.zachflask.tk/
[Wed Sep 13 17:26:51.729747 2017] [wsgi:error] [pid 24815] [client 209.54.86.83:49746] [2017-09-13 17:26:51,729] ERROR in app: Exception on /add [POST], referer: http://www.zachflask.tk/
[Wed Sep 13 17:26:51.729790 2017] [wsgi:error] [pid 24815] [client 209.54.86.83:49746] Traceback (most recent call last):, referer: http://www.zachflask.tk/
[Wed Sep 13 17:26:51.729794 2017] [wsgi:error] [pid 24815] [client 209.54.86.83:49746]   File "/usr/local/lib/python2.7/dist-packages/flask/app.py", line 1982, in wsgi_app, referer: http://www.zachflask.tk/
[Wed Sep 13 17:26:51.729796 2017] [wsgi:error] [pid 24815] [client 209.54.86.83:49746]     response = self.full_dispatch_request(), referer: http://www.zachflask.tk/
[Wed Sep 13 17:26:51.729799 2017] [wsgi:error] [pid 24815] [client 209.54.86.83:49746]   File "/usr/local/lib/python2.7/dist-packages/flask/app.py", line 1614, in full_dispatch_request, referer: http://www.zachflask.tk/
[Wed Sep 13 17:26:51.729815 2017] [wsgi:error] [pid 24815] [client 209.54.86.83:49746]     rv = self.handle_user_exception(e), referer: http://www.zachflask.tk/
[Wed Sep 13 17:26:51.729817 2017] [wsgi:error] [pid 24815] [client 209.54.86.83:49746]   File "/usr/local/lib/python2.7/dist-packages/flask/app.py", line 1517, in handle_user_exception, referer: http://www.zachflask.tk/
[Wed Sep 13 17:26:51.729819 2017] [wsgi:error] [pid 24815] [client 209.54.86.83:49746]     reraise(exc_type, exc_value, tb), referer: http://www.zachflask.tk/
[Wed Sep 13 17:26:51.729821 2017] [wsgi:error] [pid 24815] [client 209.54.86.83:49746]   File "/usr/local/lib/python2.7/dist-packages/flask/app.py", line 1612, in full_dispatch_request, referer: http://www.zachflask.tk/
[Wed Sep 13 17:26:51.729823 2017] [wsgi:error] [pid 24815] [client 209.54.86.83:49746]     rv = self.dispatch_request(), referer: http://www.zachflask.tk/
[Wed Sep 13 17:26:51.729824 2017] [wsgi:error] [pid 24815] [client 209.54.86.83:49746]   File "/usr/local/lib/python2.7/dist-packages/flask/app.py", line 1598, in dispatch_request, referer: http://www.zachflask.tk/
[Wed Sep 13 17:26:51.729826 2017] [wsgi:error] [pid 24815] [client 209.54.86.83:49746]     return self.view_functions[rule.endpoint](**req.view_args), referer: http://www.zachflask.tk/
[Wed Sep 13 17:26:51.729828 2017] [wsgi:error] [pid 24815] [client 209.54.86.83:49746]   File "/var/www/FlaskApp/FlaskApp/FlaskApp.py", line 76, in add_entry, referer: http://www.zachflask.tk/
[Wed Sep 13 17:26:51.729830 2017] [wsgi:error] [pid 24815] [client 209.54.86.83:49746]     [request.form['title'], request.form['text']]), referer: http://www.zachflask.tk/
[Wed Sep 13 17:26:51.729832 2017] [wsgi:error] [pid 24815] [client 209.54.86.83:49746] OperationalError: unable to open database file, referer: http://www.zachflask.tk/
[Wed Sep 13 18:18:25.879159 2017] [wsgi:error] [pid 25138] [client 209.54.86.83:49907] mod_wsgi (pid=25138): Target WSGI script '/var/www/FlaskApp/flaskapp.wsgi' cannot be loaded as Python module.
[Wed Sep 13 18:18:25.879206 2017] [wsgi:error] [pid 25138] [client 209.54.86.83:49907] mod_wsgi (pid=25138): Exception occurred processing WSGI script '/var/www/FlaskApp/flaskapp.wsgi'.
[Wed Sep 13 18:18:25.879231 2017] [wsgi:error] [pid 25138] [client 209.54.86.83:49907] Traceback (most recent call last):
[Wed Sep 13 18:18:25.879250 2017] [wsgi:error] [pid 25138] [client 209.54.86.83:49907]   File "/var/www/FlaskApp/flaskapp.wsgi", line 7, in <module>
[Wed Sep 13 18:18:25.879294 2017] [wsgi:error] [pid 25138] [client 209.54.86.83:49907]     from FlaskApp import app as application
[Wed Sep 13 18:18:25.879302 2017] [wsgi:error] [pid 25138] [client 209.54.86.83:49907]   File "/var/www/FlaskApp/FlaskApp/__init__.py", line 1, in <module>
[Wed Sep 13 18:18:25.879327 2017] [wsgi:error] [pid 25138] [client 209.54.86.83:49907]     from .FlaskApp import app
[Wed Sep 13 18:18:25.879334 2017] [wsgi:error] [pid 25138] [client 209.54.86.83:49907]   File "/var/www/FlaskApp/FlaskApp/FlaskApp.py", line 13, in <module>
[Wed Sep 13 18:18:25.879368 2017] [wsgi:error] [pid 25138] [client 209.54.86.83:49907]     DATABASE=app.open_instance_resource('FlaskApp.db'),
[Wed Sep 13 18:18:25.879374 2017] [wsgi:error] [pid 25138] [client 209.54.86.83:49907]   File "/usr/local/lib/python2.7/dist-packages/flask/app.py", line 677, in open_instance_resource
[Wed Sep 13 18:18:25.879748 2017] [wsgi:error] [pid 25138] [client 209.54.86.83:49907]     return open(os.path.join(self.instance_path, resource), mode)
[Wed Sep 13 18:18:25.879773 2017] [wsgi:error] [pid 25138] [client 209.54.86.83:49907] IOError: [Errno 2] No such file or directory: '/var/www/FlaskApp/instance/FlaskApp.db'
[Wed Sep 13 18:21:07.918217 2017] [wsgi:error] [pid 25256] [client 209.54.86.83:49988] [2017-09-13 18:21:07,917] ERROR in app: Exception on /add [POST], referer: http://www.zachflask.tk/
[Wed Sep 13 18:21:07.918260 2017] [wsgi:error] [pid 25256] [client 209.54.86.83:49988] Traceback (most recent call last):, referer: http://www.zachflask.tk/
[Wed Sep 13 18:21:07.918273 2017] [wsgi:error] [pid 25256] [client 209.54.86.83:49988]   File "/usr/local/lib/python2.7/dist-packages/flask/app.py", line 1982, in wsgi_app, referer: http://www.zachflask.tk/
[Wed Sep 13 18:21:07.918276 2017] [wsgi:error] [pid 25256] [client 209.54.86.83:49988]     response = self.full_dispatch_request(), referer: http://www.zachflask.tk/
[Wed Sep 13 18:21:07.918278 2017] [wsgi:error] [pid 25256] [client 209.54.86.83:49988]   File "/usr/local/lib/python2.7/dist-packages/flask/app.py", line 1614, in full_dispatch_request, referer: http://www.zachflask.tk/
[Wed Sep 13 18:21:07.918280 2017] [wsgi:error] [pid 25256] [client 209.54.86.83:49988]     rv = self.handle_user_exception(e), referer: http://www.zachflask.tk/
[Wed Sep 13 18:21:07.918281 2017] [wsgi:error] [pid 25256] [client 209.54.86.83:49988]   File "/usr/local/lib/python2.7/dist-packages/flask/app.py", line 1517, in handle_user_exception, referer: http://www.zachflask.tk/
[Wed Sep 13 18:21:07.918283 2017] [wsgi:error] [pid 25256] [client 209.54.86.83:49988]     reraise(exc_type, exc_value, tb), referer: http://www.zachflask.tk/
[Wed Sep 13 18:21:07.918285 2017] [wsgi:error] [pid 25256] [client 209.54.86.83:49988]   File "/usr/local/lib/python2.7/dist-packages/flask/app.py", line 1612, in full_dispatch_request, referer: http://www.zachflask.tk/
[Wed Sep 13 18:21:07.918287 2017] [wsgi:error] [pid 25256] [client 209.54.86.83:49988]     rv = self.dispatch_request(), referer: http://www.zachflask.tk/
[Wed Sep 13 18:21:07.918289 2017] [wsgi:error] [pid 25256] [client 209.54.86.83:49988]   File "/usr/local/lib/python2.7/dist-packages/flask/app.py", line 1598, in dispatch_request, referer: http://www.zachflask.tk/
[Wed Sep 13 18:21:07.918291 2017] [wsgi:error] [pid 25256] [client 209.54.86.83:49988]     return self.view_functions[rule.endpoint](**req.view_args), referer: http://www.zachflask.tk/
[Wed Sep 13 18:21:07.918292 2017] [wsgi:error] [pid 25256] [client 209.54.86.83:49988]   File "/var/www/FlaskApp/FlaskApp/FlaskApp.py", line 76, in add_entry, referer: http://www.zachflask.tk/
[Wed Sep 13 18:21:07.918294 2017] [wsgi:error] [pid 25256] [client 209.54.86.83:49988]     [request.form['title'], request.form['text']]), referer: http://www.zachflask.tk/
[Wed Sep 13 18:21:07.918296 2017] [wsgi:error] [pid 25256] [client 209.54.86.83:49988] OperationalError: unable to open database file, referer: http://www.zachflask.tk/
[Wed Sep 13 18:23:53.650917 2017] [wsgi:error] [pid 25374] [client 209.54.86.83:50014] [2017-09-13 18:23:53,650] ERROR in app: Exception on /add [POST], referer: http://www.zachflask.tk/
[Wed Sep 13 18:23:53.650950 2017] [wsgi:error] [pid 25374] [client 209.54.86.83:50014] Traceback (most recent call last):, referer: http://www.zachflask.tk/
[Wed Sep 13 18:23:53.650954 2017] [wsgi:error] [pid 25374] [client 209.54.86.83:50014]   File "/usr/local/lib/python2.7/dist-packages/flask/app.py", line 1982, in wsgi_app, referer: http://www.zachflask.tk/
[Wed Sep 13 18:23:53.650956 2017] [wsgi:error] [pid 25374] [client 209.54.86.83:50014]     response = self.full_dispatch_request(), referer: http://www.zachflask.tk/
[Wed Sep 13 18:23:53.650959 2017] [wsgi:error] [pid 25374] [client 209.54.86.83:50014]   File "/usr/local/lib/python2.7/dist-packages/flask/app.py", line 1614, in full_dispatch_request, referer: http://www.zachflask.tk/
[Wed Sep 13 18:23:53.650961 2017] [wsgi:error] [pid 25374] [client 209.54.86.83:50014]     rv = self.handle_user_exception(e), referer: http://www.zachflask.tk/
[Wed Sep 13 18:23:53.650963 2017] [wsgi:error] [pid 25374] [client 209.54.86.83:50014]   File "/usr/local/lib/python2.7/dist-packages/flask/app.py", line 1517, in handle_user_exception, referer: http://www.zachflask.tk/
[Wed Sep 13 18:23:53.650965 2017] [wsgi:error] [pid 25374] [client 209.54.86.83:50014]     reraise(exc_type, exc_value, tb), referer: http://www.zachflask.tk/
[Wed Sep 13 18:23:53.650967 2017] [wsgi:error] [pid 25374] [client 209.54.86.83:50014]   File "/usr/local/lib/python2.7/dist-packages/flask/app.py", line 1612, in full_dispatch_request, referer: http://www.zachflask.tk/
[Wed Sep 13 18:23:53.650979 2017] [wsgi:error] [pid 25374] [client 209.54.86.83:50014]     rv = self.dispatch_request(), referer: http://www.zachflask.tk/
[Wed Sep 13 18:23:53.650981 2017] [wsgi:error] [pid 25374] [client 209.54.86.83:50014]   File "/usr/local/lib/python2.7/dist-packages/flask/app.py", line 1598, in dispatch_request, referer: http://www.zachflask.tk/
[Wed Sep 13 18:23:53.650983 2017] [wsgi:error] [pid 25374] [client 209.54.86.83:50014]     return self.view_functions[rule.endpoint](**req.view_args), referer: http://www.zachflask.tk/
[Wed Sep 13 18:23:53.650985 2017] [wsgi:error] [pid 25374] [client 209.54.86.83:50014]   File "/var/www/FlaskApp/FlaskApp/FlaskApp.py", line 76, in add_entry, referer: http://www.zachflask.tk/
[Wed Sep 13 18:23:53.650987 2017] [wsgi:error] [pid 25374] [client 209.54.86.83:50014]     [request.form['title'], request.form['text']]), referer: http://www.zachflask.tk/
[Wed Sep 13 18:23:53.650989 2017] [wsgi:error] [pid 25374] [client 209.54.86.83:50014] OperationalError: unable to open database file, referer: http://www.zachflask.tk/
[Wed Sep 13 18:26:12.694467 2017] [wsgi:error] [pid 25497] [client 209.54.86.83:50024] [2017-09-13 18:26:12,693] ERROR in app: Exception on /add [POST], referer: http://www.zachflask.tk/
[Wed Sep 13 18:26:12.694499 2017] [wsgi:error] [pid 25497] [client 209.54.86.83:50024] Traceback (most recent call last):, referer: http://www.zachflask.tk/
[Wed Sep 13 18:26:12.694502 2017] [wsgi:error] [pid 25497] [client 209.54.86.83:50024]   File "/usr/local/lib/python2.7/dist-packages/flask/app.py", line 1982, in wsgi_app, referer: http://www.zachflask.tk/
[Wed Sep 13 18:26:12.694504 2017] [wsgi:error] [pid 25497] [client 209.54.86.83:50024]     response = self.full_dispatch_request(), referer: http://www.zachflask.tk/
[Wed Sep 13 18:26:12.694506 2017] [wsgi:error] [pid 25497] [client 209.54.86.83:50024]   File "/usr/local/lib/python2.7/dist-packages/flask/app.py", line 1614, in full_dispatch_request, referer: http://www.zachflask.tk/
[Wed Sep 13 18:26:12.694509 2017] [wsgi:error] [pid 25497] [client 209.54.86.83:50024]     rv = self.handle_user_exception(e), referer: http://www.zachflask.tk/
[Wed Sep 13 18:26:12.694511 2017] [wsgi:error] [pid 25497] [client 209.54.86.83:50024]   File "/usr/local/lib/python2.7/dist-packages/flask/app.py", line 1517, in handle_user_exception, referer: http://www.zachflask.tk/
[Wed Sep 13 18:26:12.694513 2017] [wsgi:error] [pid 25497] [client 209.54.86.83:50024]     reraise(exc_type, exc_value, tb), referer: http://www.zachflask.tk/
[Wed Sep 13 18:26:12.694515 2017] [wsgi:error] [pid 25497] [client 209.54.86.83:50024]   File "/usr/local/lib/python2.7/dist-packages/flask/app.py", line 1612, in full_dispatch_request, referer: http://www.zachflask.tk/
[Wed Sep 13 18:26:12.694517 2017] [wsgi:error] [pid 25497] [client 209.54.86.83:50024]     rv = self.dispatch_request(), referer: http://www.zachflask.tk/
[Wed Sep 13 18:26:12.694519 2017] [wsgi:error] [pid 25497] [client 209.54.86.83:50024]   File "/usr/local/lib/python2.7/dist-packages/flask/app.py", line 1598, in dispatch_request, referer: http://www.zachflask.tk/
[Wed Sep 13 18:26:12.694521 2017] [wsgi:error] [pid 25497] [client 209.54.86.83:50024]     return self.view_functions[rule.endpoint](**req.view_args), referer: http://www.zachflask.tk/
[Wed Sep 13 18:26:12.694523 2017] [wsgi:error] [pid 25497] [client 209.54.86.83:50024]   File "/var/www/FlaskApp/FlaskApp/FlaskApp.py", line 76, in add_entry, referer: http://www.zachflask.tk/
[Wed Sep 13 18:26:12.694525 2017] [wsgi:error] [pid 25497] [client 209.54.86.83:50024]     [request.form['title'], request.form['text']]), referer: http://www.zachflask.tk/
[Wed Sep 13 18:26:12.694526 2017] [wsgi:error] [pid 25497] [client 209.54.86.83:50024] OperationalError: unable to open database file, referer: http://www.zachflask.tk/
[Wed Sep 13 18:29:52.847190 2017] [wsgi:error] [pid 25649] [client 209.54.86.83:50034] [2017-09-13 18:29:52,846] ERROR in app: Exception on /add [POST], referer: http://www.zachflask.tk/
[Wed Sep 13 18:29:52.847235 2017] [wsgi:error] [pid 25649] [client 209.54.86.83:50034] Traceback (most recent call last):, referer: http://www.zachflask.tk/
[Wed Sep 13 18:29:52.847238 2017] [wsgi:error] [pid 25649] [client 209.54.86.83:50034]   File "/usr/local/lib/python2.7/dist-packages/flask/app.py", line 1982, in wsgi_app, referer: http://www.zachflask.tk/
[Wed Sep 13 18:29:52.847240 2017] [wsgi:error] [pid 25649] [client 209.54.86.83:50034]     response = self.full_dispatch_request(), referer: http://www.zachflask.tk/
[Wed Sep 13 18:29:52.847242 2017] [wsgi:error] [pid 25649] [client 209.54.86.83:50034]   File "/usr/local/lib/python2.7/dist-packages/flask/app.py", line 1614, in full_dispatch_request, referer: http://www.zachflask.tk/
[Wed Sep 13 18:29:52.847244 2017] [wsgi:error] [pid 25649] [client 209.54.86.83:50034]     rv = self.handle_user_exception(e), referer: http://www.zachflask.tk/
[Wed Sep 13 18:29:52.847246 2017] [wsgi:error] [pid 25649] [client 209.54.86.83:50034]   File "/usr/local/lib/python2.7/dist-packages/flask/app.py", line 1517, in handle_user_exception, referer: http://www.zachflask.tk/
[Wed Sep 13 18:29:52.847251 2017] [wsgi:error] [pid 25649] [client 209.54.86.83:50034]     reraise(exc_type, exc_value, tb), referer: http://www.zachflask.tk/
[Wed Sep 13 18:29:52.847253 2017] [wsgi:error] [pid 25649] [client 209.54.86.83:50034]   File "/usr/local/lib/python2.7/dist-packages/flask/app.py", line 1612, in full_dispatch_request, referer: http://www.zachflask.tk/
[Wed Sep 13 18:29:52.847255 2017] [wsgi:error] [pid 25649] [client 209.54.86.83:50034]     rv = self.dispatch_request(), referer: http://www.zachflask.tk/
[Wed Sep 13 18:29:52.847257 2017] [wsgi:error] [pid 25649] [client 209.54.86.83:50034]   File "/usr/local/lib/python2.7/dist-packages/flask/app.py", line 1598, in dispatch_request, referer: http://www.zachflask.tk/
[Wed Sep 13 18:29:52.847259 2017] [wsgi:error] [pid 25649] [client 209.54.86.83:50034]     return self.view_functions[rule.endpoint](**req.view_args), referer: http://www.zachflask.tk/
[Wed Sep 13 18:29:52.847260 2017] [wsgi:error] [pid 25649] [client 209.54.86.83:50034]   File "/var/www/FlaskApp/FlaskApp/FlaskApp.py", line 76, in add_entry, referer: http://www.zachflask.tk/
[Wed Sep 13 18:29:52.847262 2017] [wsgi:error] [pid 25649] [client 209.54.86.83:50034]     [request.form['title'], request.form['text']]), referer: http://www.zachflask.tk/
[Wed Sep 13 18:29:52.847264 2017] [wsgi:error] [pid 25649] [client 209.54.86.83:50034] OperationalError: unable to open database file, referer: http://www.zachflask.tk/
[Wed Sep 13 18:44:24.889330 2017] [wsgi:error] [pid 26087] [client 209.54.86.83:50201] [2017-09-13 18:44:24,888] ERROR in app: Exception on /add [POST], referer: http://www.zachflask.tk/
[Wed Sep 13 18:44:24.889368 2017] [wsgi:error] [pid 26087] [client 209.54.86.83:50201] Traceback (most recent call last):, referer: http://www.zachflask.tk/
[Wed Sep 13 18:44:24.889371 2017] [wsgi:error] [pid 26087] [client 209.54.86.83:50201]   File "/usr/local/lib/python2.7/dist-packages/flask/app.py", line 1982, in wsgi_app, referer: http://www.zachflask.tk/
[Wed Sep 13 18:44:24.889373 2017] [wsgi:error] [pid 26087] [client 209.54.86.83:50201]     response = self.full_dispatch_request(), referer: http://www.zachflask.tk/
[Wed Sep 13 18:44:24.889376 2017] [wsgi:error] [pid 26087] [client 209.54.86.83:50201]   File "/usr/local/lib/python2.7/dist-packages/flask/app.py", line 1614, in full_dispatch_request, referer: http://www.zachflask.tk/
[Wed Sep 13 18:44:24.889378 2017] [wsgi:error] [pid 26087] [client 209.54.86.83:50201]     rv = self.handle_user_exception(e), referer: http://www.zachflask.tk/
[Wed Sep 13 18:44:24.889380 2017] [wsgi:error] [pid 26087] [client 209.54.86.83:50201]   File "/usr/local/lib/python2.7/dist-packages/flask/app.py", line 1517, in handle_user_exception, referer: http://www.zachflask.tk/
[Wed Sep 13 18:44:24.889383 2017] [wsgi:error] [pid 26087] [client 209.54.86.83:50201]     reraise(exc_type, exc_value, tb), referer: http://www.zachflask.tk/
[Wed Sep 13 18:44:24.889396 2017] [wsgi:error] [pid 26087] [client 209.54.86.83:50201]   File "/usr/local/lib/python2.7/dist-packages/flask/app.py", line 1612, in full_dispatch_request, referer: http://www.zachflask.tk/
[Wed Sep 13 18:44:24.889398 2017] [wsgi:error] [pid 26087] [client 209.54.86.83:50201]     rv = self.dispatch_request(), referer: http://www.zachflask.tk/
[Wed Sep 13 18:44:24.889400 2017] [wsgi:error] [pid 26087] [client 209.54.86.83:50201]   File "/usr/local/lib/python2.7/dist-packages/flask/app.py", line 1598, in dispatch_request, referer: http://www.zachflask.tk/
[Wed Sep 13 18:44:24.889402 2017] [wsgi:error] [pid 26087] [client 209.54.86.83:50201]     return self.view_functions[rule.endpoint](**req.view_args), referer: http://www.zachflask.tk/
[Wed Sep 13 18:44:24.889403 2017] [wsgi:error] [pid 26087] [client 209.54.86.83:50201]   File "/var/www/FlaskApp/FlaskApp/FlaskApp.py", line 76, in add_entry, referer: http://www.zachflask.tk/
[Wed Sep 13 18:44:24.889405 2017] [wsgi:error] [pid 26087] [client 209.54.86.83:50201]     [request.form['title'], request.form['text']]), referer: http://www.zachflask.tk/
[Wed Sep 13 18:44:24.889407 2017] [wsgi:error] [pid 26087] [client 209.54.86.83:50201] OperationalError: unable to open database file, referer: http://www.zachflask.tk/
[Wed Sep 13 19:07:19.480140 2017] [wsgi:error] [pid 26086] [client 209.54.86.83:50320] [2017-09-13 19:07:19,479] ERROR in app: Exception on /add [POST], referer: http://www.zachflask.tk/
[Wed Sep 13 19:07:19.480176 2017] [wsgi:error] [pid 26086] [client 209.54.86.83:50320] Traceback (most recent call last):, referer: http://www.zachflask.tk/
[Wed Sep 13 19:07:19.480180 2017] [wsgi:error] [pid 26086] [client 209.54.86.83:50320]   File "/usr/local/lib/python2.7/dist-packages/flask/app.py", line 1982, in wsgi_app, referer: http://www.zachflask.tk/
[Wed Sep 13 19:07:19.480182 2017] [wsgi:error] [pid 26086] [client 209.54.86.83:50320]     response = self.full_dispatch_request(), referer: http://www.zachflask.tk/
[Wed Sep 13 19:07:19.480184 2017] [wsgi:error] [pid 26086] [client 209.54.86.83:50320]   File "/usr/local/lib/python2.7/dist-packages/flask/app.py", line 1614, in full_dispatch_request, referer: http://www.zachflask.tk/
[Wed Sep 13 19:07:19.480187 2017] [wsgi:error] [pid 26086] [client 209.54.86.83:50320]     rv = self.handle_user_exception(e), referer: http://www.zachflask.tk/
[Wed Sep 13 19:07:19.480189 2017] [wsgi:error] [pid 26086] [client 209.54.86.83:50320]   File "/usr/local/lib/python2.7/dist-packages/flask/app.py", line 1517, in handle_user_exception, referer: http://www.zachflask.tk/
[Wed Sep 13 19:07:19.480192 2017] [wsgi:error] [pid 26086] [client 209.54.86.83:50320]     reraise(exc_type, exc_value, tb), referer: http://www.zachflask.tk/
[Wed Sep 13 19:07:19.480194 2017] [wsgi:error] [pid 26086] [client 209.54.86.83:50320]   File "/usr/local/lib/python2.7/dist-packages/flask/app.py", line 1612, in full_dispatch_request, referer: http://www.zachflask.tk/
[Wed Sep 13 19:07:19.480196 2017] [wsgi:error] [pid 26086] [client 209.54.86.83:50320]     rv = self.dispatch_request(), referer: http://www.zachflask.tk/
[Wed Sep 13 19:07:19.480198 2017] [wsgi:error] [pid 26086] [client 209.54.86.83:50320]   File "/usr/local/lib/python2.7/dist-packages/flask/app.py", line 1598, in dispatch_request, referer: http://www.zachflask.tk/
[Wed Sep 13 19:07:19.480200 2017] [wsgi:error] [pid 26086] [client 209.54.86.83:50320]     return self.view_functions[rule.endpoint](**req.view_args), referer: http://www.zachflask.tk/
[Wed Sep 13 19:07:19.480202 2017] [wsgi:error] [pid 26086] [client 209.54.86.83:50320]   File "/var/www/FlaskApp/FlaskApp/FlaskApp.py", line 76, in add_entry, referer: http://www.zachflask.tk/
[Wed Sep 13 19:07:19.480204 2017] [wsgi:error] [pid 26086] [client 209.54.86.83:50320]     [request.form['title'], request.form['text']]), referer: http://www.zachflask.tk/
[Wed Sep 13 19:07:19.480206 2017] [wsgi:error] [pid 26086] [client 209.54.86.83:50320] OperationalError: attempt to write a readonly database, referer: http://www.zachflask.tk/
[Wed Sep 13 19:08:55.925021 2017] [wsgi:error] [pid 26306] [client 209.54.86.83:50330] [2017-09-13 19:08:55,924] ERROR in app: Exception on /add [POST], referer: http://www.zachflask.tk/
[Wed Sep 13 19:08:55.925061 2017] [wsgi:error] [pid 26306] [client 209.54.86.83:50330] Traceback (most recent call last):, referer: http://www.zachflask.tk/
[Wed Sep 13 19:08:55.925064 2017] [wsgi:error] [pid 26306] [client 209.54.86.83:50330]   File "/usr/local/lib/python2.7/dist-packages/flask/app.py", line 1982, in wsgi_app, referer: http://www.zachflask.tk/
[Wed Sep 13 19:08:55.925067 2017] [wsgi:error] [pid 26306] [client 209.54.86.83:50330]     response = self.full_dispatch_request(), referer: http://www.zachflask.tk/
[Wed Sep 13 19:08:55.925069 2017] [wsgi:error] [pid 26306] [client 209.54.86.83:50330]   File "/usr/local/lib/python2.7/dist-packages/flask/app.py", line 1614, in full_dispatch_request, referer: http://www.zachflask.tk/
[Wed Sep 13 19:08:55.925072 2017] [wsgi:error] [pid 26306] [client 209.54.86.83:50330]     rv = self.handle_user_exception(e), referer: http://www.zachflask.tk/
[Wed Sep 13 19:08:55.925074 2017] [wsgi:error] [pid 26306] [client 209.54.86.83:50330]   File "/usr/local/lib/python2.7/dist-packages/flask/app.py", line 1517, in handle_user_exception, referer: http://www.zachflask.tk/
[Wed Sep 13 19:08:55.925076 2017] [wsgi:error] [pid 26306] [client 209.54.86.83:50330]     reraise(exc_type, exc_value, tb), referer: http://www.zachflask.tk/
[Wed Sep 13 19:08:55.925078 2017] [wsgi:error] [pid 26306] [client 209.54.86.83:50330]   File "/usr/local/lib/python2.7/dist-packages/flask/app.py", line 1612, in full_dispatch_request, referer: http://www.zachflask.tk/
[Wed Sep 13 19:08:55.925080 2017] [wsgi:error] [pid 26306] [client 209.54.86.83:50330]     rv = self.dispatch_request(), referer: http://www.zachflask.tk/
[Wed Sep 13 19:08:55.925082 2017] [wsgi:error] [pid 26306] [client 209.54.86.83:50330]   File "/usr/local/lib/python2.7/dist-packages/flask/app.py", line 1598, in dispatch_request, referer: http://www.zachflask.tk/
[Wed Sep 13 19:08:55.925084 2017] [wsgi:error] [pid 26306] [client 209.54.86.83:50330]     return self.view_functions[rule.endpoint](**req.view_args), referer: http://www.zachflask.tk/
[Wed Sep 13 19:08:55.925086 2017] [wsgi:error] [pid 26306] [client 209.54.86.83:50330]   File "/var/www/FlaskApp/FlaskApp/FlaskApp.py", line 76, in add_entry, referer: http://www.zachflask.tk/
[Wed Sep 13 19:08:55.925088 2017] [wsgi:error] [pid 26306] [client 209.54.86.83:50330]     [request.form['title'], request.form['text']]), referer: http://www.zachflask.tk/
[Wed Sep 13 19:08:55.925090 2017] [wsgi:error] [pid 26306] [client 209.54.86.83:50330] OperationalError: unable to open database file, referer: http://www.zachflask.tk/
[Wed Sep 13 19:13:26.664279 2017] [wsgi:error] [pid 26506] [client 209.54.86.83:50355] [2017-09-13 19:13:26,663] ERROR in app: Exception on / [GET]
[Wed Sep 13 19:13:26.664318 2017] [wsgi:error] [pid 26506] [client 209.54.86.83:50355] Traceback (most recent call last):
[Wed Sep 13 19:13:26.664321 2017] [wsgi:error] [pid 26506] [client 209.54.86.83:50355]   File "/usr/local/lib/python2.7/dist-packages/flask/app.py", line 1982, in wsgi_app
[Wed Sep 13 19:13:26.664324 2017] [wsgi:error] [pid 26506] [client 209.54.86.83:50355]     response = self.full_dispatch_request()
[Wed Sep 13 19:13:26.664326 2017] [wsgi:error] [pid 26506] [client 209.54.86.83:50355]   File "/usr/local/lib/python2.7/dist-packages/flask/app.py", line 1614, in full_dispatch_request
[Wed Sep 13 19:13:26.664329 2017] [wsgi:error] [pid 26506] [client 209.54.86.83:50355]     rv = self.handle_user_exception(e)
[Wed Sep 13 19:13:26.664331 2017] [wsgi:error] [pid 26506] [client 209.54.86.83:50355]   File "/usr/local/lib/python2.7/dist-packages/flask/app.py", line 1517, in handle_user_exception
[Wed Sep 13 19:13:26.664333 2017] [wsgi:error] [pid 26506] [client 209.54.86.83:50355]     reraise(exc_type, exc_value, tb)
[Wed Sep 13 19:13:26.664335 2017] [wsgi:error] [pid 26506] [client 209.54.86.83:50355]   File "/usr/local/lib/python2.7/dist-packages/flask/app.py", line 1612, in full_dispatch_request
[Wed Sep 13 19:13:26.664346 2017] [wsgi:error] [pid 26506] [client 209.54.86.83:50355]     rv = self.dispatch_request()
[Wed Sep 13 19:13:26.664348 2017] [wsgi:error] [pid 26506] [client 209.54.86.83:50355]   File "/usr/local/lib/python2.7/dist-packages/flask/app.py", line 1598, in dispatch_request
[Wed Sep 13 19:13:26.664350 2017] [wsgi:error] [pid 26506] [client 209.54.86.83:50355]     return self.view_functions[rule.endpoint](**req.view_args)
[Wed Sep 13 19:13:26.664352 2017] [wsgi:error] [pid 26506] [client 209.54.86.83:50355]   File "/var/www/FlaskApp/FlaskApp/FlaskApp.py", line 64, in show_entries
[Wed Sep 13 19:13:26.664354 2017] [wsgi:error] [pid 26506] [client 209.54.86.83:50355]     db = get_db()
[Wed Sep 13 19:13:26.664355 2017] [wsgi:error] [pid 26506] [client 209.54.86.83:50355]   File "/var/www/FlaskApp/FlaskApp/FlaskApp.py", line 32, in get_db
[Wed Sep 13 19:13:26.664357 2017] [wsgi:error] [pid 26506] [client 209.54.86.83:50355]     g.sqlite_db = connect_db()
[Wed Sep 13 19:13:26.664359 2017] [wsgi:error] [pid 26506] [client 209.54.86.83:50355]   File "/var/www/FlaskApp/FlaskApp/FlaskApp.py", line 24, in connect_db
[Wed Sep 13 19:13:26.664361 2017] [wsgi:error] [pid 26506] [client 209.54.86.83:50355]     rv = sqlite3.connect(app.config['DATABASE'])
[Wed Sep 13 19:13:26.664362 2017] [wsgi:error] [pid 26506] [client 209.54.86.83:50355] OperationalError: unable to open database file
[Wed Sep 13 19:13:30.073697 2017] [wsgi:error] [pid 26507] [client 209.54.86.83:50356] [2017-09-13 19:13:30,073] ERROR in app: Exception on / [GET]
[Wed Sep 13 19:13:30.073733 2017] [wsgi:error] [pid 26507] [client 209.54.86.83:50356] Traceback (most recent call last):
[Wed Sep 13 19:13:30.073736 2017] [wsgi:error] [pid 26507] [client 209.54.86.83:50356]   File "/usr/local/lib/python2.7/dist-packages/flask/app.py", line 1982, in wsgi_app
[Wed Sep 13 19:13:30.073738 2017] [wsgi:error] [pid 26507] [client 209.54.86.83:50356]     response = self.full_dispatch_request()
[Wed Sep 13 19:13:30.073740 2017] [wsgi:error] [pid 26507] [client 209.54.86.83:50356]   File "/usr/local/lib/python2.7/dist-packages/flask/app.py", line 1614, in full_dispatch_request
[Wed Sep 13 19:13:30.073743 2017] [wsgi:error] [pid 26507] [client 209.54.86.83:50356]     rv = self.handle_user_exception(e)
[Wed Sep 13 19:13:30.073745 2017] [wsgi:error] [pid 26507] [client 209.54.86.83:50356]   File "/usr/local/lib/python2.7/dist-packages/flask/app.py", line 1517, in handle_user_exception
[Wed Sep 13 19:13:30.073747 2017] [wsgi:error] [pid 26507] [client 209.54.86.83:50356]     reraise(exc_type, exc_value, tb)
[Wed Sep 13 19:13:30.073748 2017] [wsgi:error] [pid 26507] [client 209.54.86.83:50356]   File "/usr/local/lib/python2.7/dist-packages/flask/app.py", line 1612, in full_dispatch_request
[Wed Sep 13 19:13:30.073750 2017] [wsgi:error] [pid 26507] [client 209.54.86.83:50356]     rv = self.dispatch_request()
[Wed Sep 13 19:13:30.073752 2017] [wsgi:error] [pid 26507] [client 209.54.86.83:50356]   File "/usr/local/lib/python2.7/dist-packages/flask/app.py", line 1598, in dispatch_request
[Wed Sep 13 19:13:30.073754 2017] [wsgi:error] [pid 26507] [client 209.54.86.83:50356]     return self.view_functions[rule.endpoint](**req.view_args)
[Wed Sep 13 19:13:30.073755 2017] [wsgi:error] [pid 26507] [client 209.54.86.83:50356]   File "/var/www/FlaskApp/FlaskApp/FlaskApp.py", line 64, in show_entries
[Wed Sep 13 19:13:30.073757 2017] [wsgi:error] [pid 26507] [client 209.54.86.83:50356]     db = get_db()
[Wed Sep 13 19:13:30.073759 2017] [wsgi:error] [pid 26507] [client 209.54.86.83:50356]   File "/var/www/FlaskApp/FlaskApp/FlaskApp.py", line 32, in get_db
[Wed Sep 13 19:13:30.073760 2017] [wsgi:error] [pid 26507] [client 209.54.86.83:50356]     g.sqlite_db = connect_db()
[Wed Sep 13 19:13:30.073762 2017] [wsgi:error] [pid 26507] [client 209.54.86.83:50356]   File "/var/www/FlaskApp/FlaskApp/FlaskApp.py", line 24, in connect_db
[Wed Sep 13 19:13:30.073764 2017] [wsgi:error] [pid 26507] [client 209.54.86.83:50356]     rv = sqlite3.connect(app.config['DATABASE'])
[Wed Sep 13 19:13:30.073777 2017] [wsgi:error] [pid 26507] [client 209.54.86.83:50356] OperationalError: unable to open database file
[Wed Sep 13 19:14:41.113596 2017] [wsgi:error] [pid 26625] [client 209.54.86.83:50366] [2017-09-13 19:14:41,112] ERROR in app: Exception on /add [POST], referer: http://www.zachflask.tk/
[Wed Sep 13 19:14:41.113640 2017] [wsgi:error] [pid 26625] [client 209.54.86.83:50366] Traceback (most recent call last):, referer: http://www.zachflask.tk/
[Wed Sep 13 19:14:41.113643 2017] [wsgi:error] [pid 26625] [client 209.54.86.83:50366]   File "/usr/local/lib/python2.7/dist-packages/flask/app.py", line 1982, in wsgi_app, referer: http://www.zachflask.tk/
[Wed Sep 13 19:14:41.113645 2017] [wsgi:error] [pid 26625] [client 209.54.86.83:50366]     response = self.full_dispatch_request(), referer: http://www.zachflask.tk/
[Wed Sep 13 19:14:41.113648 2017] [wsgi:error] [pid 26625] [client 209.54.86.83:50366]   File "/usr/local/lib/python2.7/dist-packages/flask/app.py", line 1614, in full_dispatch_request, referer: http://www.zachflask.tk/
[Wed Sep 13 19:14:41.113650 2017] [wsgi:error] [pid 26625] [client 209.54.86.83:50366]     rv = self.handle_user_exception(e), referer: http://www.zachflask.tk/
[Wed Sep 13 19:14:41.113652 2017] [wsgi:error] [pid 26625] [client 209.54.86.83:50366]   File "/usr/local/lib/python2.7/dist-packages/flask/app.py", line 1517, in handle_user_exception, referer: http://www.zachflask.tk/
[Wed Sep 13 19:14:41.113655 2017] [wsgi:error] [pid 26625] [client 209.54.86.83:50366]     reraise(exc_type, exc_value, tb), referer: http://www.zachflask.tk/
[Wed Sep 13 19:14:41.113657 2017] [wsgi:error] [pid 26625] [client 209.54.86.83:50366]   File "/usr/local/lib/python2.7/dist-packages/flask/app.py", line 1612, in full_dispatch_request, referer: http://www.zachflask.tk/
[Wed Sep 13 19:14:41.113659 2017] [wsgi:error] [pid 26625] [client 209.54.86.83:50366]     rv = self.dispatch_request(), referer: http://www.zachflask.tk/
[Wed Sep 13 19:14:41.113661 2017] [wsgi:error] [pid 26625] [client 209.54.86.83:50366]   File "/usr/local/lib/python2.7/dist-packages/flask/app.py", line 1598, in dispatch_request, referer: http://www.zachflask.tk/
[Wed Sep 13 19:14:41.113663 2017] [wsgi:error] [pid 26625] [client 209.54.86.83:50366]     return self.view_functions[rule.endpoint](**req.view_args), referer: http://www.zachflask.tk/
[Wed Sep 13 19:14:41.113665 2017] [wsgi:error] [pid 26625] [client 209.54.86.83:50366]   File "/var/www/FlaskApp/FlaskApp/FlaskApp.py", line 76, in add_entry, referer: http://www.zachflask.tk/
[Wed Sep 13 19:14:41.113667 2017] [wsgi:error] [pid 26625] [client 209.54.86.83:50366]     [request.form['title'], request.form['text']]), referer: http://www.zachflask.tk/
[Wed Sep 13 19:14:41.113669 2017] [wsgi:error] [pid 26625] [client 209.54.86.83:50366] OperationalError: unable to open database file, referer: http://www.zachflask.tk/
[Wed Sep 13 19:17:12.909088 2017] [wsgi:error] [pid 26757] [client 209.54.86.83:50384] [2017-09-13 19:17:12,908] ERROR in app: Exception on /add [POST], referer: http://www.zachflask.tk/
[Wed Sep 13 19:17:12.909122 2017] [wsgi:error] [pid 26757] [client 209.54.86.83:50384] Traceback (most recent call last):, referer: http://www.zachflask.tk/
[Wed Sep 13 19:17:12.909125 2017] [wsgi:error] [pid 26757] [client 209.54.86.83:50384]   File "/usr/local/lib/python2.7/dist-packages/flask/app.py", line 1982, in wsgi_app, referer: http://www.zachflask.tk/
[Wed Sep 13 19:17:12.909127 2017] [wsgi:error] [pid 26757] [client 209.54.86.83:50384]     response = self.full_dispatch_request(), referer: http://www.zachflask.tk/
[Wed Sep 13 19:17:12.909130 2017] [wsgi:error] [pid 26757] [client 209.54.86.83:50384]   File "/usr/local/lib/python2.7/dist-packages/flask/app.py", line 1614, in full_dispatch_request, referer: http://www.zachflask.tk/
[Wed Sep 13 19:17:12.909132 2017] [wsgi:error] [pid 26757] [client 209.54.86.83:50384]     rv = self.handle_user_exception(e), referer: http://www.zachflask.tk/
[Wed Sep 13 19:17:12.909144 2017] [wsgi:error] [pid 26757] [client 209.54.86.83:50384]   File "/usr/local/lib/python2.7/dist-packages/flask/app.py", line 1517, in handle_user_exception, referer: http://www.zachflask.tk/
[Wed Sep 13 19:17:12.909146 2017] [wsgi:error] [pid 26757] [client 209.54.86.83:50384]     reraise(exc_type, exc_value, tb), referer: http://www.zachflask.tk/
[Wed Sep 13 19:17:12.909148 2017] [wsgi:error] [pid 26757] [client 209.54.86.83:50384]   File "/usr/local/lib/python2.7/dist-packages/flask/app.py", line 1612, in full_dispatch_request, referer: http://www.zachflask.tk/
[Wed Sep 13 19:17:12.909150 2017] [wsgi:error] [pid 26757] [client 209.54.86.83:50384]     rv = self.dispatch_request(), referer: http://www.zachflask.tk/
[Wed Sep 13 19:17:12.909152 2017] [wsgi:error] [pid 26757] [client 209.54.86.83:50384]   File "/usr/local/lib/python2.7/dist-packages/flask/app.py", line 1598, in dispatch_request, referer: http://www.zachflask.tk/
[Wed Sep 13 19:17:12.909154 2017] [wsgi:error] [pid 26757] [client 209.54.86.83:50384]     return self.view_functions[rule.endpoint](**req.view_args), referer: http://www.zachflask.tk/
[Wed Sep 13 19:17:12.909155 2017] [wsgi:error] [pid 26757] [client 209.54.86.83:50384]   File "/var/www/FlaskApp/FlaskApp/FlaskApp.py", line 76, in add_entry, referer: http://www.zachflask.tk/
[Wed Sep 13 19:17:12.909157 2017] [wsgi:error] [pid 26757] [client 209.54.86.83:50384]     [request.form['title'], request.form['text']]), referer: http://www.zachflask.tk/
[Wed Sep 13 19:17:12.909159 2017] [wsgi:error] [pid 26757] [client 209.54.86.83:50384] OperationalError: unable to open database file, referer: http://www.zachflask.tk/
[Wed Sep 13 19:19:19.066534 2017] [wsgi:error] [pid 26895] [client 209.54.86.83:50392] [2017-09-13 19:19:19,065] ERROR in app: Exception on /add [POST], referer: http://www.zachflask.tk/
[Wed Sep 13 19:19:19.066572 2017] [wsgi:error] [pid 26895] [client 209.54.86.83:50392] Traceback (most recent call last):, referer: http://www.zachflask.tk/
[Wed Sep 13 19:19:19.066575 2017] [wsgi:error] [pid 26895] [client 209.54.86.83:50392]   File "/usr/local/lib/python2.7/dist-packages/flask/app.py", line 1982, in wsgi_app, referer: http://www.zachflask.tk/
[Wed Sep 13 19:19:19.066578 2017] [wsgi:error] [pid 26895] [client 209.54.86.83:50392]     response = self.full_dispatch_request(), referer: http://www.zachflask.tk/
[Wed Sep 13 19:19:19.066580 2017] [wsgi:error] [pid 26895] [client 209.54.86.83:50392]   File "/usr/local/lib/python2.7/dist-packages/flask/app.py", line 1614, in full_dispatch_request, referer: http://www.zachflask.tk/
[Wed Sep 13 19:19:19.066583 2017] [wsgi:error] [pid 26895] [client 209.54.86.83:50392]     rv = self.handle_user_exception(e), referer: http://www.zachflask.tk/
[Wed Sep 13 19:19:19.066585 2017] [wsgi:error] [pid 26895] [client 209.54.86.83:50392]   File "/usr/local/lib/python2.7/dist-packages/flask/app.py", line 1517, in handle_user_exception, referer: http://www.zachflask.tk/
[Wed Sep 13 19:19:19.066587 2017] [wsgi:error] [pid 26895] [client 209.54.86.83:50392]     reraise(exc_type, exc_value, tb), referer: http://www.zachflask.tk/
[Wed Sep 13 19:19:19.066589 2017] [wsgi:error] [pid 26895] [client 209.54.86.83:50392]   File "/usr/local/lib/python2.7/dist-packages/flask/app.py", line 1612, in full_dispatch_request, referer: http://www.zachflask.tk/
[Wed Sep 13 19:19:19.066591 2017] [wsgi:error] [pid 26895] [client 209.54.86.83:50392]     rv = self.dispatch_request(), referer: http://www.zachflask.tk/
[Wed Sep 13 19:19:19.066593 2017] [wsgi:error] [pid 26895] [client 209.54.86.83:50392]   File "/usr/local/lib/python2.7/dist-packages/flask/app.py", line 1598, in dispatch_request, referer: http://www.zachflask.tk/
[Wed Sep 13 19:19:19.066595 2017] [wsgi:error] [pid 26895] [client 209.54.86.83:50392]     return self.view_functions[rule.endpoint](**req.view_args), referer: http://www.zachflask.tk/
[Wed Sep 13 19:19:19.066597 2017] [wsgi:error] [pid 26895] [client 209.54.86.83:50392]   File "/var/www/FlaskApp/FlaskApp/FlaskApp.py", line 76, in add_entry, referer: http://www.zachflask.tk/
[Wed Sep 13 19:19:19.066609 2017] [wsgi:error] [pid 26895] [client 209.54.86.83:50392]     [request.form['title'], request.form['text']]), referer: http://www.zachflask.tk/
[Wed Sep 13 19:19:19.066611 2017] [wsgi:error] [pid 26895] [client 209.54.86.83:50392] OperationalError: unable to open database file, referer: http://www.zachflask.tk/
[Wed Sep 13 19:21:26.398909 2017] [wsgi:error] [pid 27046] [client 209.54.86.83:50401] [2017-09-13 19:21:26,398] ERROR in app: Exception on /add [POST], referer: http://www.zachflask.tk/
[Wed Sep 13 19:21:26.398937 2017] [wsgi:error] [pid 27046] [client 209.54.86.83:50401] Traceback (most recent call last):, referer: http://www.zachflask.tk/
[Wed Sep 13 19:21:26.398940 2017] [wsgi:error] [pid 27046] [client 209.54.86.83:50401]   File "/usr/local/lib/python2.7/dist-packages/flask/app.py", line 1982, in wsgi_app, referer: http://www.zachflask.tk/
[Wed Sep 13 19:21:26.398942 2017] [wsgi:error] [pid 27046] [client 209.54.86.83:50401]     response = self.full_dispatch_request(), referer: http://www.zachflask.tk/
[Wed Sep 13 19:21:26.398945 2017] [wsgi:error] [pid 27046] [client 209.54.86.83:50401]   File "/usr/local/lib/python2.7/dist-packages/flask/app.py", line 1614, in full_dispatch_request, referer: http://www.zachflask.tk/
[Wed Sep 13 19:21:26.398947 2017] [wsgi:error] [pid 27046] [client 209.54.86.83:50401]     rv = self.handle_user_exception(e), referer: http://www.zachflask.tk/
[Wed Sep 13 19:21:26.398949 2017] [wsgi:error] [pid 27046] [client 209.54.86.83:50401]   File "/usr/local/lib/python2.7/dist-packages/flask/app.py", line 1517, in handle_user_exception, referer: http://www.zachflask.tk/
[Wed Sep 13 19:21:26.398951 2017] [wsgi:error] [pid 27046] [client 209.54.86.83:50401]     reraise(exc_type, exc_value, tb), referer: http://www.zachflask.tk/
[Wed Sep 13 19:21:26.398953 2017] [wsgi:error] [pid 27046] [client 209.54.86.83:50401]   File "/usr/local/lib/python2.7/dist-packages/flask/app.py", line 1612, in full_dispatch_request, referer: http://www.zachflask.tk/
[Wed Sep 13 19:21:26.398956 2017] [wsgi:error] [pid 27046] [client 209.54.86.83:50401]     rv = self.dispatch_request(), referer: http://www.zachflask.tk/
[Wed Sep 13 19:21:26.398957 2017] [wsgi:error] [pid 27046] [client 209.54.86.83:50401]   File "/usr/local/lib/python2.7/dist-packages/flask/app.py", line 1598, in dispatch_request, referer: http://www.zachflask.tk/
[Wed Sep 13 19:21:26.398960 2017] [wsgi:error] [pid 27046] [client 209.54.86.83:50401]     return self.view_functions[rule.endpoint](**req.view_args), referer: http://www.zachflask.tk/
[Wed Sep 13 19:21:26.398962 2017] [wsgi:error] [pid 27046] [client 209.54.86.83:50401]   File "/var/www/FlaskApp/FlaskApp/FlaskApp.py", line 76, in add_entry, referer: http://www.zachflask.tk/
[Wed Sep 13 19:21:26.398964 2017] [wsgi:error] [pid 27046] [client 209.54.86.83:50401]     [request.form['title'], request.form['text']]), referer: http://www.zachflask.tk/
[Wed Sep 13 19:21:26.398966 2017] [wsgi:error] [pid 27046] [client 209.54.86.83:50401] OperationalError: unable to open database file, referer: http://www.zachflask.tk/
[Wed Sep 13 19:35:06.129995 2017] [wsgi:error] [pid 27434] [client 209.54.86.83:50478] [2017-09-13 19:35:06,129] ERROR in app: Exception on /add [POST], referer: http://www.zachflask.tk/
[Wed Sep 13 19:35:06.130032 2017] [wsgi:error] [pid 27434] [client 209.54.86.83:50478] Traceback (most recent call last):, referer: http://www.zachflask.tk/
[Wed Sep 13 19:35:06.130035 2017] [wsgi:error] [pid 27434] [client 209.54.86.83:50478]   File "/usr/local/lib/python2.7/dist-packages/flask/app.py", line 1982, in wsgi_app, referer: http://www.zachflask.tk/
[Wed Sep 13 19:35:06.130038 2017] [wsgi:error] [pid 27434] [client 209.54.86.83:50478]     response = self.full_dispatch_request(), referer: http://www.zachflask.tk/
[Wed Sep 13 19:35:06.130041 2017] [wsgi:error] [pid 27434] [client 209.54.86.83:50478]   File "/usr/local/lib/python2.7/dist-packages/flask/app.py", line 1614, in full_dispatch_request, referer: http://www.zachflask.tk/
[Wed Sep 13 19:35:06.130057 2017] [wsgi:error] [pid 27434] [client 209.54.86.83:50478]     rv = self.handle_user_exception(e), referer: http://www.zachflask.tk/
[Wed Sep 13 19:35:06.130059 2017] [wsgi:error] [pid 27434] [client 209.54.86.83:50478]   File "/usr/local/lib/python2.7/dist-packages/flask/app.py", line 1517, in handle_user_exception, referer: http://www.zachflask.tk/
[Wed Sep 13 19:35:06.130061 2017] [wsgi:error] [pid 27434] [client 209.54.86.83:50478]     reraise(exc_type, exc_value, tb), referer: http://www.zachflask.tk/
[Wed Sep 13 19:35:06.130063 2017] [wsgi:error] [pid 27434] [client 209.54.86.83:50478]   File "/usr/local/lib/python2.7/dist-packages/flask/app.py", line 1612, in full_dispatch_request, referer: http://www.zachflask.tk/
[Wed Sep 13 19:35:06.130065 2017] [wsgi:error] [pid 27434] [client 209.54.86.83:50478]     rv = self.dispatch_request(), referer: http://www.zachflask.tk/
[Wed Sep 13 19:35:06.130067 2017] [wsgi:error] [pid 27434] [client 209.54.86.83:50478]   File "/usr/local/lib/python2.7/dist-packages/flask/app.py", line 1598, in dispatch_request, referer: http://www.zachflask.tk/
[Wed Sep 13 19:35:06.130069 2017] [wsgi:error] [pid 27434] [client 209.54.86.83:50478]     return self.view_functions[rule.endpoint](**req.view_args), referer: http://www.zachflask.tk/
[Wed Sep 13 19:35:06.130070 2017] [wsgi:error] [pid 27434] [client 209.54.86.83:50478]   File "/var/www/FlaskApp/FlaskApp/FlaskApp.py", line 76, in add_entry, referer: http://www.zachflask.tk/
[Wed Sep 13 19:35:06.130072 2017] [wsgi:error] [pid 27434] [client 209.54.86.83:50478]     [request.form['title'], request.form['text']]), referer: http://www.zachflask.tk/
[Wed Sep 13 19:35:06.130074 2017] [wsgi:error] [pid 27434] [client 209.54.86.83:50478] OperationalError: unable to open database file, referer: http://www.zachflask.tk/
[Wed Sep 13 19:37:47.713249 2017] [wsgi:error] [pid 27587] [client 209.54.86.83:50492] [2017-09-13 19:37:47,712] ERROR in app: Exception on /add [POST], referer: http://www.zachflask.tk/
[Wed Sep 13 19:37:47.713291 2017] [wsgi:error] [pid 27587] [client 209.54.86.83:50492] Traceback (most recent call last):, referer: http://www.zachflask.tk/
[Wed Sep 13 19:37:47.713294 2017] [wsgi:error] [pid 27587] [client 209.54.86.83:50492]   File "/usr/local/lib/python2.7/dist-packages/flask/app.py", line 1982, in wsgi_app, referer: http://www.zachflask.tk/
[Wed Sep 13 19:37:47.713296 2017] [wsgi:error] [pid 27587] [client 209.54.86.83:50492]     response = self.full_dispatch_request(), referer: http://www.zachflask.tk/
[Wed Sep 13 19:37:47.713299 2017] [wsgi:error] [pid 27587] [client 209.54.86.83:50492]   File "/usr/local/lib/python2.7/dist-packages/flask/app.py", line 1614, in full_dispatch_request, referer: http://www.zachflask.tk/
[Wed Sep 13 19:37:47.713301 2017] [wsgi:error] [pid 27587] [client 209.54.86.83:50492]     rv = self.handle_user_exception(e), referer: http://www.zachflask.tk/
[Wed Sep 13 19:37:47.713304 2017] [wsgi:error] [pid 27587] [client 209.54.86.83:50492]   File "/usr/local/lib/python2.7/dist-packages/flask/app.py", line 1517, in handle_user_exception, referer: http://www.zachflask.tk/
[Wed Sep 13 19:37:47.713306 2017] [wsgi:error] [pid 27587] [client 209.54.86.83:50492]     reraise(exc_type, exc_value, tb), referer: http://www.zachflask.tk/
[Wed Sep 13 19:37:47.713308 2017] [wsgi:error] [pid 27587] [client 209.54.86.83:50492]   File "/usr/local/lib/python2.7/dist-packages/flask/app.py", line 1612, in full_dispatch_request, referer: http://www.zachflask.tk/
[Wed Sep 13 19:37:47.713310 2017] [wsgi:error] [pid 27587] [client 209.54.86.83:50492]     rv = self.dispatch_request(), referer: http://www.zachflask.tk/
[Wed Sep 13 19:37:47.713312 2017] [wsgi:error] [pid 27587] [client 209.54.86.83:50492]   File "/usr/local/lib/python2.7/dist-packages/flask/app.py", line 1598, in dispatch_request, referer: http://www.zachflask.tk/
[Wed Sep 13 19:37:47.713314 2017] [wsgi:error] [pid 27587] [client 209.54.86.83:50492]     return self.view_functions[rule.endpoint](**req.view_args), referer: http://www.zachflask.tk/
[Wed Sep 13 19:37:47.713330 2017] [wsgi:error] [pid 27587] [client 209.54.86.83:50492]   File "/var/www/FlaskApp/FlaskApp/FlaskApp.py", line 76, in add_entry, referer: http://www.zachflask.tk/
[Wed Sep 13 19:37:47.713333 2017] [wsgi:error] [pid 27587] [client 209.54.86.83:50492]     [request.form['title'], request.form['text']]), referer: http://www.zachflask.tk/
[Wed Sep 13 19:37:47.713334 2017] [wsgi:error] [pid 27587] [client 209.54.86.83:50492] OperationalError: unable to open database file, referer: http://www.zachflask.tk/
[Wed Sep 13 22:48:16.487314 2017] [wsgi:error] [pid 28480] [client 209.54.86.83:51961] [2017-09-13 22:48:16,485] ERROR in app: Exception on /add [POST], referer: http://www.zachflask.tk/
[Wed Sep 13 22:48:16.487353 2017] [wsgi:error] [pid 28480] [client 209.54.86.83:51961] Traceback (most recent call last):, referer: http://www.zachflask.tk/
[Wed Sep 13 22:48:16.487357 2017] [wsgi:error] [pid 28480] [client 209.54.86.83:51961]   File "/usr/local/lib/python2.7/dist-packages/flask/app.py", line 1982, in wsgi_app, referer: http://www.zachflask.tk/
[Wed Sep 13 22:48:16.487359 2017] [wsgi:error] [pid 28480] [client 209.54.86.83:51961]     response = self.full_dispatch_request(), referer: http://www.zachflask.tk/
[Wed Sep 13 22:48:16.487362 2017] [wsgi:error] [pid 28480] [client 209.54.86.83:51961]   File "/usr/local/lib/python2.7/dist-packages/flask/app.py", line 1614, in full_dispatch_request, referer: http://www.zachflask.tk/
[Wed Sep 13 22:48:16.487364 2017] [wsgi:error] [pid 28480] [client 209.54.86.83:51961]     rv = self.handle_user_exception(e), referer: http://www.zachflask.tk/
[Wed Sep 13 22:48:16.487366 2017] [wsgi:error] [pid 28480] [client 209.54.86.83:51961]   File "/usr/local/lib/python2.7/dist-packages/flask/app.py", line 1517, in handle_user_exception, referer: http://www.zachflask.tk/
[Wed Sep 13 22:48:16.487368 2017] [wsgi:error] [pid 28480] [client 209.54.86.83:51961]     reraise(exc_type, exc_value, tb), referer: http://www.zachflask.tk/
[Wed Sep 13 22:48:16.487370 2017] [wsgi:error] [pid 28480] [client 209.54.86.83:51961]   File "/usr/local/lib/python2.7/dist-packages/flask/app.py", line 1612, in full_dispatch_request, referer: http://www.zachflask.tk/
[Wed Sep 13 22:48:16.487372 2017] [wsgi:error] [pid 28480] [client 209.54.86.83:51961]     rv = self.dispatch_request(), referer: http://www.zachflask.tk/
[Wed Sep 13 22:48:16.487374 2017] [wsgi:error] [pid 28480] [client 209.54.86.83:51961]   File "/usr/local/lib/python2.7/dist-packages/flask/app.py", line 1598, in dispatch_request, referer: http://www.zachflask.tk/
[Wed Sep 13 22:48:16.487376 2017] [wsgi:error] [pid 28480] [client 209.54.86.83:51961]     return self.view_functions[rule.endpoint](**req.view_args), referer: http://www.zachflask.tk/
[Wed Sep 13 22:48:16.487378 2017] [wsgi:error] [pid 28480] [client 209.54.86.83:51961]   File "/var/www/FlaskApp/FlaskApp/FlaskApp.py", line 76, in add_entry, referer: http://www.zachflask.tk/
[Wed Sep 13 22:48:16.487380 2017] [wsgi:error] [pid 28480] [client 209.54.86.83:51961]     [request.form['title'], request.form['text']]), referer: http://www.zachflask.tk/
[Wed Sep 13 22:48:16.487382 2017] [wsgi:error] [pid 28480] [client 209.54.86.83:51961] OperationalError: unable to open database file, referer: http://www.zachflask.tk/
[Wed Sep 13 23:56:45.538568 2017] [wsgi:error] [pid 29565] [client 209.54.86.83:52433] [2017-09-13 23:56:45,537] ERROR in app: Exception on /add [POST], referer: http://www.zachflask.tk/
[Wed Sep 13 23:56:45.538604 2017] [wsgi:error] [pid 29565] [client 209.54.86.83:52433] Traceback (most recent call last):, referer: http://www.zachflask.tk/
[Wed Sep 13 23:56:45.538608 2017] [wsgi:error] [pid 29565] [client 209.54.86.83:52433]   File "/usr/local/lib/python2.7/dist-packages/flask/app.py", line 1982, in wsgi_app, referer: http://www.zachflask.tk/
[Wed Sep 13 23:56:45.538610 2017] [wsgi:error] [pid 29565] [client 209.54.86.83:52433]     response = self.full_dispatch_request(), referer: http://www.zachflask.tk/
[Wed Sep 13 23:56:45.538613 2017] [wsgi:error] [pid 29565] [client 209.54.86.83:52433]   File "/usr/local/lib/python2.7/dist-packages/flask/app.py", line 1614, in full_dispatch_request, referer: http://www.zachflask.tk/
[Wed Sep 13 23:56:45.538630 2017] [wsgi:error] [pid 29565] [client 209.54.86.83:52433]     rv = self.handle_user_exception(e), referer: http://www.zachflask.tk/
[Wed Sep 13 23:56:45.538632 2017] [wsgi:error] [pid 29565] [client 209.54.86.83:52433]   File "/usr/local/lib/python2.7/dist-packages/flask/app.py", line 1517, in handle_user_exception, referer: http://www.zachflask.tk/
[Wed Sep 13 23:56:45.538634 2017] [wsgi:error] [pid 29565] [client 209.54.86.83:52433]     reraise(exc_type, exc_value, tb), referer: http://www.zachflask.tk/
[Wed Sep 13 23:56:45.538636 2017] [wsgi:error] [pid 29565] [client 209.54.86.83:52433]   File "/usr/local/lib/python2.7/dist-packages/flask/app.py", line 1612, in full_dispatch_request, referer: http://www.zachflask.tk/
[Wed Sep 13 23:56:45.538638 2017] [wsgi:error] [pid 29565] [client 209.54.86.83:52433]     rv = self.dispatch_request(), referer: http://www.zachflask.tk/
[Wed Sep 13 23:56:45.538640 2017] [wsgi:error] [pid 29565] [client 209.54.86.83:52433]   File "/usr/local/lib/python2.7/dist-packages/flask/app.py", line 1598, in dispatch_request, referer: http://www.zachflask.tk/
[Wed Sep 13 23:56:45.538642 2017] [wsgi:error] [pid 29565] [client 209.54.86.83:52433]     return self.view_functions[rule.endpoint](**req.view_args), referer: http://www.zachflask.tk/
[Wed Sep 13 23:56:45.538643 2017] [wsgi:error] [pid 29565] [client 209.54.86.83:52433]   File "/var/www/FlaskApp/FlaskApp/FlaskApp.py", line 76, in add_entry, referer: http://www.zachflask.tk/
[Wed Sep 13 23:56:45.538645 2017] [wsgi:error] [pid 29565] [client 209.54.86.83:52433]     [request.form['title'], request.form['text']]), referer: http://www.zachflask.tk/
[Wed Sep 13 23:56:45.538647 2017] [wsgi:error] [pid 29565] [client 209.54.86.83:52433] OperationalError: unable to open database file, referer: http://www.zachflask.tk/
[Wed Sep 13 23:57:31.742857 2017] [wsgi:error] [pid 29569] [client 209.54.86.83:52436] [2017-09-13 23:57:31,742] ERROR in app: Exception on /add [POST], referer: http://www.zachflask.tk/
[Wed Sep 13 23:57:31.742895 2017] [wsgi:error] [pid 29569] [client 209.54.86.83:52436] Traceback (most recent call last):, referer: http://www.zachflask.tk/
[Wed Sep 13 23:57:31.742898 2017] [wsgi:error] [pid 29569] [client 209.54.86.83:52436]   File "/usr/local/lib/python2.7/dist-packages/flask/app.py", line 1982, in wsgi_app, referer: http://www.zachflask.tk/
[Wed Sep 13 23:57:31.742900 2017] [wsgi:error] [pid 29569] [client 209.54.86.83:52436]     response = self.full_dispatch_request(), referer: http://www.zachflask.tk/
[Wed Sep 13 23:57:31.742903 2017] [wsgi:error] [pid 29569] [client 209.54.86.83:52436]   File "/usr/local/lib/python2.7/dist-packages/flask/app.py", line 1614, in full_dispatch_request, referer: http://www.zachflask.tk/
[Wed Sep 13 23:57:31.742905 2017] [wsgi:error] [pid 29569] [client 209.54.86.83:52436]     rv = self.handle_user_exception(e), referer: http://www.zachflask.tk/
[Wed Sep 13 23:57:31.742907 2017] [wsgi:error] [pid 29569] [client 209.54.86.83:52436]   File "/usr/local/lib/python2.7/dist-packages/flask/app.py", line 1517, in handle_user_exception, referer: http://www.zachflask.tk/
[Wed Sep 13 23:57:31.742909 2017] [wsgi:error] [pid 29569] [client 209.54.86.83:52436]     reraise(exc_type, exc_value, tb), referer: http://www.zachflask.tk/
[Wed Sep 13 23:57:31.742911 2017] [wsgi:error] [pid 29569] [client 209.54.86.83:52436]   File "/usr/local/lib/python2.7/dist-packages/flask/app.py", line 1612, in full_dispatch_request, referer: http://www.zachflask.tk/
[Wed Sep 13 23:57:31.742913 2017] [wsgi:error] [pid 29569] [client 209.54.86.83:52436]     rv = self.dispatch_request(), referer: http://www.zachflask.tk/
[Wed Sep 13 23:57:31.742915 2017] [wsgi:error] [pid 29569] [client 209.54.86.83:52436]   File "/usr/local/lib/python2.7/dist-packages/flask/app.py", line 1598, in dispatch_request, referer: http://www.zachflask.tk/
[Wed Sep 13 23:57:31.742927 2017] [wsgi:error] [pid 29569] [client 209.54.86.83:52436]     return self.view_functions[rule.endpoint](**req.view_args), referer: http://www.zachflask.tk/
[Wed Sep 13 23:57:31.742929 2017] [wsgi:error] [pid 29569] [client 209.54.86.83:52436]   File "/var/www/FlaskApp/FlaskApp/FlaskApp.py", line 76, in add_entry, referer: http://www.zachflask.tk/
[Wed Sep 13 23:57:31.742931 2017] [wsgi:error] [pid 29569] [client 209.54.86.83:52436]     [request.form['title'], request.form['text']]), referer: http://www.zachflask.tk/
[Wed Sep 13 23:57:31.742933 2017] [wsgi:error] [pid 29569] [client 209.54.86.83:52436] OperationalError: unable to open database file, referer: http://www.zachflask.tk/
[Thu Sep 14 01:42:37.907658 2017] [wsgi:error] [pid 29566] [client 184.250.130.36:59975] [2017-09-14 01:42:37,905] ERROR in app: Exception on /add [POST], referer: http://zachflask.tk/
[Thu Sep 14 01:42:37.907730 2017] [wsgi:error] [pid 29566] [client 184.250.130.36:59975] Traceback (most recent call last):, referer: http://zachflask.tk/
[Thu Sep 14 01:42:37.907734 2017] [wsgi:error] [pid 29566] [client 184.250.130.36:59975]   File "/usr/local/lib/python2.7/dist-packages/flask/app.py", line 1982, in wsgi_app, referer: http://zachflask.tk/
[Thu Sep 14 01:42:37.907736 2017] [wsgi:error] [pid 29566] [client 184.250.130.36:59975]     response = self.full_dispatch_request(), referer: http://zachflask.tk/
[Thu Sep 14 01:42:37.907739 2017] [wsgi:error] [pid 29566] [client 184.250.130.36:59975]   File "/usr/local/lib/python2.7/dist-packages/flask/app.py", line 1614, in full_dispatch_request, referer: http://zachflask.tk/
[Thu Sep 14 01:42:37.907741 2017] [wsgi:error] [pid 29566] [client 184.250.130.36:59975]     rv = self.handle_user_exception(e), referer: http://zachflask.tk/
[Thu Sep 14 01:42:37.907743 2017] [wsgi:error] [pid 29566] [client 184.250.130.36:59975]   File "/usr/local/lib/python2.7/dist-packages/flask/app.py", line 1517, in handle_user_exception, referer: http://zachflask.tk/
[Thu Sep 14 01:42:37.907745 2017] [wsgi:error] [pid 29566] [client 184.250.130.36:59975]     reraise(exc_type, exc_value, tb), referer: http://zachflask.tk/
[Thu Sep 14 01:42:37.907747 2017] [wsgi:error] [pid 29566] [client 184.250.130.36:59975]   File "/usr/local/lib/python2.7/dist-packages/flask/app.py", line 1612, in full_dispatch_request, referer: http://zachflask.tk/
[Thu Sep 14 01:42:37.907749 2017] [wsgi:error] [pid 29566] [client 184.250.130.36:59975]     rv = self.dispatch_request(), referer: http://zachflask.tk/
[Thu Sep 14 01:42:37.907751 2017] [wsgi:error] [pid 29566] [client 184.250.130.36:59975]   File "/usr/local/lib/python2.7/dist-packages/flask/app.py", line 1598, in dispatch_request, referer: http://zachflask.tk/
[Thu Sep 14 01:42:37.907753 2017] [wsgi:error] [pid 29566] [client 184.250.130.36:59975]     return self.view_functions[rule.endpoint](**req.view_args), referer: http://zachflask.tk/
[Thu Sep 14 01:42:37.907755 2017] [wsgi:error] [pid 29566] [client 184.250.130.36:59975]   File "/var/www/FlaskApp/FlaskApp/FlaskApp.py", line 76, in add_entry, referer: http://zachflask.tk/
[Thu Sep 14 01:42:37.907759 2017] [wsgi:error] [pid 29566] [client 184.250.130.36:59975]     [request.form['title'], request.form['text']]), referer: http://zachflask.tk/
[Thu Sep 14 01:42:37.907761 2017] [wsgi:error] [pid 29566] [client 184.250.130.36:59975] OperationalError: unable to open database file, referer: http://zachflask.tk/
[Thu Sep 14 07:37:32.400119 2017] [wsgi:error] [pid 31777] [client 128.206.251.96:34672] [2017-09-14 07:37:32,399] ERROR in app: Exception on /add [POST], referer: http://www.zachflask.tk/
[Thu Sep 14 07:37:32.400160 2017] [wsgi:error] [pid 31777] [client 128.206.251.96:34672] Traceback (most recent call last):, referer: http://www.zachflask.tk/
[Thu Sep 14 07:37:32.400164 2017] [wsgi:error] [pid 31777] [client 128.206.251.96:34672]   File "/usr/local/lib/python2.7/dist-packages/flask/app.py", line 1982, in wsgi_app, referer: http://www.zachflask.tk/
[Thu Sep 14 07:37:32.400167 2017] [wsgi:error] [pid 31777] [client 128.206.251.96:34672]     response = self.full_dispatch_request(), referer: http://www.zachflask.tk/
[Thu Sep 14 07:37:32.400184 2017] [wsgi:error] [pid 31777] [client 128.206.251.96:34672]   File "/usr/local/lib/python2.7/dist-packages/flask/app.py", line 1614, in full_dispatch_request, referer: http://www.zachflask.tk/
[Thu Sep 14 07:37:32.400186 2017] [wsgi:error] [pid 31777] [client 128.206.251.96:34672]     rv = self.handle_user_exception(e), referer: http://www.zachflask.tk/
[Thu Sep 14 07:37:32.400188 2017] [wsgi:error] [pid 31777] [client 128.206.251.96:34672]   File "/usr/local/lib/python2.7/dist-packages/flask/app.py", line 1517, in handle_user_exception, referer: http://www.zachflask.tk/
[Thu Sep 14 07:37:32.400190 2017] [wsgi:error] [pid 31777] [client 128.206.251.96:34672]     reraise(exc_type, exc_value, tb), referer: http://www.zachflask.tk/
[Thu Sep 14 07:37:32.400192 2017] [wsgi:error] [pid 31777] [client 128.206.251.96:34672]   File "/usr/local/lib/python2.7/dist-packages/flask/app.py", line 1612, in full_dispatch_request, referer: http://www.zachflask.tk/
[Thu Sep 14 07:37:32.400194 2017] [wsgi:error] [pid 31777] [client 128.206.251.96:34672]     rv = self.dispatch_request(), referer: http://www.zachflask.tk/
[Thu Sep 14 07:37:32.400195 2017] [wsgi:error] [pid 31777] [client 128.206.251.96:34672]   File "/usr/local/lib/python2.7/dist-packages/flask/app.py", line 1598, in dispatch_request, referer: http://www.zachflask.tk/
[Thu Sep 14 07:37:32.400197 2017] [wsgi:error] [pid 31777] [client 128.206.251.96:34672]     return self.view_functions[rule.endpoint](**req.view_args), referer: http://www.zachflask.tk/
[Thu Sep 14 07:37:32.400199 2017] [wsgi:error] [pid 31777] [client 128.206.251.96:34672]   File "/var/www/FlaskApp/FlaskApp/FlaskApp.py", line 76, in add_entry, referer: http://www.zachflask.tk/
[Thu Sep 14 07:37:32.400201 2017] [wsgi:error] [pid 31777] [client 128.206.251.96:34672]     [request.form['title'], request.form['text']]), referer: http://www.zachflask.tk/
[Thu Sep 14 07:37:32.400203 2017] [wsgi:error] [pid 31777] [client 128.206.251.96:34672] OperationalError: unable to open database file, referer: http://www.zachflask.tk/
[Thu Sep 14 07:41:39.656252 2017] [wsgi:error] [pid 31973] [client 128.206.251.96:58001] mod_wsgi (pid=31973): Exception occurred processing WSGI script '/var/www/FlaskApp/flaskapp.wsgi'., referer: http://www.zachflask.tk/
[Thu Sep 14 07:41:39.656307 2017] [wsgi:error] [pid 31973] [client 128.206.251.96:58001] Traceback (most recent call last):, referer: http://www.zachflask.tk/
[Thu Sep 14 07:41:39.656325 2017] [wsgi:error] [pid 31973] [client 128.206.251.96:58001]   File "/usr/local/lib/python2.7/dist-packages/flask/app.py", line 1997, in __call__, referer: http://www.zachflask.tk/
[Thu Sep 14 07:41:39.656719 2017] [wsgi:error] [pid 31973] [client 128.206.251.96:58001]     return self.wsgi_app(environ, start_response), referer: http://www.zachflask.tk/
[Thu Sep 14 07:41:39.656732 2017] [wsgi:error] [pid 31973] [client 128.206.251.96:58001]   File "/usr/local/lib/python2.7/dist-packages/flask/app.py", line 1985, in wsgi_app, referer: http://www.zachflask.tk/
[Thu Sep 14 07:41:39.656746 2017] [wsgi:error] [pid 31973] [client 128.206.251.96:58001]     response = self.handle_exception(e), referer: http://www.zachflask.tk/
[Thu Sep 14 07:41:39.656752 2017] [wsgi:error] [pid 31973] [client 128.206.251.96:58001]   File "/usr/local/lib/python2.7/dist-packages/flask/app.py", line 1540, in handle_exception, referer: http://www.zachflask.tk/
[Thu Sep 14 07:41:39.656760 2017] [wsgi:error] [pid 31973] [client 128.206.251.96:58001]     reraise(exc_type, exc_value, tb), referer: http://www.zachflask.tk/
[Thu Sep 14 07:41:39.656764 2017] [wsgi:error] [pid 31973] [client 128.206.251.96:58001]   File "/usr/local/lib/python2.7/dist-packages/flask/app.py", line 1982, in wsgi_app, referer: http://www.zachflask.tk/
[Thu Sep 14 07:41:39.656771 2017] [wsgi:error] [pid 31973] [client 128.206.251.96:58001]     response = self.full_dispatch_request(), referer: http://www.zachflask.tk/
[Thu Sep 14 07:41:39.656784 2017] [wsgi:error] [pid 31973] [client 128.206.251.96:58001]   File "/usr/local/lib/python2.7/dist-packages/flask/app.py", line 1614, in full_dispatch_request, referer: http://www.zachflask.tk/
[Thu Sep 14 07:41:39.656791 2017] [wsgi:error] [pid 31973] [client 128.206.251.96:58001]     rv = self.handle_user_exception(e), referer: http://www.zachflask.tk/
[Thu Sep 14 07:41:39.656795 2017] [wsgi:error] [pid 31973] [client 128.206.251.96:58001]   File "/usr/local/lib/python2.7/dist-packages/flask/app.py", line 1517, in handle_user_exception, referer: http://www.zachflask.tk/
[Thu Sep 14 07:41:39.656801 2017] [wsgi:error] [pid 31973] [client 128.206.251.96:58001]     reraise(exc_type, exc_value, tb), referer: http://www.zachflask.tk/
[Thu Sep 14 07:41:39.656806 2017] [wsgi:error] [pid 31973] [client 128.206.251.96:58001]   File "/usr/local/lib/python2.7/dist-packages/flask/app.py", line 1612, in full_dispatch_request, referer: http://www.zachflask.tk/
[Thu Sep 14 07:41:39.656811 2017] [wsgi:error] [pid 31973] [client 128.206.251.96:58001]     rv = self.dispatch_request(), referer: http://www.zachflask.tk/
[Thu Sep 14 07:41:39.656815 2017] [wsgi:error] [pid 31973] [client 128.206.251.96:58001]   File "/usr/local/lib/python2.7/dist-packages/flask/app.py", line 1598, in dispatch_request, referer: http://www.zachflask.tk/
[Thu Sep 14 07:41:39.656822 2017] [wsgi:error] [pid 31973] [client 128.206.251.96:58001]     return self.view_functions[rule.endpoint](**req.view_args), referer: http://www.zachflask.tk/
[Thu Sep 14 07:41:39.656826 2017] [wsgi:error] [pid 31973] [client 128.206.251.96:58001]   File "/var/www/FlaskApp/FlaskApp/FlaskApp.py", line 80, in add_entry, referer: http://www.zachflask.tk/
[Thu Sep 14 07:41:39.656863 2017] [wsgi:error] [pid 31973] [client 128.206.251.96:58001]     [request.form['title'], request.form['text']]), referer: http://www.zachflask.tk/
[Thu Sep 14 07:41:39.656881 2017] [wsgi:error] [pid 31973] [client 128.206.251.96:58001] OperationalError: unable to open database file, referer: http://www.zachflask.tk/
[Thu Sep 14 07:50:07.062106 2017] [wsgi:error] [pid 32121] [client 128.206.251.96:28066] mod_wsgi (pid=32121): Exception occurred processing WSGI script '/var/www/FlaskApp/flaskapp.wsgi'., referer: http://www.zachflask.tk/
[Thu Sep 14 07:50:07.062173 2017] [wsgi:error] [pid 32121] [client 128.206.251.96:28066] Traceback (most recent call last):, referer: http://www.zachflask.tk/
[Thu Sep 14 07:50:07.062193 2017] [wsgi:error] [pid 32121] [client 128.206.251.96:28066]   File "/usr/local/lib/python2.7/dist-packages/flask/app.py", line 1997, in __call__, referer: http://www.zachflask.tk/
[Thu Sep 14 07:50:07.062584 2017] [wsgi:error] [pid 32121] [client 128.206.251.96:28066]     return self.wsgi_app(environ, start_response), referer: http://www.zachflask.tk/
[Thu Sep 14 07:50:07.062596 2017] [wsgi:error] [pid 32121] [client 128.206.251.96:28066]   File "/usr/local/lib/python2.7/dist-packages/flask/app.py", line 1985, in wsgi_app, referer: http://www.zachflask.tk/
[Thu Sep 14 07:50:07.062610 2017] [wsgi:error] [pid 32121] [client 128.206.251.96:28066]     response = self.handle_exception(e), referer: http://www.zachflask.tk/
[Thu Sep 14 07:50:07.062616 2017] [wsgi:error] [pid 32121] [client 128.206.251.96:28066]   File "/usr/local/lib/python2.7/dist-packages/flask/app.py", line 1540, in handle_exception, referer: http://www.zachflask.tk/
[Thu Sep 14 07:50:07.062624 2017] [wsgi:error] [pid 32121] [client 128.206.251.96:28066]     reraise(exc_type, exc_value, tb), referer: http://www.zachflask.tk/
[Thu Sep 14 07:50:07.062630 2017] [wsgi:error] [pid 32121] [client 128.206.251.96:28066]   File "/usr/local/lib/python2.7/dist-packages/flask/app.py", line 1982, in wsgi_app, referer: http://www.zachflask.tk/
[Thu Sep 14 07:50:07.062637 2017] [wsgi:error] [pid 32121] [client 128.206.251.96:28066]     response = self.full_dispatch_request(), referer: http://www.zachflask.tk/
[Thu Sep 14 07:50:07.062642 2017] [wsgi:error] [pid 32121] [client 128.206.251.96:28066]   File "/usr/local/lib/python2.7/dist-packages/flask/app.py", line 1614, in full_dispatch_request, referer: http://www.zachflask.tk/
[Thu Sep 14 07:50:07.062659 2017] [wsgi:error] [pid 32121] [client 128.206.251.96:28066]     rv = self.handle_user_exception(e), referer: http://www.zachflask.tk/
[Thu Sep 14 07:50:07.062664 2017] [wsgi:error] [pid 32121] [client 128.206.251.96:28066]   File "/usr/local/lib/python2.7/dist-packages/flask/app.py", line 1517, in handle_user_exception, referer: http://www.zachflask.tk/
[Thu Sep 14 07:50:07.062671 2017] [wsgi:error] [pid 32121] [client 128.206.251.96:28066]     reraise(exc_type, exc_value, tb), referer: http://www.zachflask.tk/
[Thu Sep 14 07:50:07.062675 2017] [wsgi:error] [pid 32121] [client 128.206.251.96:28066]   File "/usr/local/lib/python2.7/dist-packages/flask/app.py", line 1612, in full_dispatch_request, referer: http://www.zachflask.tk/
[Thu Sep 14 07:50:07.062681 2017] [wsgi:error] [pid 32121] [client 128.206.251.96:28066]     rv = self.dispatch_request(), referer: http://www.zachflask.tk/
[Thu Sep 14 07:50:07.062686 2017] [wsgi:error] [pid 32121] [client 128.206.251.96:28066]   File "/usr/local/lib/python2.7/dist-packages/flask/app.py", line 1598, in dispatch_request, referer: http://www.zachflask.tk/
[Thu Sep 14 07:50:07.062692 2017] [wsgi:error] [pid 32121] [client 128.206.251.96:28066]     return self.view_functions[rule.endpoint](**req.view_args), referer: http://www.zachflask.tk/
[Thu Sep 14 07:50:07.062698 2017] [wsgi:error] [pid 32121] [client 128.206.251.96:28066]   File "/var/www/FlaskApp/FlaskApp/FlaskApp.py", line 80, in add_entry, referer: http://www.zachflask.tk/
[Thu Sep 14 07:50:07.062734 2017] [wsgi:error] [pid 32121] [client 128.206.251.96:28066]     [request.form['title'], request.form['text']]), referer: http://www.zachflask.tk/
[Thu Sep 14 07:50:07.062752 2017] [wsgi:error] [pid 32121] [client 128.206.251.96:28066] OperationalError: unable to open database file, referer: http://www.zachflask.tk/
[Thu Sep 14 07:53:55.652461 2017] [wsgi:error] [pid 32153] [client 128.206.251.96:8811] mod_wsgi (pid=32153): Exception occurred processing WSGI script '/var/www/FlaskApp/flaskapp.wsgi'., referer: http://www.zachflask.tk/
[Thu Sep 14 07:53:55.652548 2017] [wsgi:error] [pid 32153] [client 128.206.251.96:8811] Traceback (most recent call last):, referer: http://www.zachflask.tk/
[Thu Sep 14 07:53:55.652575 2017] [wsgi:error] [pid 32153] [client 128.206.251.96:8811]   File "/usr/local/lib/python2.7/dist-packages/flask/app.py", line 1997, in __call__, referer: http://www.zachflask.tk/
[Thu Sep 14 07:53:55.653043 2017] [wsgi:error] [pid 32153] [client 128.206.251.96:8811]     return self.wsgi_app(environ, start_response), referer: http://www.zachflask.tk/
[Thu Sep 14 07:53:55.653056 2017] [wsgi:error] [pid 32153] [client 128.206.251.96:8811]   File "/usr/local/lib/python2.7/dist-packages/flask/app.py", line 1985, in wsgi_app, referer: http://www.zachflask.tk/
[Thu Sep 14 07:53:55.653072 2017] [wsgi:error] [pid 32153] [client 128.206.251.96:8811]     response = self.handle_exception(e), referer: http://www.zachflask.tk/
[Thu Sep 14 07:53:55.653079 2017] [wsgi:error] [pid 32153] [client 128.206.251.96:8811]   File "/usr/local/lib/python2.7/dist-packages/flask/app.py", line 1540, in handle_exception, referer: http://www.zachflask.tk/
[Thu Sep 14 07:53:55.653088 2017] [wsgi:error] [pid 32153] [client 128.206.251.96:8811]     reraise(exc_type, exc_value, tb), referer: http://www.zachflask.tk/
[Thu Sep 14 07:53:55.653093 2017] [wsgi:error] [pid 32153] [client 128.206.251.96:8811]   File "/usr/local/lib/python2.7/dist-packages/flask/app.py", line 1982, in wsgi_app, referer: http://www.zachflask.tk/
[Thu Sep 14 07:53:55.653101 2017] [wsgi:error] [pid 32153] [client 128.206.251.96:8811]     response = self.full_dispatch_request(), referer: http://www.zachflask.tk/
[Thu Sep 14 07:53:55.653106 2017] [wsgi:error] [pid 32153] [client 128.206.251.96:8811]   File "/usr/local/lib/python2.7/dist-packages/flask/app.py", line 1614, in full_dispatch_request, referer: http://www.zachflask.tk/
[Thu Sep 14 07:53:55.653123 2017] [wsgi:error] [pid 32153] [client 128.206.251.96:8811]     rv = self.handle_user_exception(e), referer: http://www.zachflask.tk/
[Thu Sep 14 07:53:55.653129 2017] [wsgi:error] [pid 32153] [client 128.206.251.96:8811]   File "/usr/local/lib/python2.7/dist-packages/flask/app.py", line 1517, in handle_user_exception, referer: http://www.zachflask.tk/
[Thu Sep 14 07:53:55.653135 2017] [wsgi:error] [pid 32153] [client 128.206.251.96:8811]     reraise(exc_type, exc_value, tb), referer: http://www.zachflask.tk/
[Thu Sep 14 07:53:55.653140 2017] [wsgi:error] [pid 32153] [client 128.206.251.96:8811]   File "/usr/local/lib/python2.7/dist-packages/flask/app.py", line 1612, in full_dispatch_request, referer: http://www.zachflask.tk/
[Thu Sep 14 07:53:55.653146 2017] [wsgi:error] [pid 32153] [client 128.206.251.96:8811]     rv = self.dispatch_request(), referer: http://www.zachflask.tk/
[Thu Sep 14 07:53:55.653150 2017] [wsgi:error] [pid 32153] [client 128.206.251.96:8811]   File "/usr/local/lib/python2.7/dist-packages/flask/app.py", line 1598, in dispatch_request, referer: http://www.zachflask.tk/
[Thu Sep 14 07:53:55.653157 2017] [wsgi:error] [pid 32153] [client 128.206.251.96:8811]     return self.view_functions[rule.endpoint](**req.view_args), referer: http://www.zachflask.tk/
[Thu Sep 14 07:53:55.653164 2017] [wsgi:error] [pid 32153] [client 128.206.251.96:8811]   File "/var/www/FlaskApp/FlaskApp/FlaskApp.py", line 80, in add_entry, referer: http://www.zachflask.tk/
[Thu Sep 14 07:53:55.653203 2017] [wsgi:error] [pid 32153] [client 128.206.251.96:8811]     [request.form['title'], request.form['text']]), referer: http://www.zachflask.tk/
[Thu Sep 14 07:53:55.653224 2017] [wsgi:error] [pid 32153] [client 128.206.251.96:8811] OperationalError: database is locked, referer: http://www.zachflask.tk/
[Thu Sep 14 08:16:05.403072 2017] [wsgi:error] [pid 32699] [client 128.206.251.96:7381] mod_wsgi (pid=32699): Exception occurred processing WSGI script '/var/www/FlaskApp/flaskapp.wsgi'., referer: http://www.zachflask.tk/
[Thu Sep 14 08:16:05.403184 2017] [wsgi:error] [pid 32699] [client 128.206.251.96:7381] Traceback (most recent call last):, referer: http://www.zachflask.tk/
[Thu Sep 14 08:16:05.403204 2017] [wsgi:error] [pid 32699] [client 128.206.251.96:7381]   File "/usr/local/lib/python2.7/dist-packages/flask/app.py", line 1997, in __call__, referer: http://www.zachflask.tk/
[Thu Sep 14 08:16:05.403599 2017] [wsgi:error] [pid 32699] [client 128.206.251.96:7381]     return self.wsgi_app(environ, start_response), referer: http://www.zachflask.tk/
[Thu Sep 14 08:16:05.403612 2017] [wsgi:error] [pid 32699] [client 128.206.251.96:7381]   File "/usr/local/lib/python2.7/dist-packages/flask/app.py", line 1985, in wsgi_app, referer: http://www.zachflask.tk/
[Thu Sep 14 08:16:05.403626 2017] [wsgi:error] [pid 32699] [client 128.206.251.96:7381]     response = self.handle_exception(e), referer: http://www.zachflask.tk/
[Thu Sep 14 08:16:05.403632 2017] [wsgi:error] [pid 32699] [client 128.206.251.96:7381]   File "/usr/local/lib/python2.7/dist-packages/flask/app.py", line 1540, in handle_exception, referer: http://www.zachflask.tk/
[Thu Sep 14 08:16:05.403640 2017] [wsgi:error] [pid 32699] [client 128.206.251.96:7381]     reraise(exc_type, exc_value, tb), referer: http://www.zachflask.tk/
[Thu Sep 14 08:16:05.403645 2017] [wsgi:error] [pid 32699] [client 128.206.251.96:7381]   File "/usr/local/lib/python2.7/dist-packages/flask/app.py", line 1982, in wsgi_app, referer: http://www.zachflask.tk/
[Thu Sep 14 08:16:05.403652 2017] [wsgi:error] [pid 32699] [client 128.206.251.96:7381]     response = self.full_dispatch_request(), referer: http://www.zachflask.tk/
[Thu Sep 14 08:16:05.403657 2017] [wsgi:error] [pid 32699] [client 128.206.251.96:7381]   File "/usr/local/lib/python2.7/dist-packages/flask/app.py", line 1614, in full_dispatch_request, referer: http://www.zachflask.tk/
[Thu Sep 14 08:16:05.403664 2017] [wsgi:error] [pid 32699] [client 128.206.251.96:7381]     rv = self.handle_user_exception(e), referer: http://www.zachflask.tk/
[Thu Sep 14 08:16:05.403678 2017] [wsgi:error] [pid 32699] [client 128.206.251.96:7381]   File "/usr/local/lib/python2.7/dist-packages/flask/app.py", line 1517, in handle_user_exception, referer: http://www.zachflask.tk/
[Thu Sep 14 08:16:05.403686 2017] [wsgi:error] [pid 32699] [client 128.206.251.96:7381]     reraise(exc_type, exc_value, tb), referer: http://www.zachflask.tk/
[Thu Sep 14 08:16:05.403690 2017] [wsgi:error] [pid 32699] [client 128.206.251.96:7381]   File "/usr/local/lib/python2.7/dist-packages/flask/app.py", line 1612, in full_dispatch_request, referer: http://www.zachflask.tk/
[Thu Sep 14 08:16:05.403697 2017] [wsgi:error] [pid 32699] [client 128.206.251.96:7381]     rv = self.dispatch_request(), referer: http://www.zachflask.tk/
[Thu Sep 14 08:16:05.403701 2017] [wsgi:error] [pid 32699] [client 128.206.251.96:7381]   File "/usr/local/lib/python2.7/dist-packages/flask/app.py", line 1598, in dispatch_request, referer: http://www.zachflask.tk/
[Thu Sep 14 08:16:05.403707 2017] [wsgi:error] [pid 32699] [client 128.206.251.96:7381]     return self.view_functions[rule.endpoint](**req.view_args), referer: http://www.zachflask.tk/
[Thu Sep 14 08:16:05.403712 2017] [wsgi:error] [pid 32699] [client 128.206.251.96:7381]   File "/var/www/FlaskApp/FlaskApp/FlaskApp.py", line 80, in add_entry, referer: http://www.zachflask.tk/
[Thu Sep 14 08:16:05.403748 2017] [wsgi:error] [pid 32699] [client 128.206.251.96:7381]     [request.form['title'], request.form['text']]), referer: http://www.zachflask.tk/
[Thu Sep 14 08:16:05.403765 2017] [wsgi:error] [pid 32699] [client 128.206.251.96:7381] OperationalError: unable to open database file, referer: http://www.zachflask.tk/
[Thu Sep 14 08:16:13.986476 2017] [wsgi:error] [pid 32700] [client 128.206.251.96:20921] mod_wsgi (pid=32700): Exception occurred processing WSGI script '/var/www/FlaskApp/flaskapp.wsgi'., referer: http://www.zachflask.tk/
[Thu Sep 14 08:16:13.986561 2017] [wsgi:error] [pid 32700] [client 128.206.251.96:20921] Traceback (most recent call last):, referer: http://www.zachflask.tk/
[Thu Sep 14 08:16:13.986589 2017] [wsgi:error] [pid 32700] [client 128.206.251.96:20921]   File "/usr/local/lib/python2.7/dist-packages/flask/app.py", line 1997, in __call__, referer: http://www.zachflask.tk/
[Thu Sep 14 08:16:13.987065 2017] [wsgi:error] [pid 32700] [client 128.206.251.96:20921]     return self.wsgi_app(environ, start_response), referer: http://www.zachflask.tk/
[Thu Sep 14 08:16:13.987078 2017] [wsgi:error] [pid 32700] [client 128.206.251.96:20921]   File "/usr/local/lib/python2.7/dist-packages/flask/app.py", line 1985, in wsgi_app, referer: http://www.zachflask.tk/
[Thu Sep 14 08:16:13.987129 2017] [wsgi:error] [pid 32700] [client 128.206.251.96:20921]     response = self.handle_exception(e), referer: http://www.zachflask.tk/
[Thu Sep 14 08:16:13.987138 2017] [wsgi:error] [pid 32700] [client 128.206.251.96:20921]   File "/usr/local/lib/python2.7/dist-packages/flask/app.py", line 1540, in handle_exception, referer: http://www.zachflask.tk/
[Thu Sep 14 08:16:13.987147 2017] [wsgi:error] [pid 32700] [client 128.206.251.96:20921]     reraise(exc_type, exc_value, tb), referer: http://www.zachflask.tk/
[Thu Sep 14 08:16:13.987152 2017] [wsgi:error] [pid 32700] [client 128.206.251.96:20921]   File "/usr/local/lib/python2.7/dist-packages/flask/app.py", line 1982, in wsgi_app, referer: http://www.zachflask.tk/
[Thu Sep 14 08:16:13.987159 2017] [wsgi:error] [pid 32700] [client 128.206.251.96:20921]     response = self.full_dispatch_request(), referer: http://www.zachflask.tk/
[Thu Sep 14 08:16:13.987164 2017] [wsgi:error] [pid 32700] [client 128.206.251.96:20921]   File "/usr/local/lib/python2.7/dist-packages/flask/app.py", line 1614, in full_dispatch_request, referer: http://www.zachflask.tk/
[Thu Sep 14 08:16:13.987171 2017] [wsgi:error] [pid 32700] [client 128.206.251.96:20921]     rv = self.handle_user_exception(e), referer: http://www.zachflask.tk/
[Thu Sep 14 08:16:13.987176 2017] [wsgi:error] [pid 32700] [client 128.206.251.96:20921]   File "/usr/local/lib/python2.7/dist-packages/flask/app.py", line 1517, in handle_user_exception, referer: http://www.zachflask.tk/
[Thu Sep 14 08:16:13.987194 2017] [wsgi:error] [pid 32700] [client 128.206.251.96:20921]     reraise(exc_type, exc_value, tb), referer: http://www.zachflask.tk/
[Thu Sep 14 08:16:13.987199 2017] [wsgi:error] [pid 32700] [client 128.206.251.96:20921]   File "/usr/local/lib/python2.7/dist-packages/flask/app.py", line 1612, in full_dispatch_request, referer: http://www.zachflask.tk/
[Thu Sep 14 08:16:13.987205 2017] [wsgi:error] [pid 32700] [client 128.206.251.96:20921]     rv = self.dispatch_request(), referer: http://www.zachflask.tk/
[Thu Sep 14 08:16:13.987210 2017] [wsgi:error] [pid 32700] [client 128.206.251.96:20921]   File "/usr/local/lib/python2.7/dist-packages/flask/app.py", line 1598, in dispatch_request, referer: http://www.zachflask.tk/
[Thu Sep 14 08:16:13.987216 2017] [wsgi:error] [pid 32700] [client 128.206.251.96:20921]     return self.view_functions[rule.endpoint](**req.view_args), referer: http://www.zachflask.tk/
[Thu Sep 14 08:16:13.987222 2017] [wsgi:error] [pid 32700] [client 128.206.251.96:20921]   File "/var/www/FlaskApp/FlaskApp/FlaskApp.py", line 80, in add_entry, referer: http://www.zachflask.tk/
[Thu Sep 14 08:16:13.987263 2017] [wsgi:error] [pid 32700] [client 128.206.251.96:20921]     [request.form['title'], request.form['text']]), referer: http://www.zachflask.tk/
[Thu Sep 14 08:16:13.987285 2017] [wsgi:error] [pid 32700] [client 128.206.251.96:20921] OperationalError: database is locked, referer: http://www.zachflask.tk/
[Thu Sep 14 08:18:54.359327 2017] [wsgi:error] [pid 32696] [client 128.206.251.96:30510] mod_wsgi (pid=32696): Exception occurred processing WSGI script '/var/www/FlaskApp/flaskapp.wsgi'., referer: http://www.zachflask.tk/
[Thu Sep 14 08:18:54.359406 2017] [wsgi:error] [pid 32696] [client 128.206.251.96:30510] Traceback (most recent call last):, referer: http://www.zachflask.tk/
[Thu Sep 14 08:18:54.359434 2017] [wsgi:error] [pid 32696] [client 128.206.251.96:30510]   File "/usr/local/lib/python2.7/dist-packages/flask/app.py", line 1997, in __call__, referer: http://www.zachflask.tk/
[Thu Sep 14 08:18:54.359891 2017] [wsgi:error] [pid 32696] [client 128.206.251.96:30510]     return self.wsgi_app(environ, start_response), referer: http://www.zachflask.tk/
[Thu Sep 14 08:18:54.359903 2017] [wsgi:error] [pid 32696] [client 128.206.251.96:30510]   File "/usr/local/lib/python2.7/dist-packages/flask/app.py", line 1985, in wsgi_app, referer: http://www.zachflask.tk/
[Thu Sep 14 08:18:54.359918 2017] [wsgi:error] [pid 32696] [client 128.206.251.96:30510]     response = self.handle_exception(e), referer: http://www.zachflask.tk/
[Thu Sep 14 08:18:54.359924 2017] [wsgi:error] [pid 32696] [client 128.206.251.96:30510]   File "/usr/local/lib/python2.7/dist-packages/flask/app.py", line 1540, in handle_exception, referer: http://www.zachflask.tk/
[Thu Sep 14 08:18:54.359932 2017] [wsgi:error] [pid 32696] [client 128.206.251.96:30510]     reraise(exc_type, exc_value, tb), referer: http://www.zachflask.tk/
[Thu Sep 14 08:18:54.359937 2017] [wsgi:error] [pid 32696] [client 128.206.251.96:30510]   File "/usr/local/lib/python2.7/dist-packages/flask/app.py", line 1982, in wsgi_app, referer: http://www.zachflask.tk/
[Thu Sep 14 08:18:54.359944 2017] [wsgi:error] [pid 32696] [client 128.206.251.96:30510]     response = self.full_dispatch_request(), referer: http://www.zachflask.tk/
[Thu Sep 14 08:18:54.359949 2017] [wsgi:error] [pid 32696] [client 128.206.251.96:30510]   File "/usr/local/lib/python2.7/dist-packages/flask/app.py", line 1614, in full_dispatch_request, referer: http://www.zachflask.tk/
[Thu Sep 14 08:18:54.359956 2017] [wsgi:error] [pid 32696] [client 128.206.251.96:30510]     rv = self.handle_user_exception(e), referer: http://www.zachflask.tk/
[Thu Sep 14 08:18:54.359960 2017] [wsgi:error] [pid 32696] [client 128.206.251.96:30510]   File "/usr/local/lib/python2.7/dist-packages/flask/app.py", line 1517, in handle_user_exception, referer: http://www.zachflask.tk/
[Thu Sep 14 08:18:54.359978 2017] [wsgi:error] [pid 32696] [client 128.206.251.96:30510]     reraise(exc_type, exc_value, tb), referer: http://www.zachflask.tk/
[Thu Sep 14 08:18:54.359983 2017] [wsgi:error] [pid 32696] [client 128.206.251.96:30510]   File "/usr/local/lib/python2.7/dist-packages/flask/app.py", line 1612, in full_dispatch_request, referer: http://www.zachflask.tk/
[Thu Sep 14 08:18:54.359989 2017] [wsgi:error] [pid 32696] [client 128.206.251.96:30510]     rv = self.dispatch_request(), referer: http://www.zachflask.tk/
[Thu Sep 14 08:18:54.359994 2017] [wsgi:error] [pid 32696] [client 128.206.251.96:30510]   File "/usr/local/lib/python2.7/dist-packages/flask/app.py", line 1598, in dispatch_request, referer: http://www.zachflask.tk/
[Thu Sep 14 08:18:54.360000 2017] [wsgi:error] [pid 32696] [client 128.206.251.96:30510]     return self.view_functions[rule.endpoint](**req.view_args), referer: http://www.zachflask.tk/
[Thu Sep 14 08:18:54.360008 2017] [wsgi:error] [pid 32696] [client 128.206.251.96:30510]   File "/var/www/FlaskApp/FlaskApp/FlaskApp.py", line 80, in add_entry, referer: http://www.zachflask.tk/
[Thu Sep 14 08:18:54.360052 2017] [wsgi:error] [pid 32696] [client 128.206.251.96:30510]     [request.form['title'], request.form['text']]), referer: http://www.zachflask.tk/
[Thu Sep 14 08:18:54.360076 2017] [wsgi:error] [pid 32696] [client 128.206.251.96:30510] OperationalError: database is locked, referer: http://www.zachflask.tk/
[Thu Sep 14 08:20:34.795717 2017] [wsgi:error] [pid 408] [client 128.206.251.96:30355] mod_wsgi (pid=408): Exception occurred processing WSGI script '/var/www/FlaskApp/flaskapp.wsgi'., referer: http://www.zachflask.tk/
[Thu Sep 14 08:20:34.795780 2017] [wsgi:error] [pid 408] [client 128.206.251.96:30355] Traceback (most recent call last):, referer: http://www.zachflask.tk/
[Thu Sep 14 08:20:34.795799 2017] [wsgi:error] [pid 408] [client 128.206.251.96:30355]   File "/usr/local/lib/python2.7/dist-packages/flask/app.py", line 1997, in __call__, referer: http://www.zachflask.tk/
[Thu Sep 14 08:20:34.796189 2017] [wsgi:error] [pid 408] [client 128.206.251.96:30355]     return self.wsgi_app(environ, start_response), referer: http://www.zachflask.tk/
[Thu Sep 14 08:20:34.796202 2017] [wsgi:error] [pid 408] [client 128.206.251.96:30355]   File "/usr/local/lib/python2.7/dist-packages/flask/app.py", line 1985, in wsgi_app, referer: http://www.zachflask.tk/
[Thu Sep 14 08:20:34.796216 2017] [wsgi:error] [pid 408] [client 128.206.251.96:30355]     response = self.handle_exception(e), referer: http://www.zachflask.tk/
[Thu Sep 14 08:20:34.796222 2017] [wsgi:error] [pid 408] [client 128.206.251.96:30355]   File "/usr/local/lib/python2.7/dist-packages/flask/app.py", line 1540, in handle_exception, referer: http://www.zachflask.tk/
[Thu Sep 14 08:20:34.796230 2017] [wsgi:error] [pid 408] [client 128.206.251.96:30355]     reraise(exc_type, exc_value, tb), referer: http://www.zachflask.tk/
[Thu Sep 14 08:20:34.796236 2017] [wsgi:error] [pid 408] [client 128.206.251.96:30355]   File "/usr/local/lib/python2.7/dist-packages/flask/app.py", line 1982, in wsgi_app, referer: http://www.zachflask.tk/
[Thu Sep 14 08:20:34.796243 2017] [wsgi:error] [pid 408] [client 128.206.251.96:30355]     response = self.full_dispatch_request(), referer: http://www.zachflask.tk/
[Thu Sep 14 08:20:34.796248 2017] [wsgi:error] [pid 408] [client 128.206.251.96:30355]   File "/usr/local/lib/python2.7/dist-packages/flask/app.py", line 1614, in full_dispatch_request, referer: http://www.zachflask.tk/
[Thu Sep 14 08:20:34.796256 2017] [wsgi:error] [pid 408] [client 128.206.251.96:30355]     rv = self.handle_user_exception(e), referer: http://www.zachflask.tk/
[Thu Sep 14 08:20:34.796261 2017] [wsgi:error] [pid 408] [client 128.206.251.96:30355]   File "/usr/local/lib/python2.7/dist-packages/flask/app.py", line 1517, in handle_user_exception, referer: http://www.zachflask.tk/
[Thu Sep 14 08:20:34.796267 2017] [wsgi:error] [pid 408] [client 128.206.251.96:30355]     reraise(exc_type, exc_value, tb), referer: http://www.zachflask.tk/
[Thu Sep 14 08:20:34.796283 2017] [wsgi:error] [pid 408] [client 128.206.251.96:30355]   File "/usr/local/lib/python2.7/dist-packages/flask/app.py", line 1612, in full_dispatch_request, referer: http://www.zachflask.tk/
[Thu Sep 14 08:20:34.796291 2017] [wsgi:error] [pid 408] [client 128.206.251.96:30355]     rv = self.dispatch_request(), referer: http://www.zachflask.tk/
[Thu Sep 14 08:20:34.796296 2017] [wsgi:error] [pid 408] [client 128.206.251.96:30355]   File "/usr/local/lib/python2.7/dist-packages/flask/app.py", line 1598, in dispatch_request, referer: http://www.zachflask.tk/
[Thu Sep 14 08:20:34.796302 2017] [wsgi:error] [pid 408] [client 128.206.251.96:30355]     return self.view_functions[rule.endpoint](**req.view_args), referer: http://www.zachflask.tk/
[Thu Sep 14 08:20:34.796307 2017] [wsgi:error] [pid 408] [client 128.206.251.96:30355]   File "/var/www/FlaskApp/FlaskApp/FlaskApp.py", line 80, in add_entry, referer: http://www.zachflask.tk/
[Thu Sep 14 08:20:34.796344 2017] [wsgi:error] [pid 408] [client 128.206.251.96:30355]     [request.form['title'], request.form['text']]), referer: http://www.zachflask.tk/
[Thu Sep 14 08:20:34.796363 2017] [wsgi:error] [pid 408] [client 128.206.251.96:30355] OperationalError: unable to open database file, referer: http://www.zachflask.tk/
[Thu Sep 14 08:27:45.540216 2017] [wsgi:error] [pid 412] [client 128.206.251.96:10891] mod_wsgi (pid=412): Exception occurred processing WSGI script '/var/www/FlaskApp/flaskapp.wsgi'.
[Thu Sep 14 08:27:45.540282 2017] [wsgi:error] [pid 412] [client 128.206.251.96:10891] Traceback (most recent call last):
[Thu Sep 14 08:27:45.540302 2017] [wsgi:error] [pid 412] [client 128.206.251.96:10891]   File "/usr/local/lib/python2.7/dist-packages/flask/app.py", line 1997, in __call__
[Thu Sep 14 08:27:45.540693 2017] [wsgi:error] [pid 412] [client 128.206.251.96:10891]     return self.wsgi_app(environ, start_response)
[Thu Sep 14 08:27:45.540704 2017] [wsgi:error] [pid 412] [client 128.206.251.96:10891]   File "/usr/local/lib/python2.7/dist-packages/flask/app.py", line 1985, in wsgi_app
[Thu Sep 14 08:27:45.540718 2017] [wsgi:error] [pid 412] [client 128.206.251.96:10891]     response = self.handle_exception(e)
[Thu Sep 14 08:27:45.540724 2017] [wsgi:error] [pid 412] [client 128.206.251.96:10891]   File "/usr/local/lib/python2.7/dist-packages/flask/app.py", line 1540, in handle_exception
[Thu Sep 14 08:27:45.540732 2017] [wsgi:error] [pid 412] [client 128.206.251.96:10891]     reraise(exc_type, exc_value, tb)
[Thu Sep 14 08:27:45.540737 2017] [wsgi:error] [pid 412] [client 128.206.251.96:10891]   File "/usr/local/lib/python2.7/dist-packages/flask/app.py", line 1982, in wsgi_app
[Thu Sep 14 08:27:45.540744 2017] [wsgi:error] [pid 412] [client 128.206.251.96:10891]     response = self.full_dispatch_request()
[Thu Sep 14 08:27:45.540749 2017] [wsgi:error] [pid 412] [client 128.206.251.96:10891]   File "/usr/local/lib/python2.7/dist-packages/flask/app.py", line 1614, in full_dispatch_request
[Thu Sep 14 08:27:45.540756 2017] [wsgi:error] [pid 412] [client 128.206.251.96:10891]     rv = self.handle_user_exception(e)
[Thu Sep 14 08:27:45.540760 2017] [wsgi:error] [pid 412] [client 128.206.251.96:10891]   File "/usr/local/lib/python2.7/dist-packages/flask/app.py", line 1517, in handle_user_exception
[Thu Sep 14 08:27:45.540767 2017] [wsgi:error] [pid 412] [client 128.206.251.96:10891]     reraise(exc_type, exc_value, tb)
[Thu Sep 14 08:27:45.540772 2017] [wsgi:error] [pid 412] [client 128.206.251.96:10891]   File "/usr/local/lib/python2.7/dist-packages/flask/app.py", line 1612, in full_dispatch_request
[Thu Sep 14 08:27:45.540779 2017] [wsgi:error] [pid 412] [client 128.206.251.96:10891]     rv = self.dispatch_request()
[Thu Sep 14 08:27:45.540783 2017] [wsgi:error] [pid 412] [client 128.206.251.96:10891]   File "/usr/local/lib/python2.7/dist-packages/flask/app.py", line 1598, in dispatch_request
[Thu Sep 14 08:27:45.540790 2017] [wsgi:error] [pid 412] [client 128.206.251.96:10891]     return self.view_functions[rule.endpoint](**req.view_args)
[Thu Sep 14 08:27:45.540807 2017] [wsgi:error] [pid 412] [client 128.206.251.96:10891]   File "/var/www/FlaskApp/FlaskApp/FlaskApp.py", line 69, in show_entries
[Thu Sep 14 08:27:45.540851 2017] [wsgi:error] [pid 412] [client 128.206.251.96:10891]     db = get_db()
[Thu Sep 14 08:27:45.540860 2017] [wsgi:error] [pid 412] [client 128.206.251.96:10891]   File "/var/www/FlaskApp/FlaskApp/FlaskApp.py", line 37, in get_db
[Thu Sep 14 08:27:45.540870 2017] [wsgi:error] [pid 412] [client 128.206.251.96:10891]     g.sqlite_db = connect_db()
[Thu Sep 14 08:27:45.540875 2017] [wsgi:error] [pid 412] [client 128.206.251.96:10891]   File "/var/www/FlaskApp/FlaskApp/FlaskApp.py", line 29, in connect_db
[Thu Sep 14 08:27:45.540882 2017] [wsgi:error] [pid 412] [client 128.206.251.96:10891]     rv = sqlite3.connect('FlaskApp.db', timeout=5)
[Thu Sep 14 08:27:45.540899 2017] [wsgi:error] [pid 412] [client 128.206.251.96:10891] OperationalError: unable to open database file
[Thu Sep 14 08:27:46.102161 2017] [wsgi:error] [pid 417] [client 128.206.251.96:41773] mod_wsgi (pid=417): Exception occurred processing WSGI script '/var/www/FlaskApp/flaskapp.wsgi'.
[Thu Sep 14 08:27:46.102218 2017] [wsgi:error] [pid 417] [client 128.206.251.96:41773] Traceback (most recent call last):
[Thu Sep 14 08:27:46.102237 2017] [wsgi:error] [pid 417] [client 128.206.251.96:41773]   File "/usr/local/lib/python2.7/dist-packages/flask/app.py", line 1997, in __call__
[Thu Sep 14 08:27:46.102626 2017] [wsgi:error] [pid 417] [client 128.206.251.96:41773]     return self.wsgi_app(environ, start_response)
[Thu Sep 14 08:27:46.102637 2017] [wsgi:error] [pid 417] [client 128.206.251.96:41773]   File "/usr/local/lib/python2.7/dist-packages/flask/app.py", line 1985, in wsgi_app
[Thu Sep 14 08:27:46.102651 2017] [wsgi:error] [pid 417] [client 128.206.251.96:41773]     response = self.handle_exception(e)
[Thu Sep 14 08:27:46.102656 2017] [wsgi:error] [pid 417] [client 128.206.251.96:41773]   File "/usr/local/lib/python2.7/dist-packages/flask/app.py", line 1540, in handle_exception
[Thu Sep 14 08:27:46.102665 2017] [wsgi:error] [pid 417] [client 128.206.251.96:41773]     reraise(exc_type, exc_value, tb)
[Thu Sep 14 08:27:46.102670 2017] [wsgi:error] [pid 417] [client 128.206.251.96:41773]   File "/usr/local/lib/python2.7/dist-packages/flask/app.py", line 1982, in wsgi_app
[Thu Sep 14 08:27:46.102677 2017] [wsgi:error] [pid 417] [client 128.206.251.96:41773]     response = self.full_dispatch_request()
[Thu Sep 14 08:27:46.102681 2017] [wsgi:error] [pid 417] [client 128.206.251.96:41773]   File "/usr/local/lib/python2.7/dist-packages/flask/app.py", line 1614, in full_dispatch_request
[Thu Sep 14 08:27:46.102688 2017] [wsgi:error] [pid 417] [client 128.206.251.96:41773]     rv = self.handle_user_exception(e)
[Thu Sep 14 08:27:46.102693 2017] [wsgi:error] [pid 417] [client 128.206.251.96:41773]   File "/usr/local/lib/python2.7/dist-packages/flask/app.py", line 1517, in handle_user_exception
[Thu Sep 14 08:27:46.102700 2017] [wsgi:error] [pid 417] [client 128.206.251.96:41773]     reraise(exc_type, exc_value, tb)
[Thu Sep 14 08:27:46.102704 2017] [wsgi:error] [pid 417] [client 128.206.251.96:41773]   File "/usr/local/lib/python2.7/dist-packages/flask/app.py", line 1612, in full_dispatch_request
[Thu Sep 14 08:27:46.102711 2017] [wsgi:error] [pid 417] [client 128.206.251.96:41773]     rv = self.dispatch_request()
[Thu Sep 14 08:27:46.102715 2017] [wsgi:error] [pid 417] [client 128.206.251.96:41773]   File "/usr/local/lib/python2.7/dist-packages/flask/app.py", line 1598, in dispatch_request
[Thu Sep 14 08:27:46.102722 2017] [wsgi:error] [pid 417] [client 128.206.251.96:41773]     return self.view_functions[rule.endpoint](**req.view_args)
[Thu Sep 14 08:27:46.102729 2017] [wsgi:error] [pid 417] [client 128.206.251.96:41773]   File "/var/www/FlaskApp/FlaskApp/FlaskApp.py", line 69, in show_entries
[Thu Sep 14 08:27:46.102770 2017] [wsgi:error] [pid 417] [client 128.206.251.96:41773]     db = get_db()
[Thu Sep 14 08:27:46.102779 2017] [wsgi:error] [pid 417] [client 128.206.251.96:41773]   File "/var/www/FlaskApp/FlaskApp/FlaskApp.py", line 37, in get_db
[Thu Sep 14 08:27:46.102802 2017] [wsgi:error] [pid 417] [client 128.206.251.96:41773]     g.sqlite_db = connect_db()
[Thu Sep 14 08:27:46.102808 2017] [wsgi:error] [pid 417] [client 128.206.251.96:41773]   File "/var/www/FlaskApp/FlaskApp/FlaskApp.py", line 29, in connect_db
[Thu Sep 14 08:27:46.102815 2017] [wsgi:error] [pid 417] [client 128.206.251.96:41773]     rv = sqlite3.connect('FlaskApp.db', timeout=5)
[Thu Sep 14 08:27:46.102831 2017] [wsgi:error] [pid 417] [client 128.206.251.96:41773] OperationalError: unable to open database file
[Thu Sep 14 08:31:11.492939 2017] [wsgi:error] [pid 414] [client 128.206.251.96:10935] mod_wsgi (pid=414): Exception occurred processing WSGI script '/var/www/FlaskApp/flaskapp.wsgi'.
[Thu Sep 14 08:31:11.493004 2017] [wsgi:error] [pid 414] [client 128.206.251.96:10935] Traceback (most recent call last):
[Thu Sep 14 08:31:11.493023 2017] [wsgi:error] [pid 414] [client 128.206.251.96:10935]   File "/usr/local/lib/python2.7/dist-packages/flask/app.py", line 1997, in __call__
[Thu Sep 14 08:31:11.493409 2017] [wsgi:error] [pid 414] [client 128.206.251.96:10935]     return self.wsgi_app(environ, start_response)
[Thu Sep 14 08:31:11.493419 2017] [wsgi:error] [pid 414] [client 128.206.251.96:10935]   File "/usr/local/lib/python2.7/dist-packages/flask/app.py", line 1985, in wsgi_app
[Thu Sep 14 08:31:11.493433 2017] [wsgi:error] [pid 414] [client 128.206.251.96:10935]     response = self.handle_exception(e)
[Thu Sep 14 08:31:11.493439 2017] [wsgi:error] [pid 414] [client 128.206.251.96:10935]   File "/usr/local/lib/python2.7/dist-packages/flask/app.py", line 1540, in handle_exception
[Thu Sep 14 08:31:11.493448 2017] [wsgi:error] [pid 414] [client 128.206.251.96:10935]     reraise(exc_type, exc_value, tb)
[Thu Sep 14 08:31:11.493453 2017] [wsgi:error] [pid 414] [client 128.206.251.96:10935]   File "/usr/local/lib/python2.7/dist-packages/flask/app.py", line 1982, in wsgi_app
[Thu Sep 14 08:31:11.493460 2017] [wsgi:error] [pid 414] [client 128.206.251.96:10935]     response = self.full_dispatch_request()
[Thu Sep 14 08:31:11.493465 2017] [wsgi:error] [pid 414] [client 128.206.251.96:10935]   File "/usr/local/lib/python2.7/dist-packages/flask/app.py", line 1614, in full_dispatch_request
[Thu Sep 14 08:31:11.493472 2017] [wsgi:error] [pid 414] [client 128.206.251.96:10935]     rv = self.handle_user_exception(e)
[Thu Sep 14 08:31:11.493477 2017] [wsgi:error] [pid 414] [client 128.206.251.96:10935]   File "/usr/local/lib/python2.7/dist-packages/flask/app.py", line 1517, in handle_user_exception
[Thu Sep 14 08:31:11.493485 2017] [wsgi:error] [pid 414] [client 128.206.251.96:10935]     reraise(exc_type, exc_value, tb)
[Thu Sep 14 08:31:11.493489 2017] [wsgi:error] [pid 414] [client 128.206.251.96:10935]   File "/usr/local/lib/python2.7/dist-packages/flask/app.py", line 1612, in full_dispatch_request
[Thu Sep 14 08:31:11.493496 2017] [wsgi:error] [pid 414] [client 128.206.251.96:10935]     rv = self.dispatch_request()
[Thu Sep 14 08:31:11.493501 2017] [wsgi:error] [pid 414] [client 128.206.251.96:10935]   File "/usr/local/lib/python2.7/dist-packages/flask/app.py", line 1598, in dispatch_request
[Thu Sep 14 08:31:11.493508 2017] [wsgi:error] [pid 414] [client 128.206.251.96:10935]     return self.view_functions[rule.endpoint](**req.view_args)
[Thu Sep 14 08:31:11.493515 2017] [wsgi:error] [pid 414] [client 128.206.251.96:10935]   File "/var/www/FlaskApp/FlaskApp/FlaskApp.py", line 69, in show_entries
[Thu Sep 14 08:31:11.493557 2017] [wsgi:error] [pid 414] [client 128.206.251.96:10935]     db = get_db()
[Thu Sep 14 08:31:11.493566 2017] [wsgi:error] [pid 414] [client 128.206.251.96:10935]   File "/var/www/FlaskApp/FlaskApp/FlaskApp.py", line 37, in get_db
[Thu Sep 14 08:31:11.493576 2017] [wsgi:error] [pid 414] [client 128.206.251.96:10935]     g.sqlite_db = connect_db()
[Thu Sep 14 08:31:11.493582 2017] [wsgi:error] [pid 414] [client 128.206.251.96:10935]   File "/var/www/FlaskApp/FlaskApp/FlaskApp.py", line 29, in connect_db
[Thu Sep 14 08:31:11.493602 2017] [wsgi:error] [pid 414] [client 128.206.251.96:10935]     rv = sqlite3.connect('FlaskApp.db', timeout=5)
[Thu Sep 14 08:31:11.493619 2017] [wsgi:error] [pid 414] [client 128.206.251.96:10935] OperationalError: unable to open database file
[Thu Sep 14 08:31:34.992241 2017] [wsgi:error] [pid 692] [client 128.206.251.96:56190] mod_wsgi (pid=692): Exception occurred processing WSGI script '/var/www/FlaskApp/flaskapp.wsgi'.
[Thu Sep 14 08:31:34.992307 2017] [wsgi:error] [pid 692] [client 128.206.251.96:56190] Traceback (most recent call last):
[Thu Sep 14 08:31:34.992326 2017] [wsgi:error] [pid 692] [client 128.206.251.96:56190]   File "/usr/local/lib/python2.7/dist-packages/flask/app.py", line 1997, in __call__
[Thu Sep 14 08:31:34.992705 2017] [wsgi:error] [pid 692] [client 128.206.251.96:56190]     return self.wsgi_app(environ, start_response)
[Thu Sep 14 08:31:34.992716 2017] [wsgi:error] [pid 692] [client 128.206.251.96:56190]   File "/usr/local/lib/python2.7/dist-packages/flask/app.py", line 1985, in wsgi_app
[Thu Sep 14 08:31:34.992729 2017] [wsgi:error] [pid 692] [client 128.206.251.96:56190]     response = self.handle_exception(e)
[Thu Sep 14 08:31:34.992734 2017] [wsgi:error] [pid 692] [client 128.206.251.96:56190]   File "/usr/local/lib/python2.7/dist-packages/flask/app.py", line 1540, in handle_exception
[Thu Sep 14 08:31:34.992742 2017] [wsgi:error] [pid 692] [client 128.206.251.96:56190]     reraise(exc_type, exc_value, tb)
[Thu Sep 14 08:31:34.992746 2017] [wsgi:error] [pid 692] [client 128.206.251.96:56190]   File "/usr/local/lib/python2.7/dist-packages/flask/app.py", line 1982, in wsgi_app
[Thu Sep 14 08:31:34.992752 2017] [wsgi:error] [pid 692] [client 128.206.251.96:56190]     response = self.full_dispatch_request()
[Thu Sep 14 08:31:34.992757 2017] [wsgi:error] [pid 692] [client 128.206.251.96:56190]   File "/usr/local/lib/python2.7/dist-packages/flask/app.py", line 1614, in full_dispatch_request
[Thu Sep 14 08:31:34.992763 2017] [wsgi:error] [pid 692] [client 128.206.251.96:56190]     rv = self.handle_user_exception(e)
[Thu Sep 14 08:31:34.992767 2017] [wsgi:error] [pid 692] [client 128.206.251.96:56190]   File "/usr/local/lib/python2.7/dist-packages/flask/app.py", line 1517, in handle_user_exception
[Thu Sep 14 08:31:34.992773 2017] [wsgi:error] [pid 692] [client 128.206.251.96:56190]     reraise(exc_type, exc_value, tb)
[Thu Sep 14 08:31:34.992778 2017] [wsgi:error] [pid 692] [client 128.206.251.96:56190]   File "/usr/local/lib/python2.7/dist-packages/flask/app.py", line 1612, in full_dispatch_request
[Thu Sep 14 08:31:34.992784 2017] [wsgi:error] [pid 692] [client 128.206.251.96:56190]     rv = self.dispatch_request()
[Thu Sep 14 08:31:34.992788 2017] [wsgi:error] [pid 692] [client 128.206.251.96:56190]   File "/usr/local/lib/python2.7/dist-packages/flask/app.py", line 1598, in dispatch_request
[Thu Sep 14 08:31:34.992794 2017] [wsgi:error] [pid 692] [client 128.206.251.96:56190]     return self.view_functions[rule.endpoint](**req.view_args)
[Thu Sep 14 08:31:34.992800 2017] [wsgi:error] [pid 692] [client 128.206.251.96:56190]   File "/var/www/FlaskApp/FlaskApp/FlaskApp.py", line 69, in show_entries
[Thu Sep 14 08:31:34.992839 2017] [wsgi:error] [pid 692] [client 128.206.251.96:56190]     db = get_db()
[Thu Sep 14 08:31:34.992847 2017] [wsgi:error] [pid 692] [client 128.206.251.96:56190]   File "/var/www/FlaskApp/FlaskApp/FlaskApp.py", line 37, in get_db
[Thu Sep 14 08:31:34.992856 2017] [wsgi:error] [pid 692] [client 128.206.251.96:56190]     g.sqlite_db = connect_db()
[Thu Sep 14 08:31:34.992860 2017] [wsgi:error] [pid 692] [client 128.206.251.96:56190]   File "/var/www/FlaskApp/FlaskApp/FlaskApp.py", line 29, in connect_db
[Thu Sep 14 08:31:34.992867 2017] [wsgi:error] [pid 692] [client 128.206.251.96:56190]     rv = sqlite3.connect('FlaskApp.db', timeout=5)
[Thu Sep 14 08:31:34.992883 2017] [wsgi:error] [pid 692] [client 128.206.251.96:56190] OperationalError: unable to open database file
[Thu Sep 14 08:33:06.303527 2017] [wsgi:error] [pid 692] [client 128.206.251.96:48427] mod_wsgi (pid=692): Exception occurred processing WSGI script '/var/www/FlaskApp/flaskapp.wsgi'., referer: http://www.zachflask.tk/
[Thu Sep 14 08:33:06.303594 2017] [wsgi:error] [pid 692] [client 128.206.251.96:48427] Traceback (most recent call last):, referer: http://www.zachflask.tk/
[Thu Sep 14 08:33:06.303615 2017] [wsgi:error] [pid 692] [client 128.206.251.96:48427]   File "/usr/local/lib/python2.7/dist-packages/flask/app.py", line 1997, in __call__, referer: http://www.zachflask.tk/
[Thu Sep 14 08:33:06.303647 2017] [wsgi:error] [pid 692] [client 128.206.251.96:48427]     return self.wsgi_app(environ, start_response), referer: http://www.zachflask.tk/
[Thu Sep 14 08:33:06.303653 2017] [wsgi:error] [pid 692] [client 128.206.251.96:48427]   File "/usr/local/lib/python2.7/dist-packages/flask/app.py", line 1985, in wsgi_app, referer: http://www.zachflask.tk/
[Thu Sep 14 08:33:06.303661 2017] [wsgi:error] [pid 692] [client 128.206.251.96:48427]     response = self.handle_exception(e), referer: http://www.zachflask.tk/
[Thu Sep 14 08:33:06.303666 2017] [wsgi:error] [pid 692] [client 128.206.251.96:48427]   File "/usr/local/lib/python2.7/dist-packages/flask/app.py", line 1540, in handle_exception, referer: http://www.zachflask.tk/
[Thu Sep 14 08:33:06.303673 2017] [wsgi:error] [pid 692] [client 128.206.251.96:48427]     reraise(exc_type, exc_value, tb), referer: http://www.zachflask.tk/
[Thu Sep 14 08:33:06.303677 2017] [wsgi:error] [pid 692] [client 128.206.251.96:48427]   File "/usr/local/lib/python2.7/dist-packages/flask/app.py", line 1982, in wsgi_app, referer: http://www.zachflask.tk/
[Thu Sep 14 08:33:06.303684 2017] [wsgi:error] [pid 692] [client 128.206.251.96:48427]     response = self.full_dispatch_request(), referer: http://www.zachflask.tk/
[Thu Sep 14 08:33:06.303688 2017] [wsgi:error] [pid 692] [client 128.206.251.96:48427]   File "/usr/local/lib/python2.7/dist-packages/flask/app.py", line 1614, in full_dispatch_request, referer: http://www.zachflask.tk/
[Thu Sep 14 08:33:06.303694 2017] [wsgi:error] [pid 692] [client 128.206.251.96:48427]     rv = self.handle_user_exception(e), referer: http://www.zachflask.tk/
[Thu Sep 14 08:33:06.303698 2017] [wsgi:error] [pid 692] [client 128.206.251.96:48427]   File "/usr/local/lib/python2.7/dist-packages/flask/app.py", line 1517, in handle_user_exception, referer: http://www.zachflask.tk/
[Thu Sep 14 08:33:06.303704 2017] [wsgi:error] [pid 692] [client 128.206.251.96:48427]     reraise(exc_type, exc_value, tb), referer: http://www.zachflask.tk/
[Thu Sep 14 08:33:06.303708 2017] [wsgi:error] [pid 692] [client 128.206.251.96:48427]   File "/usr/local/lib/python2.7/dist-packages/flask/app.py", line 1612, in full_dispatch_request, referer: http://www.zachflask.tk/
[Thu Sep 14 08:33:06.303715 2017] [wsgi:error] [pid 692] [client 128.206.251.96:48427]     rv = self.dispatch_request(), referer: http://www.zachflask.tk/
[Thu Sep 14 08:33:06.303719 2017] [wsgi:error] [pid 692] [client 128.206.251.96:48427]   File "/usr/local/lib/python2.7/dist-packages/flask/app.py", line 1598, in dispatch_request, referer: http://www.zachflask.tk/
[Thu Sep 14 08:33:06.303725 2017] [wsgi:error] [pid 692] [client 128.206.251.96:48427]     return self.view_functions[rule.endpoint](**req.view_args), referer: http://www.zachflask.tk/
[Thu Sep 14 08:33:06.303730 2017] [wsgi:error] [pid 692] [client 128.206.251.96:48427]   File "/var/www/FlaskApp/FlaskApp/FlaskApp.py", line 79, in add_entry, referer: http://www.zachflask.tk/
[Thu Sep 14 08:33:06.303799 2017] [wsgi:error] [pid 692] [client 128.206.251.96:48427]     db = get_db(), referer: http://www.zachflask.tk/
[Thu Sep 14 08:33:06.303807 2017] [wsgi:error] [pid 692] [client 128.206.251.96:48427]   File "/var/www/FlaskApp/FlaskApp/FlaskApp.py", line 37, in get_db, referer: http://www.zachflask.tk/
[Thu Sep 14 08:33:06.303815 2017] [wsgi:error] [pid 692] [client 128.206.251.96:48427]     g.sqlite_db = connect_db(), referer: http://www.zachflask.tk/
[Thu Sep 14 08:33:06.303820 2017] [wsgi:error] [pid 692] [client 128.206.251.96:48427]   File "/var/www/FlaskApp/FlaskApp/FlaskApp.py", line 29, in connect_db, referer: http://www.zachflask.tk/
[Thu Sep 14 08:33:06.303833 2017] [wsgi:error] [pid 692] [client 128.206.251.96:48427]     # rv = sqlite3.connect('FlaskApp.db', timeout=5), referer: http://www.zachflask.tk/
[Thu Sep 14 08:33:06.303848 2017] [wsgi:error] [pid 692] [client 128.206.251.96:48427] OperationalError: unable to open database file, referer: http://www.zachflask.tk/
[Thu Sep 14 08:36:17.651799 2017] [wsgi:error] [pid 907] [client 128.206.251.96:27284] mod_wsgi (pid=907): Exception occurred processing WSGI script '/var/www/FlaskApp/flaskapp.wsgi'., referer: http://www.zachflask.tk/
[Thu Sep 14 08:36:17.651868 2017] [wsgi:error] [pid 907] [client 128.206.251.96:27284] Traceback (most recent call last):, referer: http://www.zachflask.tk/
[Thu Sep 14 08:36:17.651889 2017] [wsgi:error] [pid 907] [client 128.206.251.96:27284]   File "/usr/local/lib/python2.7/dist-packages/flask/app.py", line 1997, in __call__, referer: http://www.zachflask.tk/
[Thu Sep 14 08:36:17.652299 2017] [wsgi:error] [pid 907] [client 128.206.251.96:27284]     return self.wsgi_app(environ, start_response), referer: http://www.zachflask.tk/
[Thu Sep 14 08:36:17.652312 2017] [wsgi:error] [pid 907] [client 128.206.251.96:27284]   File "/usr/local/lib/python2.7/dist-packages/flask/app.py", line 1985, in wsgi_app, referer: http://www.zachflask.tk/
[Thu Sep 14 08:36:17.652325 2017] [wsgi:error] [pid 907] [client 128.206.251.96:27284]     response = self.handle_exception(e), referer: http://www.zachflask.tk/
[Thu Sep 14 08:36:17.652332 2017] [wsgi:error] [pid 907] [client 128.206.251.96:27284]   File "/usr/local/lib/python2.7/dist-packages/flask/app.py", line 1540, in handle_exception, referer: http://www.zachflask.tk/
[Thu Sep 14 08:36:17.652339 2017] [wsgi:error] [pid 907] [client 128.206.251.96:27284]     reraise(exc_type, exc_value, tb), referer: http://www.zachflask.tk/
[Thu Sep 14 08:36:17.652344 2017] [wsgi:error] [pid 907] [client 128.206.251.96:27284]   File "/usr/local/lib/python2.7/dist-packages/flask/app.py", line 1982, in wsgi_app, referer: http://www.zachflask.tk/
[Thu Sep 14 08:36:17.652351 2017] [wsgi:error] [pid 907] [client 128.206.251.96:27284]     response = self.full_dispatch_request(), referer: http://www.zachflask.tk/
[Thu Sep 14 08:36:17.652356 2017] [wsgi:error] [pid 907] [client 128.206.251.96:27284]   File "/usr/local/lib/python2.7/dist-packages/flask/app.py", line 1614, in full_dispatch_request, referer: http://www.zachflask.tk/
[Thu Sep 14 08:36:17.652362 2017] [wsgi:error] [pid 907] [client 128.206.251.96:27284]     rv = self.handle_user_exception(e), referer: http://www.zachflask.tk/
[Thu Sep 14 08:36:17.652367 2017] [wsgi:error] [pid 907] [client 128.206.251.96:27284]   File "/usr/local/lib/python2.7/dist-packages/flask/app.py", line 1517, in handle_user_exception, referer: http://www.zachflask.tk/
[Thu Sep 14 08:36:17.652373 2017] [wsgi:error] [pid 907] [client 128.206.251.96:27284]     reraise(exc_type, exc_value, tb), referer: http://www.zachflask.tk/
[Thu Sep 14 08:36:17.652378 2017] [wsgi:error] [pid 907] [client 128.206.251.96:27284]   File "/usr/local/lib/python2.7/dist-packages/flask/app.py", line 1612, in full_dispatch_request, referer: http://www.zachflask.tk/
[Thu Sep 14 08:36:17.652384 2017] [wsgi:error] [pid 907] [client 128.206.251.96:27284]     rv = self.dispatch_request(), referer: http://www.zachflask.tk/
[Thu Sep 14 08:36:17.652389 2017] [wsgi:error] [pid 907] [client 128.206.251.96:27284]   File "/usr/local/lib/python2.7/dist-packages/flask/app.py", line 1598, in dispatch_request, referer: http://www.zachflask.tk/
[Thu Sep 14 08:36:17.652396 2017] [wsgi:error] [pid 907] [client 128.206.251.96:27284]     return self.view_functions[rule.endpoint](**req.view_args), referer: http://www.zachflask.tk/
[Thu Sep 14 08:36:17.652403 2017] [wsgi:error] [pid 907] [client 128.206.251.96:27284]   File "/var/www/FlaskApp/FlaskApp/FlaskApp.py", line 81, in add_entry, referer: http://www.zachflask.tk/
[Thu Sep 14 08:36:17.652439 2017] [wsgi:error] [pid 907] [client 128.206.251.96:27284]     [request.form['title'], request.form['text']]), referer: http://www.zachflask.tk/
[Thu Sep 14 08:36:17.652468 2017] [wsgi:error] [pid 907] [client 128.206.251.96:27284] OperationalError: unable to open database file, referer: http://www.zachflask.tk/
[Thu Sep 14 08:43:48.841363 2017] [wsgi:error] [pid 887] [client 128.206.251.96:35730] mod_wsgi (pid=887): Exception occurred processing WSGI script '/var/www/FlaskApp/flaskapp.wsgi'., referer: http://www.zachflask.tk/
[Thu Sep 14 08:43:48.841445 2017] [wsgi:error] [pid 887] [client 128.206.251.96:35730] Traceback (most recent call last):, referer: http://www.zachflask.tk/
[Thu Sep 14 08:43:48.841473 2017] [wsgi:error] [pid 887] [client 128.206.251.96:35730]   File "/usr/local/lib/python2.7/dist-packages/flask/app.py", line 1997, in __call__, referer: http://www.zachflask.tk/
[Thu Sep 14 08:43:48.841933 2017] [wsgi:error] [pid 887] [client 128.206.251.96:35730]     return self.wsgi_app(environ, start_response), referer: http://www.zachflask.tk/
[Thu Sep 14 08:43:48.841947 2017] [wsgi:error] [pid 887] [client 128.206.251.96:35730]   File "/usr/local/lib/python2.7/dist-packages/flask/app.py", line 1985, in wsgi_app, referer: http://www.zachflask.tk/
[Thu Sep 14 08:43:48.841963 2017] [wsgi:error] [pid 887] [client 128.206.251.96:35730]     response = self.handle_exception(e), referer: http://www.zachflask.tk/
[Thu Sep 14 08:43:48.841970 2017] [wsgi:error] [pid 887] [client 128.206.251.96:35730]   File "/usr/local/lib/python2.7/dist-packages/flask/app.py", line 1540, in handle_exception, referer: http://www.zachflask.tk/
[Thu Sep 14 08:43:48.841978 2017] [wsgi:error] [pid 887] [client 128.206.251.96:35730]     reraise(exc_type, exc_value, tb), referer: http://www.zachflask.tk/
[Thu Sep 14 08:43:48.841984 2017] [wsgi:error] [pid 887] [client 128.206.251.96:35730]   File "/usr/local/lib/python2.7/dist-packages/flask/app.py", line 1982, in wsgi_app, referer: http://www.zachflask.tk/
[Thu Sep 14 08:43:48.841991 2017] [wsgi:error] [pid 887] [client 128.206.251.96:35730]     response = self.full_dispatch_request(), referer: http://www.zachflask.tk/
[Thu Sep 14 08:43:48.841996 2017] [wsgi:error] [pid 887] [client 128.206.251.96:35730]   File "/usr/local/lib/python2.7/dist-packages/flask/app.py", line 1614, in full_dispatch_request, referer: http://www.zachflask.tk/
[Thu Sep 14 08:43:48.842003 2017] [wsgi:error] [pid 887] [client 128.206.251.96:35730]     rv = self.handle_user_exception(e), referer: http://www.zachflask.tk/
[Thu Sep 14 08:43:48.842008 2017] [wsgi:error] [pid 887] [client 128.206.251.96:35730]   File "/usr/local/lib/python2.7/dist-packages/flask/app.py", line 1517, in handle_user_exception, referer: http://www.zachflask.tk/
[Thu Sep 14 08:43:48.842014 2017] [wsgi:error] [pid 887] [client 128.206.251.96:35730]     reraise(exc_type, exc_value, tb), referer: http://www.zachflask.tk/
[Thu Sep 14 08:43:48.842019 2017] [wsgi:error] [pid 887] [client 128.206.251.96:35730]   File "/usr/local/lib/python2.7/dist-packages/flask/app.py", line 1612, in full_dispatch_request, referer: http://www.zachflask.tk/
[Thu Sep 14 08:43:48.842025 2017] [wsgi:error] [pid 887] [client 128.206.251.96:35730]     rv = self.dispatch_request(), referer: http://www.zachflask.tk/
[Thu Sep 14 08:43:48.842030 2017] [wsgi:error] [pid 887] [client 128.206.251.96:35730]   File "/usr/local/lib/python2.7/dist-packages/flask/app.py", line 1598, in dispatch_request, referer: http://www.zachflask.tk/
[Thu Sep 14 08:43:48.842037 2017] [wsgi:error] [pid 887] [client 128.206.251.96:35730]     return self.view_functions[rule.endpoint](**req.view_args), referer: http://www.zachflask.tk/
[Thu Sep 14 08:43:48.842044 2017] [wsgi:error] [pid 887] [client 128.206.251.96:35730]   File "/var/www/FlaskApp/FlaskApp/FlaskApp.py", line 81, in add_entry, referer: http://www.zachflask.tk/
[Thu Sep 14 08:43:48.842085 2017] [wsgi:error] [pid 887] [client 128.206.251.96:35730]     [request.form['title'], request.form['text']]), referer: http://www.zachflask.tk/
[Thu Sep 14 08:43:48.842106 2017] [wsgi:error] [pid 887] [client 128.206.251.96:35730] OperationalError: database is locked, referer: http://www.zachflask.tk/
[Thu Sep 14 08:45:05.978209 2017] [wsgi:error] [pid 1175] [client 128.206.251.96:32567] mod_wsgi (pid=1175): Exception occurred processing WSGI script '/var/www/FlaskApp/flaskapp.wsgi'., referer: http://www.zachflask.tk/
[Thu Sep 14 08:45:05.978277 2017] [wsgi:error] [pid 1175] [client 128.206.251.96:32567] Traceback (most recent call last):, referer: http://www.zachflask.tk/
[Thu Sep 14 08:45:05.978298 2017] [wsgi:error] [pid 1175] [client 128.206.251.96:32567]   File "/usr/local/lib/python2.7/dist-packages/flask/app.py", line 1997, in __call__, referer: http://www.zachflask.tk/
[Thu Sep 14 08:45:05.978692 2017] [wsgi:error] [pid 1175] [client 128.206.251.96:32567]     return self.wsgi_app(environ, start_response), referer: http://www.zachflask.tk/
[Thu Sep 14 08:45:05.978705 2017] [wsgi:error] [pid 1175] [client 128.206.251.96:32567]   File "/usr/local/lib/python2.7/dist-packages/flask/app.py", line 1985, in wsgi_app, referer: http://www.zachflask.tk/
[Thu Sep 14 08:45:05.978720 2017] [wsgi:error] [pid 1175] [client 128.206.251.96:32567]     response = self.handle_exception(e), referer: http://www.zachflask.tk/
[Thu Sep 14 08:45:05.978726 2017] [wsgi:error] [pid 1175] [client 128.206.251.96:32567]   File "/usr/local/lib/python2.7/dist-packages/flask/app.py", line 1540, in handle_exception, referer: http://www.zachflask.tk/
[Thu Sep 14 08:45:05.978734 2017] [wsgi:error] [pid 1175] [client 128.206.251.96:32567]     reraise(exc_type, exc_value, tb), referer: http://www.zachflask.tk/
[Thu Sep 14 08:45:05.978739 2017] [wsgi:error] [pid 1175] [client 128.206.251.96:32567]   File "/usr/local/lib/python2.7/dist-packages/flask/app.py", line 1982, in wsgi_app, referer: http://www.zachflask.tk/
[Thu Sep 14 08:45:05.978746 2017] [wsgi:error] [pid 1175] [client 128.206.251.96:32567]     response = self.full_dispatch_request(), referer: http://www.zachflask.tk/
[Thu Sep 14 08:45:05.978751 2017] [wsgi:error] [pid 1175] [client 128.206.251.96:32567]   File "/usr/local/lib/python2.7/dist-packages/flask/app.py", line 1614, in full_dispatch_request, referer: http://www.zachflask.tk/
[Thu Sep 14 08:45:05.978758 2017] [wsgi:error] [pid 1175] [client 128.206.251.96:32567]     rv = self.handle_user_exception(e), referer: http://www.zachflask.tk/
[Thu Sep 14 08:45:05.978762 2017] [wsgi:error] [pid 1175] [client 128.206.251.96:32567]   File "/usr/local/lib/python2.7/dist-packages/flask/app.py", line 1517, in handle_user_exception, referer: http://www.zachflask.tk/
[Thu Sep 14 08:45:05.978769 2017] [wsgi:error] [pid 1175] [client 128.206.251.96:32567]     reraise(exc_type, exc_value, tb), referer: http://www.zachflask.tk/
[Thu Sep 14 08:45:05.978773 2017] [wsgi:error] [pid 1175] [client 128.206.251.96:32567]   File "/usr/local/lib/python2.7/dist-packages/flask/app.py", line 1612, in full_dispatch_request, referer: http://www.zachflask.tk/
[Thu Sep 14 08:45:05.978780 2017] [wsgi:error] [pid 1175] [client 128.206.251.96:32567]     rv = self.dispatch_request(), referer: http://www.zachflask.tk/
[Thu Sep 14 08:45:05.978785 2017] [wsgi:error] [pid 1175] [client 128.206.251.96:32567]   File "/usr/local/lib/python2.7/dist-packages/flask/app.py", line 1598, in dispatch_request, referer: http://www.zachflask.tk/
[Thu Sep 14 08:45:05.978791 2017] [wsgi:error] [pid 1175] [client 128.206.251.96:32567]     return self.view_functions[rule.endpoint](**req.view_args), referer: http://www.zachflask.tk/
[Thu Sep 14 08:45:05.978798 2017] [wsgi:error] [pid 1175] [client 128.206.251.96:32567]   File "/var/www/FlaskApp/FlaskApp/FlaskApp.py", line 81, in add_entry, referer: http://www.zachflask.tk/
[Thu Sep 14 08:45:05.978835 2017] [wsgi:error] [pid 1175] [client 128.206.251.96:32567]     [request.form['title'], request.form['text']]), referer: http://www.zachflask.tk/
[Thu Sep 14 08:45:05.978854 2017] [wsgi:error] [pid 1175] [client 128.206.251.96:32567] OperationalError: unable to open database file, referer: http://www.zachflask.tk/
